2013-11-27 20:41:13,611 INFO org.apache.hadoop.yarn.server.resourcemanager.rmapp.RMAppImpl: Sakshi application_1385613010171_00055 State change from FINISHING to FINISHED after EVENT: ATTEMPT_FINISHED

/************************************************************
STARTUP_MSG: Starting ResourceManager
STARTUP_MSG:   host = ubuntusakshi/127.0.1.1
STARTUP_MSG:   args = []
STARTUP_MSG:   version = 2.1.0-beta
STARTUP_MSG:   build = https://svn.apache.org/repos/asf/hadoop/common -r 1514472; compiled by 'hortonmu' on 2013-08-15T20:48Z
STARTUP_MSG:   java = 1.7.0_17
************************************************************/
2013-11-27 22:30:10,333 INFO org.apache.hadoop.yarn.server.resourcemanager.ResourceManager: registered UNIX signal handlers for [TERM, HUP, INT]
2013-11-27 22:30:11,746 INFO org.apache.hadoop.yarn.server.resourcemanager.security.AMRMTokenSecretManager: Rolling master-key for amrm-tokens
2013-11-27 22:30:11,825 INFO org.apache.hadoop.yarn.server.resourcemanager.security.RMContainerTokenSecretManager: ContainerTokenKeyRollingInterval: 86400000ms and ContainerTokenKeyActivationDelay: 900000ms
2013-11-27 22:30:11,829 INFO org.apache.hadoop.yarn.server.resourcemanager.security.NMTokenSecretManagerInRM: NMTokenKeyRollingInterval: 86400000ms and NMTokenKeyActivationDelay: 900000ms
2013-11-27 22:30:11,840 INFO org.apache.hadoop.yarn.event.AsyncDispatcher: Registering class org.apache.hadoop.yarn.server.resourcemanager.recovery.RMStateStoreEventType for class org.apache.hadoop.yarn.server.resourcemanager.recovery.RMStateStore$ForwardingEventHandler
2013-11-27 22:30:11,844 INFO org.apache.hadoop.yarn.event.AsyncDispatcher: Registering class org.apache.hadoop.yarn.server.resourcemanager.NodesListManagerEventType for class org.apache.hadoop.yarn.server.resourcemanager.NodesListManager
2013-11-27 22:30:11,844 INFO org.apache.hadoop.yarn.server.resourcemanager.ResourceManager: Using Scheduler: org.apache.hadoop.yarn.server.resourcemanager.scheduler.capacity.CapacityScheduler
2013-11-27 22:30:12,539 INFO org.apache.hadoop.yarn.event.AsyncDispatcher: Registering class org.apache.hadoop.yarn.server.resourcemanager.scheduler.event.SchedulerEventType for class org.apache.hadoop.yarn.server.resourcemanager.ResourceManager$SchedulerEventDispatcher
2013-11-27 22:30:12,574 INFO org.apache.hadoop.yarn.event.AsyncDispatcher: Registering class org.apache.hadoop.yarn.server.resourcemanager.rmapp.RMAppEventType for class org.apache.hadoop.yarn.server.resourcemanager.ResourceManager$ApplicationEventDispatcher
2013-11-27 22:30:12,576 INFO org.apache.hadoop.yarn.event.AsyncDispatcher: Registering class org.apache.hadoop.yarn.server.resourcemanager.rmapp.attempt.RMAppAttemptEventType for class org.apache.hadoop.yarn.server.resourcemanager.ResourceManager$ApplicationAttemptEventDispatcher
2013-11-27 22:30:12,578 INFO org.apache.hadoop.yarn.event.AsyncDispatcher: Registering class org.apache.hadoop.yarn.server.resourcemanager.rmnode.RMNodeEventType for class org.apache.hadoop.yarn.server.resourcemanager.ResourceManager$NodeEventDispatcher
2013-11-27 22:30:13,906 INFO org.apache.hadoop.metrics2.impl.MetricsConfig: loaded properties from hadoop-metrics2.properties
2013-11-27 22:30:14,476 INFO org.apache.hadoop.metrics2.impl.MetricsSystemImpl: Scheduled snapshot period at 10 second(s).
2013-11-27 22:30:14,476 INFO org.apache.hadoop.metrics2.impl.MetricsSystemImpl: ResourceManager metrics system started
2013-11-27 22:30:15,407 WARN org.apache.hadoop.util.NativeCodeLoader: Unable to load native-hadoop library for your platform... using builtin-java classes where applicable
2013-11-27 22:30:15,469 INFO org.apache.hadoop.yarn.server.resourcemanager.scheduler.capacity.ParentQueue: root, capacity=1.0, asboluteCapacity=1.0, maxCapacity=1.0, asboluteMaxCapacity=1.0, state=RUNNING, acls=SUBMIT_APPLICATIONS:*ADMINISTER_QUEUE:*
2013-11-27 22:30:15,469 INFO org.apache.hadoop.yarn.server.resourcemanager.scheduler.capacity.ParentQueue: Initialized parent-queue root name=root, fullname=root
2013-11-27 22:30:15,500 INFO org.apache.hadoop.yarn.server.resourcemanager.scheduler.capacity.LeafQueue: Initializing default
capacity = 1.0 [= (float) configuredCapacity / 100 ]
asboluteCapacity = 1.0 [= parentAbsoluteCapacity * capacity ]
maxCapacity = 1.0 [= configuredMaxCapacity ]
absoluteMaxCapacity = 1.0 [= 1.0 maximumCapacity undefined, (parentAbsoluteMaxCapacity * maximumCapacity) / 100 otherwise ]
userLimit = 100 [= configuredUserLimit ]
userLimitFactor = 1.0 [= configuredUserLimitFactor ]
maxApplications = 10000 [= configuredMaximumSystemApplicationsPerQueue or (int)(configuredMaximumSystemApplications * absoluteCapacity)]
maxApplicationsPerUser = 10000 [= (int)(maxApplications * (userLimit / 100.0f) * userLimitFactor) ]
maxActiveApplications = 1 [= max((int)ceil((clusterResourceMemory / minimumAllocation) * maxAMResourcePerQueuePercent * absoluteMaxCapacity),1) ]
maxActiveAppsUsingAbsCap = 1 [= max((int)ceil((clusterResourceMemory / minimumAllocation) *maxAMResourcePercent * absoluteCapacity),1) ]
maxActiveApplicationsPerUser = 1 [= max((int)(maxActiveApplications * (userLimit / 100.0f) * userLimitFactor),1) ]
usedCapacity = 0.0 [= usedResourcesMemory / (clusterResourceMemory * absoluteCapacity)]
absoluteUsedCapacity = 0.0 [= usedResourcesMemory / clusterResourceMemory]
maxAMResourcePerQueuePercent = 0.1 [= configuredMaximumAMResourcePercent ]
minimumAllocationFactor = 0.875 [= (float)(maximumAllocationMemory - minimumAllocationMemory) / maximumAllocationMemory ]
numContainers = 0 [= currentNumContainers ]
state = RUNNING [= configuredState ]
acls = SUBMIT_APPLICATIONS:*ADMINISTER_QUEUE:* [= configuredAcls ]
nodeLocalityDelay = 0

2013-11-27 22:30:15,500 INFO org.apache.hadoop.yarn.server.resourcemanager.scheduler.capacity.CapacityScheduler: Initialized queue: default: capacity=1.0, absoluteCapacity=1.0, usedResources=<memory:0, vCores:0>usedCapacity=0.0, absoluteUsedCapacity=0.0, numApps=0, numContainers=0
2013-11-27 22:30:15,501 INFO org.apache.hadoop.yarn.server.resourcemanager.scheduler.capacity.CapacityScheduler: Initialized queue: root: numChildQueue= 1, capacity=1.0, absoluteCapacity=1.0, usedResources=<memory:0, vCores:0>usedCapacity=0.0, numApps=0, numContainers=0
2013-11-27 22:30:15,501 INFO org.apache.hadoop.yarn.server.resourcemanager.scheduler.capacity.CapacityScheduler: Initialized root queue root: numChildQueue= 1, capacity=1.0, absoluteCapacity=1.0, usedResources=<memory:0, vCores:0>usedCapacity=0.0, numApps=0, numContainers=0
2013-11-27 22:30:15,501 INFO org.apache.hadoop.yarn.server.resourcemanager.scheduler.capacity.CapacityScheduler: Initialized CapacityScheduler with calculator=class org.apache.hadoop.yarn.util.resource.DefaultResourceCalculator, minimumAllocation=<<memory:1024, vCores:1>>, maximumAllocation=<<memory:8192, vCores:32>>
2013-11-27 22:30:16,163 INFO org.apache.hadoop.yarn.event.AsyncDispatcher: Registering class org.apache.hadoop.yarn.server.resourcemanager.RMAppManagerEventType for class org.apache.hadoop.yarn.server.resourcemanager.RMAppManager
2013-11-27 22:30:16,219 INFO org.apache.hadoop.yarn.event.AsyncDispatcher: Registering class org.apache.hadoop.yarn.server.resourcemanager.amlauncher.AMLauncherEventType for class org.apache.hadoop.yarn.server.resourcemanager.amlauncher.ApplicationMasterLauncher
2013-11-27 22:30:16,222 INFO org.apache.hadoop.yarn.server.resourcemanager.RMNMInfo: Registered RMNMInfo MBean
2013-11-27 22:30:16,224 INFO org.apache.hadoop.util.HostsFileReader: Refreshing hosts (include/exclude) list
2013-11-27 22:30:16,248 INFO org.apache.hadoop.yarn.server.resourcemanager.security.AMRMTokenSecretManager: Rolling master-key for amrm-tokens
2013-11-27 22:30:16,248 INFO org.apache.hadoop.yarn.server.resourcemanager.security.RMContainerTokenSecretManager: Rolling master-key for container-tokens
2013-11-27 22:30:16,255 INFO org.apache.hadoop.yarn.server.resourcemanager.security.NMTokenSecretManagerInRM: Rolling master-key for nm-tokens
2013-11-27 22:30:16,357 INFO org.mortbay.log: Logging to org.slf4j.impl.Log4jLoggerAdapter(org.mortbay.log) via org.mortbay.log.Slf4jLog
2013-11-27 22:30:16,440 INFO org.apache.hadoop.http.HttpServer: Added global filter 'safety' (class=org.apache.hadoop.http.HttpServer$QuotingInputFilter)
2013-11-27 22:30:16,444 INFO org.apache.hadoop.http.HttpServer: Added filter static_user_filter (class=org.apache.hadoop.http.lib.StaticUserWebFilter$StaticUserFilter) to context cluster
2013-11-27 22:30:16,444 INFO org.apache.hadoop.http.HttpServer: Added filter static_user_filter (class=org.apache.hadoop.http.lib.StaticUserWebFilter$StaticUserFilter) to context static
2013-11-27 22:30:16,444 INFO org.apache.hadoop.http.HttpServer: Added filter static_user_filter (class=org.apache.hadoop.http.lib.StaticUserWebFilter$StaticUserFilter) to context logs
2013-11-27 22:30:16,448 INFO org.apache.hadoop.http.HttpServer: adding path spec: /cluster
2013-11-27 22:30:16,449 INFO org.apache.hadoop.http.HttpServer: adding path spec: /cluster/*
2013-11-27 22:30:16,449 INFO org.apache.hadoop.http.HttpServer: adding path spec: /ws
2013-11-27 22:30:16,449 INFO org.apache.hadoop.http.HttpServer: adding path spec: /ws/*
2013-11-27 22:30:16,451 INFO org.apache.hadoop.http.HttpServer: Added global filter 'guice' (class=com.google.inject.servlet.GuiceFilter)
2013-11-27 22:30:16,462 INFO org.apache.hadoop.http.HttpServer: Jetty bound to port 8088
2013-11-27 22:30:16,462 INFO org.mortbay.log: jetty-6.1.26
2013-11-27 22:30:16,524 INFO org.mortbay.log: Extract jar:file:/home/hduser/yarn/hadoop-2.1.0-beta/share/hadoop/yarn/hadoop-yarn-common-2.1.0-beta.jar!/webapps/cluster to /tmp/Jetty_0_0_0_0_8088_cluster____u0rgz3/webapp
2013-11-27 22:30:17,062 INFO org.mortbay.log: Started SelectChannelConnector@0.0.0.0:8088
2013-11-27 22:30:17,062 INFO org.apache.hadoop.yarn.webapp.WebApps: Web app /cluster started at 8088
2013-11-27 22:30:18,747 INFO org.apache.hadoop.yarn.webapp.WebApps: Registered webapp guice modules
2013-11-27 22:30:18,749 INFO org.apache.hadoop.security.token.delegation.AbstractDelegationTokenSecretManager: Updating the current master key for generating delegation tokens
2013-11-27 22:30:18,750 INFO org.apache.hadoop.yarn.server.resourcemanager.security.RMDelegationTokenSecretManager: storing master key with keyID 1
2013-11-27 22:30:18,751 INFO org.apache.hadoop.security.token.delegation.AbstractDelegationTokenSecretManager: Starting expired delegation token remover thread, tokenRemoverScanInterval=60 min(s)
2013-11-27 22:30:18,860 INFO org.apache.hadoop.security.token.delegation.AbstractDelegationTokenSecretManager: Updating the current master key for generating delegation tokens
2013-11-27 22:30:18,921 INFO org.apache.hadoop.yarn.server.resourcemanager.security.RMDelegationTokenSecretManager: storing master key with keyID 2
2013-11-27 22:30:25,297 INFO org.apache.hadoop.ipc.Server: Starting Socket Reader #1 for port 8031
2013-11-27 22:30:25,691 INFO org.apache.hadoop.yarn.factories.impl.pb.RpcServerFactoryPBImpl: Adding protocol org.apache.hadoop.yarn.server.api.ResourceTrackerPB to the server
2013-11-27 22:30:25,700 INFO org.apache.hadoop.ipc.Server: IPC Server Responder: starting
2013-11-27 22:30:25,886 INFO org.apache.hadoop.ipc.Server: IPC Server listener on 8031: starting
2013-11-27 22:30:31,459 INFO org.apache.hadoop.ipc.Server: Starting Socket Reader #1 for port 8030
2013-11-27 22:30:31,560 INFO org.apache.hadoop.yarn.factories.impl.pb.RpcServerFactoryPBImpl: Adding protocol org.apache.hadoop.yarn.api.ApplicationMasterProtocolPB to the server
2013-11-27 22:30:31,565 INFO org.apache.hadoop.ipc.Server: IPC Server Responder: starting
2013-11-27 22:30:31,567 INFO org.apache.hadoop.ipc.Server: IPC Server listener on 8030: starting
2013-11-27 22:30:37,115 INFO org.apache.hadoop.ipc.Server: Starting Socket Reader #1 for port 8032
2013-11-27 22:30:37,200 INFO org.apache.hadoop.yarn.factories.impl.pb.RpcServerFactoryPBImpl: Adding protocol org.apache.hadoop.yarn.api.ApplicationClientProtocolPB to the server
2013-11-27 22:30:37,200 INFO org.apache.hadoop.ipc.Server: IPC Server Responder: starting
2013-11-27 22:30:37,200 INFO org.apache.hadoop.ipc.Server: IPC Server listener on 8032: starting
2013-11-27 22:30:42,689 INFO org.apache.hadoop.yarn.factories.impl.pb.RpcServerFactoryPBImpl: Adding protocol org.apache.hadoop.yarn.server.api.ResourceManagerAdministrationProtocolPB to the server
2013-11-27 22:30:42,689 INFO org.apache.hadoop.ipc.Server: Starting Socket Reader #1 for port 8033
2013-11-27 22:30:42,696 INFO org.apache.hadoop.ipc.Server: IPC Server listener on 8033: starting
2013-11-27 22:30:42,708 INFO org.apache.hadoop.ipc.Server: IPC Server Responder: starting
2013-11-27 22:30:45,056 INFO org.apache.hadoop.yarn.util.RackResolver: Resolved ubuntusakshi to /default-rack
2013-11-27 22:30:45,076 INFO org.apache.hadoop.yarn.server.resourcemanager.ResourceTrackerService: NodeManager from node ubuntusakshi(cmPort: 59487 httpPort: 8042) registered with capability: <memory:8192, vCores:8>, assigned nodeId ubuntusakshi:59487
2013-11-27 22:30:45,134 INFO org.apache.hadoop.yarn.server.resourcemanager.rmnode.RMNodeImpl: ubuntusakshi:59487 Node Transitioned from NEW to RUNNING
2013-11-27 22:30:45,169 INFO org.apache.hadoop.yarn.server.resourcemanager.scheduler.capacity.CapacityScheduler: Added node ubuntusakshi:59487 clusterResource: <memory:8192, vCores:8>
2013-11-27 22:34:31,684 INFO org.apache.hadoop.yarn.server.resourcemanager.ClientRMService: Allocated new applicationId: 1
2013-11-27 22:34:31,685 INFO org.apache.hadoop.yarn.server.resourcemanager.ClientRMService: Allocated new applicationId: 2
2013-11-27 22:34:53,485 INFO org.apache.hadoop.yarn.server.resourcemanager.ClientRMService: Application with id 2 submitted by user sakshi
2013-11-27 22:34:53,486 INFO org.apache.hadoop.yarn.server.resourcemanager.ClientRMService: Application with id 1 submitted by user sakshi
2013-11-27 22:34:53,596 INFO org.apache.hadoop.yarn.server.resourcemanager.rmapp.RMAppImpl: Storing application with id application_1385613010171_0002
2013-11-27 22:34:53,605 INFO org.apache.hadoop.yarn.server.resourcemanager.rmapp.RMAppImpl: Sakshi application_1385613010171_0002 State change from NEW to NEW_SAVING after EVENT: START
2013-11-27 22:34:53,606 INFO org.apache.hadoop.yarn.server.resourcemanager.rmapp.RMAppImpl: Storing application with id application_1385613010171_0001
2013-11-27 22:34:53,614 INFO org.apache.hadoop.yarn.server.resourcemanager.recovery.RMStateStore: Storing info for app: application_1385613010171_0002
2013-11-27 22:34:53,614 INFO org.apache.hadoop.yarn.server.resourcemanager.rmapp.RMAppImpl: Sakshi application_1385613010171_0001 State change from NEW to NEW_SAVING after EVENT: START
2013-11-27 22:34:53,615 INFO org.apache.hadoop.yarn.server.resourcemanager.RMAuditLogger: USER=sakshi	IP=127.0.0.1	OPERATION=Submit Application Request	TARGET=ClientRMService	RESULT=SUCCESS	APPID=application_1385613010171_0002
2013-11-27 22:34:53,616 INFO org.apache.hadoop.yarn.server.resourcemanager.RMAuditLogger: USER=sakshi	IP=127.0.0.1	OPERATION=Submit Application Request	TARGET=ClientRMService	RESULT=SUCCESS	APPID=application_1385613010171_0001
2013-11-27 22:34:53,618 INFO org.apache.hadoop.yarn.server.resourcemanager.recovery.RMStateStore: Storing info for app: application_1385613010171_0001
2013-11-27 22:34:54,095 INFO org.apache.hadoop.yarn.server.resourcemanager.rmapp.RMAppImpl: Sakshi application_1385613010171_0002 State change from NEW_SAVING to SUBMITTED after EVENT: APP_SAVED
2013-11-27 22:34:54,101 INFO org.apache.hadoop.yarn.server.resourcemanager.rmapp.RMAppImpl: Sakshi application_1385613010171_0001 State change from NEW_SAVING to SUBMITTED after EVENT: APP_SAVED
2013-11-27 22:34:54,102 INFO org.apache.hadoop.yarn.server.resourcemanager.rmapp.attempt.RMAppAttemptImpl: Processing event for appattempt_1385613010171_0002_000001 of type START
2013-11-27 22:34:54,141 INFO org.apache.hadoop.yarn.server.resourcemanager.ApplicationMasterService: Registering app attempt : appattempt_1385613010171_0002_000001
2013-11-27 22:34:55,282 INFO org.apache.hadoop.yarn.server.resourcemanager.rmapp.attempt.RMAppAttemptImpl: Sakshi appattempt_1385613010171_0002_000001 State change from NEW to SUBMITTED after EVENT: START
2013-11-27 22:34:55,371 INFO org.apache.hadoop.yarn.server.resourcemanager.rmapp.attempt.RMAppAttemptImpl: Processing event for appattempt_1385613010171_0001_000001 of type START
2013-11-27 22:34:55,459 INFO org.apache.hadoop.yarn.server.resourcemanager.ApplicationMasterService: Registering app attempt : appattempt_1385613010171_0001_000001
2013-11-27 22:34:55,459 INFO org.apache.hadoop.yarn.server.resourcemanager.rmapp.attempt.RMAppAttemptImpl: Sakshi appattempt_1385613010171_0001_000001 State change from NEW to SUBMITTED after EVENT: START
2013-11-27 22:34:55,737 INFO org.apache.hadoop.yarn.server.resourcemanager.scheduler.capacity.LeafQueue: Application application_1385613010171_0002 from user: sakshi activated in queue: default
2013-11-27 22:34:55,738 INFO org.apache.hadoop.yarn.server.resourcemanager.scheduler.capacity.LeafQueue: Application added - appId: application_1385613010171_0002 user: org.apache.hadoop.yarn.server.resourcemanager.scheduler.capacity.LeafQueue$User@301e76a9, leaf-queue: default #user-pending-applications: 0 #user-active-applications: 1 #queue-pending-applications: 0 #queue-active-applications: 1
2013-11-27 22:34:55,769 INFO org.apache.hadoop.yarn.server.resourcemanager.scheduler.capacity.ParentQueue: Application added - appId: application_1385613010171_0002 user: sakshi leaf-queue of parent: root #applications: 1
2013-11-27 22:34:55,770 INFO org.apache.hadoop.yarn.server.resourcemanager.scheduler.capacity.CapacityScheduler: Application Submission: appattempt_1385613010171_0002_000001, user: sakshi queue: default: capacity=1.0, absoluteCapacity=1.0, usedResources=<memory:0, vCores:0>usedCapacity=0.0, absoluteUsedCapacity=0.0, numApps=1, numContainers=0, currently active: 1
2013-11-27 22:34:55,770 INFO org.apache.hadoop.yarn.server.resourcemanager.rmapp.attempt.RMAppAttemptImpl: Processing event for appattempt_1385613010171_0002_000001 of type APP_ACCEPTED
2013-11-27 22:34:55,772 INFO org.apache.hadoop.yarn.server.resourcemanager.rmapp.attempt.RMAppAttemptImpl: Sakshi appattempt_1385613010171_0002_000001 State change from SUBMITTED to SCHEDULED after EVENT: APP_ACCEPTED
2013-11-27 22:34:55,772 INFO org.apache.hadoop.yarn.server.resourcemanager.rmapp.RMAppImpl: Sakshi application_1385613010171_0002 State change from SUBMITTED to ACCEPTED after EVENT: APP_ACCEPTED
2013-11-27 22:34:55,772 INFO org.apache.hadoop.yarn.server.resourcemanager.scheduler.capacity.LeafQueue: Application added - appId: application_1385613010171_0001 user: org.apache.hadoop.yarn.server.resourcemanager.scheduler.capacity.LeafQueue$User@301e76a9, leaf-queue: default #user-pending-applications: 1 #user-active-applications: 1 #queue-pending-applications: 1 #queue-active-applications: 1
2013-11-27 22:34:55,772 INFO org.apache.hadoop.yarn.server.resourcemanager.scheduler.capacity.ParentQueue: Application added - appId: application_1385613010171_0001 user: sakshi leaf-queue of parent: root #applications: 2
2013-11-27 22:34:55,772 INFO org.apache.hadoop.yarn.server.resourcemanager.scheduler.capacity.CapacityScheduler: Application Submission: appattempt_1385613010171_0001_000001, user: sakshi queue: default: capacity=1.0, absoluteCapacity=1.0, usedResources=<memory:0, vCores:0>usedCapacity=0.0, absoluteUsedCapacity=0.0, numApps=2, numContainers=0, currently active: 2
2013-11-27 22:34:55,773 INFO org.apache.hadoop.yarn.server.resourcemanager.rmapp.attempt.RMAppAttemptImpl: Processing event for appattempt_1385613010171_0001_000001 of type APP_ACCEPTED
2013-11-27 22:34:55,773 INFO org.apache.hadoop.yarn.server.resourcemanager.rmapp.attempt.RMAppAttemptImpl: Sakshi appattempt_1385613010171_0001_000001 State change from SUBMITTED to SCHEDULED after EVENT: APP_ACCEPTED
2013-11-27 22:34:55,773 INFO org.apache.hadoop.yarn.server.resourcemanager.rmapp.RMAppImpl: Sakshi application_1385613010171_0001 State change from SUBMITTED to ACCEPTED after EVENT: APP_ACCEPTED
2013-11-27 22:34:57,788 INFO org.apache.hadoop.yarn.server.resourcemanager.rmcontainer.RMContainerImpl: container_1385613010171_0002_01_000001 Container Transitioned from NEW to ALLOCATED
2013-11-27 22:34:57,788 INFO org.apache.hadoop.yarn.server.resourcemanager.RMAuditLogger: USER=sakshi	OPERATION=AM Allocated Container	TARGET=SchedulerApp	RESULT=SUCCESS	APPID=application_1385613010171_0002	CONTAINERID=container_1385613010171_0002_01_000001
2013-11-27 22:34:57,789 INFO org.apache.hadoop.yarn.server.resourcemanager.scheduler.common.fica.FiCaSchedulerNode: Assigned container container_1385613010171_0002_01_000001 of capacity <memory:2048, vCores:1> on host ubuntusakshi:59487, which currently has 1 containers, <memory:2048, vCores:1> used and <memory:6144, vCores:7> available
2013-11-27 22:34:57,789 INFO org.apache.hadoop.yarn.server.resourcemanager.scheduler.capacity.LeafQueue: assignedContainer application=application_1385613010171_0002 container=Container: [ContainerId: container_1385613010171_0002_01_000001, NodeId: ubuntusakshi:59487, NodeHttpAddress: ubuntusakshi:8042, Resource: <memory:2048, vCores:1>, Priority: 0, Token: Token { kind: ContainerToken, service: 127.0.1.1:59487 }, ] containerId=container_1385613010171_0002_01_000001 queue=default: capacity=1.0, absoluteCapacity=1.0, usedResources=<memory:0, vCores:0>usedCapacity=0.0, absoluteUsedCapacity=0.0, numApps=2, numContainers=0 usedCapacity=0.0 absoluteUsedCapacity=0.0 used=<memory:0, vCores:0> cluster=<memory:8192, vCores:8>
2013-11-27 22:34:57,789 INFO org.apache.hadoop.yarn.server.resourcemanager.rmapp.attempt.RMAppAttemptImpl: Processing event for appattempt_1385613010171_0002_000001 of type CONTAINER_ALLOCATED
2013-11-27 22:34:57,792 INFO org.apache.hadoop.yarn.server.resourcemanager.rmcontainer.RMContainerImpl: container_1385613010171_0002_01_000001 Container Transitioned from ALLOCATED to ACQUIRED
2013-11-27 22:34:57,794 INFO org.apache.hadoop.yarn.server.resourcemanager.scheduler.capacity.ParentQueue: Re-sorting assigned queue: root.default stats: default: capacity=1.0, absoluteCapacity=1.0, usedResources=<memory:2048, vCores:1>usedCapacity=0.25, absoluteUsedCapacity=0.25, numApps=2, numContainers=1
2013-11-27 22:34:57,912 INFO org.apache.hadoop.yarn.server.resourcemanager.scheduler.capacity.ParentQueue: assignedContainer queue=root usedCapacity=0.25 absoluteUsedCapacity=0.25 used=<memory:2048, vCores:1> cluster=<memory:8192, vCores:8>
2013-11-27 22:34:57,929 INFO org.apache.hadoop.yarn.server.resourcemanager.rmapp.attempt.RMAppAttemptImpl: Storing attempt: AppId: application_1385613010171_0002 AttemptId: appattempt_1385613010171_0002_000001 MasterContainer: Container: [ContainerId: container_1385613010171_0002_01_000001, NodeId: ubuntusakshi:59487, NodeHttpAddress: ubuntusakshi:8042, Resource: <memory:2048, vCores:1>, Priority: 0, Token: Token { kind: ContainerToken, service: 127.0.1.1:59487 }, ]
2013-11-27 22:35:00,017 INFO org.apache.hadoop.yarn.server.resourcemanager.rmapp.attempt.RMAppAttemptImpl: Sakshi appattempt_1385613010171_0002_000001 State change from SCHEDULED to ALLOCATED_SAVING after EVENT: CONTAINER_ALLOCATED
2013-11-27 22:35:00,024 INFO org.apache.hadoop.yarn.server.resourcemanager.rmapp.attempt.RMAppAttemptImpl: Processing event for appattempt_1385613010171_0002_000001 of type CONTAINER_ACQUIRED
2013-11-27 22:35:00,116 INFO org.apache.hadoop.yarn.server.resourcemanager.recovery.RMStateStore: Storing info for attempt: appattempt_1385613010171_0002_000001
2013-11-27 22:35:00,117 INFO org.apache.hadoop.yarn.server.resourcemanager.rmapp.attempt.RMAppAttemptImpl: Processing event for appattempt_1385613010171_0002_000001 of type ATTEMPT_SAVED
2013-11-27 22:35:00,118 INFO org.apache.hadoop.yarn.server.resourcemanager.rmapp.attempt.RMAppAttemptImpl: Sakshi appattempt_1385613010171_0002_000001 State change from ALLOCATED_SAVING to ALLOCATED after EVENT: ATTEMPT_SAVED
2013-11-27 22:35:00,201 INFO org.apache.hadoop.yarn.server.resourcemanager.amlauncher.AMLauncher: Launching masterappattempt_1385613010171_0002_000001
2013-11-27 22:35:00,554 INFO org.apache.hadoop.yarn.server.resourcemanager.amlauncher.AMLauncher: Setting up container Container: [ContainerId: container_1385613010171_0002_01_000001, NodeId: ubuntusakshi:59487, NodeHttpAddress: ubuntusakshi:8042, Resource: <memory:2048, vCores:1>, Priority: 0, Token: Token { kind: ContainerToken, service: 127.0.1.1:59487 }, ] for AM appattempt_1385613010171_0002_000001
2013-11-27 22:35:00,557 INFO org.apache.hadoop.yarn.server.resourcemanager.amlauncher.AMLauncher: Command to launch container container_1385613010171_0002_01_000001 : $JAVA_HOME/bin/java -Dlog4j.configuration=container-log4j.properties -Dyarn.app.container.log.dir=<LOG_DIR> -Dyarn.app.container.log.filesize=0 -Dhadoop.root.logger=INFO,CLA  -Xmx1024m org.apache.hadoop.mapreduce.v2.app.MRAppMaster 1><LOG_DIR>/stdout 2><LOG_DIR>/stderr 
2013-11-27 22:35:32,274 INFO org.apache.hadoop.yarn.server.resourcemanager.rmcontainer.RMContainerImpl: container_1385613010171_0002_01_000001 Container Transitioned from ACQUIRED to RUNNING
2013-11-27 22:35:32,533 INFO org.apache.hadoop.yarn.server.resourcemanager.amlauncher.AMLauncher: Done launching container Container: [ContainerId: container_1385613010171_0002_01_000001, NodeId: ubuntusakshi:59487, NodeHttpAddress: ubuntusakshi:8042, Resource: <memory:2048, vCores:1>, Priority: 0, Token: Token { kind: ContainerToken, service: 127.0.1.1:59487 }, ] for AM appattempt_1385613010171_0002_000001
2013-11-27 22:35:32,534 INFO org.apache.hadoop.yarn.server.resourcemanager.rmapp.attempt.RMAppAttemptImpl: Processing event for appattempt_1385613010171_0002_000001 of type LAUNCHED
2013-11-27 22:35:32,534 INFO org.apache.hadoop.yarn.server.resourcemanager.rmapp.attempt.RMAppAttemptImpl: Sakshi appattempt_1385613010171_0002_000001 State change from ALLOCATED to LAUNCHED after EVENT: LAUNCHED
2013-11-27 22:36:15,945 INFO SecurityLogger.org.apache.hadoop.ipc.Server: Auth successful for appattempt_1385613010171_0002_000001 (auth:SIMPLE)
2013-11-27 22:36:16,087 INFO org.apache.hadoop.yarn.server.resourcemanager.ApplicationMasterService: AM registration appattempt_1385613010171_0002_000001
2013-11-27 22:36:16,090 INFO org.apache.hadoop.yarn.server.resourcemanager.rmapp.attempt.RMAppAttemptImpl: Processing event for appattempt_1385613010171_0002_000001 of type REGISTERED
2013-11-27 22:36:16,091 INFO org.apache.hadoop.yarn.server.resourcemanager.RMAuditLogger: USER=sakshi	IP=127.0.0.1	OPERATION=Register App Master	TARGET=ApplicationMasterService	RESULT=SUCCESS	APPID=application_1385613010171_0002	APPATTEMPTID=appattempt_1385613010171_0002_000001
2013-11-27 22:36:16,130 INFO org.apache.hadoop.yarn.server.resourcemanager.rmapp.attempt.RMAppAttemptImpl: Sakshi appattempt_1385613010171_0002_000001 State change from LAUNCHED to RUNNING after EVENT: REGISTERED
2013-11-27 22:36:16,131 INFO org.apache.hadoop.yarn.server.resourcemanager.rmapp.RMAppImpl: Sakshi application_1385613010171_0002 State change from ACCEPTED to RUNNING after EVENT: ATTEMPT_REGISTERED
2013-11-27 22:36:18,208 INFO org.apache.hadoop.yarn.server.resourcemanager.rmapp.attempt.RMAppAttemptImpl: Processing event for appattempt_1385613010171_0002_000001 of type STATUS_UPDATE
2013-11-27 22:36:19,298 INFO org.apache.hadoop.yarn.server.resourcemanager.rmapp.attempt.RMAppAttemptImpl: Processing event for appattempt_1385613010171_0002_000001 of type CONTAINER_ALLOCATED
2013-11-27 22:36:19,298 INFO org.apache.hadoop.yarn.server.resourcemanager.rmcontainer.RMContainerImpl: container_1385613010171_0002_01_000002 Container Transitioned from NEW to ALLOCATED
2013-11-27 22:36:19,324 INFO org.apache.hadoop.yarn.server.resourcemanager.RMAuditLogger: USER=sakshi	OPERATION=AM Allocated Container	TARGET=SchedulerApp	RESULT=SUCCESS	APPID=application_1385613010171_0002	CONTAINERID=container_1385613010171_0002_01_000002
2013-11-27 22:36:19,324 INFO org.apache.hadoop.yarn.server.resourcemanager.scheduler.common.fica.FiCaSchedulerNode: Assigned container container_1385613010171_0002_01_000002 of capacity <memory:1024, vCores:1> on host ubuntusakshi:59487, which currently has 2 containers, <memory:3072, vCores:2> used and <memory:5120, vCores:6> available
2013-11-27 22:36:19,325 INFO org.apache.hadoop.yarn.server.resourcemanager.scheduler.capacity.LeafQueue: assignedContainer application=application_1385613010171_0002 container=Container: [ContainerId: container_1385613010171_0002_01_000002, NodeId: ubuntusakshi:59487, NodeHttpAddress: ubuntusakshi:8042, Resource: <memory:1024, vCores:1>, Priority: 20, Token: Token { kind: ContainerToken, service: 127.0.1.1:59487 }, ] containerId=container_1385613010171_0002_01_000002 queue=default: capacity=1.0, absoluteCapacity=1.0, usedResources=<memory:2048, vCores:1>usedCapacity=0.25, absoluteUsedCapacity=0.25, numApps=2, numContainers=1 usedCapacity=0.25 absoluteUsedCapacity=0.25 used=<memory:2048, vCores:1> cluster=<memory:8192, vCores:8>
2013-11-27 22:36:19,495 INFO org.apache.hadoop.yarn.server.resourcemanager.scheduler.capacity.ParentQueue: Re-sorting assigned queue: root.default stats: default: capacity=1.0, absoluteCapacity=1.0, usedResources=<memory:3072, vCores:2>usedCapacity=0.375, absoluteUsedCapacity=0.375, numApps=2, numContainers=2
2013-11-27 22:36:19,496 INFO org.apache.hadoop.yarn.server.resourcemanager.scheduler.capacity.ParentQueue: assignedContainer queue=root usedCapacity=0.375 absoluteUsedCapacity=0.375 used=<memory:3072, vCores:2> cluster=<memory:8192, vCores:8>
2013-11-27 22:36:19,496 INFO org.apache.hadoop.yarn.server.resourcemanager.rmapp.attempt.RMAppAttemptImpl: Processing event for appattempt_1385613010171_0002_000001 of type CONTAINER_ALLOCATED
2013-11-27 22:36:20,085 INFO org.apache.hadoop.yarn.server.resourcemanager.rmcontainer.RMContainerImpl: container_1385613010171_0002_01_000003 Container Transitioned from NEW to ALLOCATED
2013-11-27 22:36:20,302 INFO org.apache.hadoop.yarn.server.resourcemanager.RMAuditLogger: USER=sakshi	OPERATION=AM Allocated Container	TARGET=SchedulerApp	RESULT=SUCCESS	APPID=application_1385613010171_0002	CONTAINERID=container_1385613010171_0002_01_000003
2013-11-27 22:36:20,302 INFO org.apache.hadoop.yarn.server.resourcemanager.scheduler.common.fica.FiCaSchedulerNode: Assigned container container_1385613010171_0002_01_000003 of capacity <memory:1024, vCores:1> on host ubuntusakshi:59487, which currently has 3 containers, <memory:4096, vCores:3> used and <memory:4096, vCores:5> available
2013-11-27 22:36:20,302 INFO org.apache.hadoop.yarn.server.resourcemanager.scheduler.capacity.LeafQueue: assignedContainer application=application_1385613010171_0002 container=Container: [ContainerId: container_1385613010171_0002_01_000003, NodeId: ubuntusakshi:59487, NodeHttpAddress: ubuntusakshi:8042, Resource: <memory:1024, vCores:1>, Priority: 20, Token: Token { kind: ContainerToken, service: 127.0.1.1:59487 }, ] containerId=container_1385613010171_0002_01_000003 queue=default: capacity=1.0, absoluteCapacity=1.0, usedResources=<memory:3072, vCores:2>usedCapacity=0.375, absoluteUsedCapacity=0.375, numApps=2, numContainers=2 usedCapacity=0.375 absoluteUsedCapacity=0.375 used=<memory:3072, vCores:2> cluster=<memory:8192, vCores:8>
2013-11-27 22:36:20,302 INFO org.apache.hadoop.yarn.server.resourcemanager.scheduler.capacity.ParentQueue: Re-sorting assigned queue: root.default stats: default: capacity=1.0, absoluteCapacity=1.0, usedResources=<memory:4096, vCores:3>usedCapacity=0.5, absoluteUsedCapacity=0.5, numApps=2, numContainers=3
2013-11-27 22:36:20,302 INFO org.apache.hadoop.yarn.server.resourcemanager.scheduler.capacity.ParentQueue: assignedContainer queue=root usedCapacity=0.5 absoluteUsedCapacity=0.5 used=<memory:4096, vCores:3> cluster=<memory:8192, vCores:8>
2013-11-27 22:36:20,306 INFO org.apache.hadoop.yarn.server.resourcemanager.rmcontainer.RMContainerImpl: container_1385613010171_0002_01_000004 Container Transitioned from NEW to ALLOCATED
2013-11-27 22:36:20,326 INFO org.apache.hadoop.yarn.server.resourcemanager.rmapp.attempt.RMAppAttemptImpl: Processing event for appattempt_1385613010171_0002_000001 of type CONTAINER_ALLOCATED
2013-11-27 22:36:20,716 INFO org.apache.hadoop.yarn.server.resourcemanager.rmapp.attempt.RMAppAttemptImpl: Processing event for appattempt_1385613010171_0002_000001 of type STATUS_UPDATE
2013-11-27 22:36:20,516 INFO org.apache.hadoop.yarn.server.resourcemanager.RMAuditLogger: USER=sakshi	OPERATION=AM Allocated Container	TARGET=SchedulerApp	RESULT=SUCCESS	APPID=application_1385613010171_0002	CONTAINERID=container_1385613010171_0002_01_000004
2013-11-27 22:36:20,716 INFO org.apache.hadoop.yarn.server.resourcemanager.scheduler.common.fica.FiCaSchedulerNode: Assigned container container_1385613010171_0002_01_000004 of capacity <memory:1024, vCores:1> on host ubuntusakshi:59487, which currently has 4 containers, <memory:5120, vCores:4> used and <memory:3072, vCores:4> available
2013-11-27 22:36:20,716 INFO org.apache.hadoop.yarn.server.resourcemanager.scheduler.capacity.LeafQueue: assignedContainer application=application_1385613010171_0002 container=Container: [ContainerId: container_1385613010171_0002_01_000004, NodeId: ubuntusakshi:59487, NodeHttpAddress: ubuntusakshi:8042, Resource: <memory:1024, vCores:1>, Priority: 20, Token: Token { kind: ContainerToken, service: 127.0.1.1:59487 }, ] containerId=container_1385613010171_0002_01_000004 queue=default: capacity=1.0, absoluteCapacity=1.0, usedResources=<memory:4096, vCores:3>usedCapacity=0.5, absoluteUsedCapacity=0.5, numApps=2, numContainers=3 usedCapacity=0.5 absoluteUsedCapacity=0.5 used=<memory:4096, vCores:3> cluster=<memory:8192, vCores:8>
2013-11-27 22:36:20,716 INFO org.apache.hadoop.yarn.server.resourcemanager.scheduler.capacity.ParentQueue: Re-sorting assigned queue: root.default stats: default: capacity=1.0, absoluteCapacity=1.0, usedResources=<memory:5120, vCores:4>usedCapacity=0.625, absoluteUsedCapacity=0.625, numApps=2, numContainers=4
2013-11-27 22:36:20,716 INFO org.apache.hadoop.yarn.server.resourcemanager.scheduler.capacity.ParentQueue: assignedContainer queue=root usedCapacity=0.625 absoluteUsedCapacity=0.625 used=<memory:5120, vCores:4> cluster=<memory:8192, vCores:8>
2013-11-27 22:36:20,717 INFO org.apache.hadoop.yarn.server.resourcemanager.rmcontainer.RMContainerImpl: container_1385613010171_0002_01_000005 Container Transitioned from NEW to ALLOCATED
2013-11-27 22:36:20,717 INFO org.apache.hadoop.yarn.server.resourcemanager.RMAuditLogger: USER=sakshi	OPERATION=AM Allocated Container	TARGET=SchedulerApp	RESULT=SUCCESS	APPID=application_1385613010171_0002	CONTAINERID=container_1385613010171_0002_01_000005
2013-11-27 22:36:20,717 INFO org.apache.hadoop.yarn.server.resourcemanager.scheduler.common.fica.FiCaSchedulerNode: Assigned container container_1385613010171_0002_01_000005 of capacity <memory:1024, vCores:1> on host ubuntusakshi:59487, which currently has 5 containers, <memory:6144, vCores:5> used and <memory:2048, vCores:3> available
2013-11-27 22:36:20,718 INFO org.apache.hadoop.yarn.server.resourcemanager.scheduler.capacity.LeafQueue: assignedContainer application=application_1385613010171_0002 container=Container: [ContainerId: container_1385613010171_0002_01_000005, NodeId: ubuntusakshi:59487, NodeHttpAddress: ubuntusakshi:8042, Resource: <memory:1024, vCores:1>, Priority: 20, Token: Token { kind: ContainerToken, service: 127.0.1.1:59487 }, ] containerId=container_1385613010171_0002_01_000005 queue=default: capacity=1.0, absoluteCapacity=1.0, usedResources=<memory:5120, vCores:4>usedCapacity=0.625, absoluteUsedCapacity=0.625, numApps=2, numContainers=4 usedCapacity=0.625 absoluteUsedCapacity=0.625 used=<memory:5120, vCores:4> cluster=<memory:8192, vCores:8>
2013-11-27 22:36:20,718 INFO org.apache.hadoop.yarn.server.resourcemanager.scheduler.capacity.ParentQueue: Re-sorting assigned queue: root.default stats: default: capacity=1.0, absoluteCapacity=1.0, usedResources=<memory:6144, vCores:5>usedCapacity=0.75, absoluteUsedCapacity=0.75, numApps=2, numContainers=5
2013-11-27 22:36:20,718 INFO org.apache.hadoop.yarn.server.resourcemanager.scheduler.capacity.ParentQueue: assignedContainer queue=root usedCapacity=0.75 absoluteUsedCapacity=0.75 used=<memory:6144, vCores:5> cluster=<memory:8192, vCores:8>
2013-11-27 22:36:20,719 INFO org.apache.hadoop.yarn.server.resourcemanager.rmcontainer.RMContainerImpl: container_1385613010171_0002_01_000006 Container Transitioned from NEW to ALLOCATED
2013-11-27 22:36:20,719 INFO org.apache.hadoop.yarn.server.resourcemanager.RMAuditLogger: USER=sakshi	OPERATION=AM Allocated Container	TARGET=SchedulerApp	RESULT=SUCCESS	APPID=application_1385613010171_0002	CONTAINERID=container_1385613010171_0002_01_000006
2013-11-27 22:36:20,719 INFO org.apache.hadoop.yarn.server.resourcemanager.scheduler.common.fica.FiCaSchedulerNode: Assigned container container_1385613010171_0002_01_000006 of capacity <memory:1024, vCores:1> on host ubuntusakshi:59487, which currently has 6 containers, <memory:7168, vCores:6> used and <memory:1024, vCores:2> available
2013-11-27 22:36:20,719 INFO org.apache.hadoop.yarn.server.resourcemanager.scheduler.capacity.LeafQueue: assignedContainer application=application_1385613010171_0002 container=Container: [ContainerId: container_1385613010171_0002_01_000006, NodeId: ubuntusakshi:59487, NodeHttpAddress: ubuntusakshi:8042, Resource: <memory:1024, vCores:1>, Priority: 20, Token: Token { kind: ContainerToken, service: 127.0.1.1:59487 }, ] containerId=container_1385613010171_0002_01_000006 queue=default: capacity=1.0, absoluteCapacity=1.0, usedResources=<memory:6144, vCores:5>usedCapacity=0.75, absoluteUsedCapacity=0.75, numApps=2, numContainers=5 usedCapacity=0.75 absoluteUsedCapacity=0.75 used=<memory:6144, vCores:5> cluster=<memory:8192, vCores:8>
2013-11-27 22:36:20,719 INFO org.apache.hadoop.yarn.server.resourcemanager.scheduler.capacity.ParentQueue: Re-sorting assigned queue: root.default stats: default: capacity=1.0, absoluteCapacity=1.0, usedResources=<memory:7168, vCores:6>usedCapacity=0.875, absoluteUsedCapacity=0.875, numApps=2, numContainers=6
2013-11-27 22:36:20,719 INFO org.apache.hadoop.yarn.server.resourcemanager.scheduler.capacity.ParentQueue: assignedContainer queue=root usedCapacity=0.875 absoluteUsedCapacity=0.875 used=<memory:7168, vCores:6> cluster=<memory:8192, vCores:8>
2013-11-27 22:36:20,720 INFO org.apache.hadoop.yarn.server.resourcemanager.rmapp.attempt.RMAppAttemptImpl: Processing event for appattempt_1385613010171_0002_000001 of type CONTAINER_ALLOCATED
2013-11-27 22:36:20,720 INFO org.apache.hadoop.yarn.server.resourcemanager.rmapp.attempt.RMAppAttemptImpl: Processing event for appattempt_1385613010171_0002_000001 of type CONTAINER_ALLOCATED
2013-11-27 22:36:20,720 INFO org.apache.hadoop.yarn.server.resourcemanager.rmapp.attempt.RMAppAttemptImpl: Processing event for appattempt_1385613010171_0002_000001 of type CONTAINER_ACQUIRED
2013-11-27 22:36:20,720 INFO org.apache.hadoop.yarn.server.resourcemanager.rmcontainer.RMContainerImpl: container_1385613010171_0002_01_000002 Container Transitioned from ALLOCATED to ACQUIRED
2013-11-27 22:36:20,721 INFO org.apache.hadoop.yarn.server.resourcemanager.rmcontainer.RMContainerImpl: container_1385613010171_0002_01_000003 Container Transitioned from ALLOCATED to ACQUIRED
2013-11-27 22:36:20,721 INFO org.apache.hadoop.yarn.server.resourcemanager.rmapp.attempt.RMAppAttemptImpl: Processing event for appattempt_1385613010171_0002_000001 of type CONTAINER_ACQUIRED
2013-11-27 22:36:20,721 INFO org.apache.hadoop.yarn.server.resourcemanager.rmcontainer.RMContainerImpl: container_1385613010171_0002_01_000004 Container Transitioned from ALLOCATED to ACQUIRED
2013-11-27 22:36:20,721 INFO org.apache.hadoop.yarn.server.resourcemanager.rmapp.attempt.RMAppAttemptImpl: Processing event for appattempt_1385613010171_0002_000001 of type CONTAINER_ACQUIRED
2013-11-27 22:36:20,721 INFO org.apache.hadoop.yarn.server.resourcemanager.rmcontainer.RMContainerImpl: container_1385613010171_0002_01_000005 Container Transitioned from ALLOCATED to ACQUIRED
2013-11-27 22:36:20,721 INFO org.apache.hadoop.yarn.server.resourcemanager.rmapp.attempt.RMAppAttemptImpl: Processing event for appattempt_1385613010171_0002_000001 of type CONTAINER_ACQUIRED
2013-11-27 22:36:20,722 INFO org.apache.hadoop.yarn.server.resourcemanager.rmcontainer.RMContainerImpl: container_1385613010171_0002_01_000006 Container Transitioned from ALLOCATED to ACQUIRED
2013-11-27 22:36:20,722 INFO org.apache.hadoop.yarn.server.resourcemanager.rmapp.attempt.RMAppAttemptImpl: Processing event for appattempt_1385613010171_0002_000001 of type CONTAINER_ACQUIRED
2013-11-27 22:36:25,088 INFO org.apache.hadoop.yarn.server.resourcemanager.rmcontainer.RMContainerImpl: container_1385613010171_0002_01_000002 Container Transitioned from ACQUIRED to RUNNING
2013-11-27 22:36:25,120 INFO org.apache.hadoop.yarn.server.resourcemanager.rmcontainer.RMContainerImpl: container_1385613010171_0002_01_000003 Container Transitioned from ACQUIRED to RUNNING
2013-11-27 22:36:25,120 INFO org.apache.hadoop.yarn.server.resourcemanager.rmcontainer.RMContainerImpl: container_1385613010171_0002_01_000005 Container Transitioned from ACQUIRED to RUNNING
2013-11-27 22:36:25,088 INFO org.apache.hadoop.yarn.server.resourcemanager.rmapp.attempt.RMAppAttemptImpl: Processing event for appattempt_1385613010171_0002_000001 of type STATUS_UPDATE
2013-11-27 22:36:25,121 INFO org.apache.hadoop.yarn.server.resourcemanager.rmcontainer.RMContainerImpl: container_1385613010171_0002_01_000006 Container Transitioned from ACQUIRED to RUNNING
2013-11-27 22:36:25,121 INFO org.apache.hadoop.yarn.server.resourcemanager.scheduler.AppSchedulingInfo: checking for deactivate... 
2013-11-27 22:36:26,614 INFO org.apache.hadoop.yarn.server.resourcemanager.rmapp.attempt.RMAppAttemptImpl: Processing event for appattempt_1385613010171_0002_000001 of type STATUS_UPDATE
2013-11-27 22:36:26,735 INFO org.apache.hadoop.yarn.server.resourcemanager.rmcontainer.RMContainerImpl: container_1385613010171_0002_01_000004 Container Transitioned from ACQUIRED to RUNNING
2013-11-27 22:36:28,154 INFO org.apache.hadoop.yarn.server.resourcemanager.rmapp.attempt.RMAppAttemptImpl: Processing event for appattempt_1385613010171_0002_000001 of type STATUS_UPDATE
2013-11-27 22:36:29,375 INFO org.apache.hadoop.yarn.server.resourcemanager.rmapp.attempt.RMAppAttemptImpl: Processing event for appattempt_1385613010171_0002_000001 of type STATUS_UPDATE
2013-11-27 22:36:31,120 INFO org.apache.hadoop.yarn.server.resourcemanager.rmapp.attempt.RMAppAttemptImpl: Processing event for appattempt_1385613010171_0002_000001 of type STATUS_UPDATE
2013-11-27 22:36:33,297 INFO org.apache.hadoop.yarn.server.resourcemanager.rmapp.attempt.RMAppAttemptImpl: Processing event for appattempt_1385613010171_0002_000001 of type STATUS_UPDATE
2013-11-27 22:36:36,891 INFO org.apache.hadoop.yarn.server.resourcemanager.rmapp.attempt.RMAppAttemptImpl: Processing event for appattempt_1385613010171_0002_000001 of type STATUS_UPDATE
2013-11-27 22:36:42,275 INFO org.apache.hadoop.yarn.server.resourcemanager.rmapp.attempt.RMAppAttemptImpl: Processing event for appattempt_1385613010171_0002_000001 of type STATUS_UPDATE
2013-11-27 22:36:49,239 INFO org.apache.hadoop.yarn.server.resourcemanager.rmapp.attempt.RMAppAttemptImpl: Processing event for appattempt_1385613010171_0002_000001 of type STATUS_UPDATE
2013-11-27 22:36:50,689 INFO org.apache.hadoop.yarn.server.resourcemanager.rmapp.attempt.RMAppAttemptImpl: Processing event for appattempt_1385613010171_0002_000001 of type STATUS_UPDATE
2013-11-27 22:36:51,812 INFO org.apache.hadoop.yarn.server.resourcemanager.rmapp.attempt.RMAppAttemptImpl: Processing event for appattempt_1385613010171_0002_000001 of type STATUS_UPDATE
2013-11-27 22:36:52,927 INFO org.apache.hadoop.yarn.server.resourcemanager.rmapp.attempt.RMAppAttemptImpl: Processing event for appattempt_1385613010171_0002_000001 of type STATUS_UPDATE
2013-11-27 22:36:54,300 INFO org.apache.hadoop.yarn.server.resourcemanager.rmapp.attempt.RMAppAttemptImpl: Processing event for appattempt_1385613010171_0002_000001 of type STATUS_UPDATE
2013-11-27 22:36:55,452 INFO org.apache.hadoop.yarn.server.resourcemanager.rmapp.attempt.RMAppAttemptImpl: Processing event for appattempt_1385613010171_0002_000001 of type STATUS_UPDATE
2013-11-27 22:36:56,559 INFO org.apache.hadoop.yarn.server.resourcemanager.rmapp.attempt.RMAppAttemptImpl: Processing event for appattempt_1385613010171_0002_000001 of type STATUS_UPDATE
2013-11-27 22:36:57,600 INFO org.apache.hadoop.yarn.server.resourcemanager.rmapp.attempt.RMAppAttemptImpl: Processing event for appattempt_1385613010171_0002_000001 of type STATUS_UPDATE
2013-11-27 22:36:58,921 INFO org.apache.hadoop.yarn.server.resourcemanager.rmapp.attempt.RMAppAttemptImpl: Processing event for appattempt_1385613010171_0002_000001 of type STATUS_UPDATE
2013-11-27 22:37:00,122 INFO org.apache.hadoop.yarn.server.resourcemanager.rmapp.attempt.RMAppAttemptImpl: Processing event for appattempt_1385613010171_0002_000001 of type STATUS_UPDATE
2013-11-27 22:37:01,335 INFO org.apache.hadoop.yarn.server.resourcemanager.rmapp.attempt.RMAppAttemptImpl: Processing event for appattempt_1385613010171_0002_000001 of type STATUS_UPDATE
2013-11-27 22:37:02,536 INFO org.apache.hadoop.yarn.server.resourcemanager.rmapp.attempt.RMAppAttemptImpl: Processing event for appattempt_1385613010171_0002_000001 of type STATUS_UPDATE
2013-11-27 22:37:04,025 INFO org.apache.hadoop.yarn.server.resourcemanager.rmapp.attempt.RMAppAttemptImpl: Processing event for appattempt_1385613010171_0002_000001 of type STATUS_UPDATE
2013-11-27 22:37:05,273 INFO org.apache.hadoop.yarn.server.resourcemanager.rmapp.attempt.RMAppAttemptImpl: Processing event for appattempt_1385613010171_0002_000001 of type STATUS_UPDATE
2013-11-27 22:37:06,470 INFO org.apache.hadoop.yarn.server.resourcemanager.rmapp.attempt.RMAppAttemptImpl: Processing event for appattempt_1385613010171_0002_000001 of type STATUS_UPDATE
2013-11-27 22:37:07,835 INFO org.apache.hadoop.yarn.server.resourcemanager.rmapp.attempt.RMAppAttemptImpl: Processing event for appattempt_1385613010171_0002_000001 of type STATUS_UPDATE
2013-11-27 22:37:08,992 INFO org.apache.hadoop.yarn.server.resourcemanager.rmapp.attempt.RMAppAttemptImpl: Processing event for appattempt_1385613010171_0002_000001 of type STATUS_UPDATE
2013-11-27 22:37:10,480 INFO org.apache.hadoop.yarn.server.resourcemanager.rmapp.attempt.RMAppAttemptImpl: Processing event for appattempt_1385613010171_0002_000001 of type STATUS_UPDATE
2013-11-27 22:37:11,992 INFO org.apache.hadoop.yarn.server.resourcemanager.rmapp.attempt.RMAppAttemptImpl: Processing event for appattempt_1385613010171_0002_000001 of type STATUS_UPDATE
2013-11-27 22:37:13,438 INFO org.apache.hadoop.yarn.server.resourcemanager.rmapp.attempt.RMAppAttemptImpl: Processing event for appattempt_1385613010171_0002_000001 of type STATUS_UPDATE
2013-11-27 22:37:16,061 INFO org.apache.hadoop.yarn.server.resourcemanager.rmapp.attempt.RMAppAttemptImpl: Processing event for appattempt_1385613010171_0002_000001 of type STATUS_UPDATE
2013-11-27 22:37:18,499 INFO org.apache.hadoop.yarn.server.resourcemanager.rmapp.attempt.RMAppAttemptImpl: Processing event for appattempt_1385613010171_0002_000001 of type STATUS_UPDATE
2013-11-27 22:37:20,208 INFO org.apache.hadoop.yarn.server.resourcemanager.rmapp.attempt.RMAppAttemptImpl: Processing event for appattempt_1385613010171_0002_000001 of type STATUS_UPDATE
2013-11-27 22:37:22,028 INFO org.apache.hadoop.yarn.server.resourcemanager.rmapp.attempt.RMAppAttemptImpl: Processing event for appattempt_1385613010171_0002_000001 of type STATUS_UPDATE
2013-11-27 22:37:24,261 INFO org.apache.hadoop.yarn.server.resourcemanager.rmapp.attempt.RMAppAttemptImpl: Processing event for appattempt_1385613010171_0002_000001 of type STATUS_UPDATE
2013-11-27 22:37:27,833 INFO org.apache.hadoop.yarn.server.resourcemanager.rmapp.attempt.RMAppAttemptImpl: Processing event for appattempt_1385613010171_0002_000001 of type STATUS_UPDATE
2013-11-27 22:37:29,615 INFO org.apache.hadoop.yarn.server.resourcemanager.rmapp.attempt.RMAppAttemptImpl: Processing event for appattempt_1385613010171_0002_000001 of type STATUS_UPDATE
2013-11-27 22:37:30,970 INFO org.apache.hadoop.yarn.server.resourcemanager.rmapp.attempt.RMAppAttemptImpl: Processing event for appattempt_1385613010171_0002_000001 of type STATUS_UPDATE
2013-11-27 22:37:32,194 INFO org.apache.hadoop.yarn.server.resourcemanager.rmapp.attempt.RMAppAttemptImpl: Processing event for appattempt_1385613010171_0002_000001 of type STATUS_UPDATE
2013-11-27 22:37:33,433 INFO org.apache.hadoop.yarn.server.resourcemanager.rmapp.attempt.RMAppAttemptImpl: Processing event for appattempt_1385613010171_0002_000001 of type STATUS_UPDATE
2013-11-27 22:37:34,830 INFO org.apache.hadoop.yarn.server.resourcemanager.rmapp.attempt.RMAppAttemptImpl: Processing event for appattempt_1385613010171_0002_000001 of type STATUS_UPDATE
2013-11-27 22:37:36,961 INFO org.apache.hadoop.yarn.server.resourcemanager.rmapp.attempt.RMAppAttemptImpl: Processing event for appattempt_1385613010171_0002_000001 of type STATUS_UPDATE
2013-11-27 22:38:00,765 INFO org.apache.hadoop.yarn.server.resourcemanager.rmapp.attempt.RMAppAttemptImpl: Processing event for appattempt_1385613010171_0002_000001 of type STATUS_UPDATE
2013-11-27 22:39:12,982 INFO SecurityLogger.org.apache.hadoop.ipc.Server: Auth successful for appattempt_1385613010171_0002_000001 (auth:SIMPLE)
2013-11-27 22:39:13,176 INFO org.apache.hadoop.yarn.server.resourcemanager.rmapp.attempt.RMAppAttemptImpl: Processing event for appattempt_1385613010171_0002_000001 of type STATUS_UPDATE
2013-11-27 22:39:17,755 INFO org.apache.hadoop.yarn.server.resourcemanager.rmapp.attempt.RMAppAttemptImpl: Processing event for appattempt_1385613010171_0002_000001 of type STATUS_UPDATE
2013-11-27 22:39:21,498 INFO org.apache.hadoop.yarn.server.resourcemanager.rmapp.attempt.RMAppAttemptImpl: Processing event for appattempt_1385613010171_0002_000001 of type STATUS_UPDATE
2013-11-27 22:39:28,379 INFO org.apache.hadoop.yarn.server.resourcemanager.rmapp.attempt.RMAppAttemptImpl: Processing event for appattempt_1385613010171_0002_000001 of type STATUS_UPDATE
2013-11-27 22:39:29,601 INFO org.apache.hadoop.yarn.server.resourcemanager.rmapp.attempt.RMAppAttemptImpl: Processing event for appattempt_1385613010171_0002_000001 of type STATUS_UPDATE
2013-11-27 22:39:32,364 INFO org.apache.hadoop.yarn.server.resourcemanager.rmapp.attempt.RMAppAttemptImpl: Processing event for appattempt_1385613010171_0002_000001 of type STATUS_UPDATE
2013-11-27 22:39:37,934 INFO org.apache.hadoop.yarn.server.resourcemanager.rmapp.attempt.RMAppAttemptImpl: Processing event for appattempt_1385613010171_0002_000001 of type STATUS_UPDATE
2013-11-27 22:39:51,532 INFO SecurityLogger.org.apache.hadoop.ipc.Server: Auth successful for appattempt_1385613010171_0002_000001 (auth:SIMPLE)
2013-11-27 22:40:09,546 INFO org.apache.hadoop.yarn.server.resourcemanager.rmapp.attempt.RMAppAttemptImpl: Processing event for appattempt_1385613010171_0002_000001 of type STATUS_UPDATE
2013-11-27 22:40:21,681 INFO SecurityLogger.org.apache.hadoop.ipc.Server: Auth successful for appattempt_1385613010171_0002_000001 (auth:SIMPLE)
2013-11-27 22:40:22,377 INFO org.apache.hadoop.yarn.server.resourcemanager.rmapp.attempt.RMAppAttemptImpl: Processing event for appattempt_1385613010171_0002_000001 of type STATUS_UPDATE
2013-11-27 22:40:23,915 INFO org.apache.hadoop.yarn.server.resourcemanager.rmapp.attempt.RMAppAttemptImpl: Processing event for appattempt_1385613010171_0002_000001 of type CONTAINER_FINISHED
2013-11-27 22:40:23,918 INFO org.apache.hadoop.yarn.server.resourcemanager.rmcontainer.RMContainerImpl: container_1385613010171_0002_01_000004 Container Transitioned from RUNNING to COMPLETED
2013-11-27 22:40:24,042 INFO org.apache.hadoop.yarn.server.resourcemanager.scheduler.common.fica.FiCaSchedulerApp: Completed container: container_1385613010171_0002_01_000004 in state: COMPLETED event:FINISHED
2013-11-27 22:40:24,049 INFO org.apache.hadoop.yarn.server.resourcemanager.RMAuditLogger: USER=sakshi	OPERATION=AM Released Container	TARGET=SchedulerApp	RESULT=SUCCESS	APPID=application_1385613010171_0002	CONTAINERID=container_1385613010171_0002_01_000004
2013-11-27 22:40:24,062 INFO org.apache.hadoop.yarn.server.resourcemanager.scheduler.common.fica.FiCaSchedulerNode: Released container container_1385613010171_0002_01_000004 of capacity <memory:1024, vCores:1> on host ubuntusakshi:59487, which currently has 5 containers, <memory:6144, vCores:5> used and <memory:2048, vCores:3> available, release resources=true
2013-11-27 22:40:24,062 INFO org.apache.hadoop.yarn.server.resourcemanager.scheduler.capacity.LeafQueue: default used=<memory:6144, vCores:5> numContainers=5 user=sakshi user-resources=<memory:6144, vCores:5>
2013-11-27 22:40:24,078 INFO org.apache.hadoop.yarn.server.resourcemanager.scheduler.capacity.LeafQueue: completedContainer container=Container: [ContainerId: container_1385613010171_0002_01_000004, NodeId: ubuntusakshi:59487, NodeHttpAddress: ubuntusakshi:8042, Resource: <memory:1024, vCores:1>, Priority: 20, Token: Token { kind: ContainerToken, service: 127.0.1.1:59487 }, ] resource=<memory:1024, vCores:1> queue=default: capacity=1.0, absoluteCapacity=1.0, usedResources=<memory:6144, vCores:5>usedCapacity=0.75, absoluteUsedCapacity=0.75, numApps=2, numContainers=5 usedCapacity=0.75 absoluteUsedCapacity=0.75 used=<memory:6144, vCores:5> cluster=<memory:8192, vCores:8>
2013-11-27 22:40:24,092 INFO org.apache.hadoop.yarn.server.resourcemanager.scheduler.capacity.ParentQueue: completedContainer queue=root usedCapacity=0.75 absoluteUsedCapacity=0.75 used=<memory:6144, vCores:5> cluster=<memory:8192, vCores:8>
2013-11-27 22:40:24,093 INFO org.apache.hadoop.yarn.server.resourcemanager.scheduler.capacity.ParentQueue: Re-sorting completed queue: root.default stats: default: capacity=1.0, absoluteCapacity=1.0, usedResources=<memory:6144, vCores:5>usedCapacity=0.75, absoluteUsedCapacity=0.75, numApps=2, numContainers=5
2013-11-27 22:40:24,093 INFO org.apache.hadoop.yarn.server.resourcemanager.scheduler.capacity.CapacityScheduler: Application appattempt_1385613010171_0002_000001 released container container_1385613010171_0002_01_000004 on node: host: ubuntusakshi:59487 #containers=5 available=2048 used=6144 with event: FINISHED
2013-11-27 22:40:24,094 INFO org.apache.hadoop.yarn.server.resourcemanager.rmapp.attempt.RMAppAttemptImpl: Processing event for appattempt_1385613010171_0002_000001 of type CONTAINER_FINISHED
2013-11-27 22:40:24,277 INFO org.apache.hadoop.yarn.server.resourcemanager.rmcontainer.RMContainerImpl: container_1385613010171_0002_01_000006 Container Transitioned from RUNNING to COMPLETED
2013-11-27 22:40:24,277 INFO org.apache.hadoop.yarn.server.resourcemanager.scheduler.common.fica.FiCaSchedulerApp: Completed container: container_1385613010171_0002_01_000006 in state: COMPLETED event:FINISHED
2013-11-27 22:40:24,279 INFO org.apache.hadoop.yarn.server.resourcemanager.RMAuditLogger: USER=sakshi	OPERATION=AM Released Container	TARGET=SchedulerApp	RESULT=SUCCESS	APPID=application_1385613010171_0002	CONTAINERID=container_1385613010171_0002_01_000006
2013-11-27 22:40:24,290 INFO org.apache.hadoop.yarn.server.resourcemanager.scheduler.common.fica.FiCaSchedulerNode: Released container container_1385613010171_0002_01_000006 of capacity <memory:1024, vCores:1> on host ubuntusakshi:59487, which currently has 4 containers, <memory:5120, vCores:4> used and <memory:3072, vCores:4> available, release resources=true
2013-11-27 22:40:24,291 INFO org.apache.hadoop.yarn.server.resourcemanager.scheduler.capacity.LeafQueue: default used=<memory:5120, vCores:4> numContainers=4 user=sakshi user-resources=<memory:5120, vCores:4>
2013-11-27 22:40:24,291 INFO org.apache.hadoop.yarn.server.resourcemanager.scheduler.capacity.LeafQueue: completedContainer container=Container: [ContainerId: container_1385613010171_0002_01_000006, NodeId: ubuntusakshi:59487, NodeHttpAddress: ubuntusakshi:8042, Resource: <memory:1024, vCores:1>, Priority: 20, Token: Token { kind: ContainerToken, service: 127.0.1.1:59487 }, ] resource=<memory:1024, vCores:1> queue=default: capacity=1.0, absoluteCapacity=1.0, usedResources=<memory:5120, vCores:4>usedCapacity=0.625, absoluteUsedCapacity=0.625, numApps=2, numContainers=4 usedCapacity=0.625 absoluteUsedCapacity=0.625 used=<memory:5120, vCores:4> cluster=<memory:8192, vCores:8>
2013-11-27 22:40:24,291 INFO org.apache.hadoop.yarn.server.resourcemanager.scheduler.capacity.ParentQueue: completedContainer queue=root usedCapacity=0.625 absoluteUsedCapacity=0.625 used=<memory:5120, vCores:4> cluster=<memory:8192, vCores:8>
2013-11-27 22:40:24,364 INFO org.apache.hadoop.yarn.server.resourcemanager.scheduler.capacity.ParentQueue: Re-sorting completed queue: root.default stats: default: capacity=1.0, absoluteCapacity=1.0, usedResources=<memory:5120, vCores:4>usedCapacity=0.625, absoluteUsedCapacity=0.625, numApps=2, numContainers=4
2013-11-27 22:40:24,365 INFO org.apache.hadoop.yarn.server.resourcemanager.scheduler.capacity.CapacityScheduler: Application appattempt_1385613010171_0002_000001 released container container_1385613010171_0002_01_000006 on node: host: ubuntusakshi:59487 #containers=4 available=3072 used=5120 with event: FINISHED
2013-11-27 22:40:24,695 INFO org.apache.hadoop.yarn.server.resourcemanager.rmcontainer.RMContainerImpl: container_1385613010171_0002_01_000002 Container Transitioned from RUNNING to COMPLETED
2013-11-27 22:40:24,695 INFO org.apache.hadoop.yarn.server.resourcemanager.scheduler.common.fica.FiCaSchedulerApp: Completed container: container_1385613010171_0002_01_000002 in state: COMPLETED event:FINISHED
2013-11-27 22:40:24,695 INFO org.apache.hadoop.yarn.server.resourcemanager.rmapp.attempt.RMAppAttemptImpl: Processing event for appattempt_1385613010171_0002_000001 of type CONTAINER_FINISHED
2013-11-27 22:40:24,717 INFO org.apache.hadoop.yarn.server.resourcemanager.RMAuditLogger: USER=sakshi	OPERATION=AM Released Container	TARGET=SchedulerApp	RESULT=SUCCESS	APPID=application_1385613010171_0002	CONTAINERID=container_1385613010171_0002_01_000002
2013-11-27 22:40:24,717 INFO org.apache.hadoop.yarn.server.resourcemanager.scheduler.common.fica.FiCaSchedulerNode: Released container container_1385613010171_0002_01_000002 of capacity <memory:1024, vCores:1> on host ubuntusakshi:59487, which currently has 3 containers, <memory:4096, vCores:3> used and <memory:4096, vCores:5> available, release resources=true
2013-11-27 22:40:24,717 INFO org.apache.hadoop.yarn.server.resourcemanager.scheduler.capacity.LeafQueue: default used=<memory:4096, vCores:3> numContainers=3 user=sakshi user-resources=<memory:4096, vCores:3>
2013-11-27 22:40:24,717 INFO org.apache.hadoop.yarn.server.resourcemanager.scheduler.capacity.LeafQueue: completedContainer container=Container: [ContainerId: container_1385613010171_0002_01_000002, NodeId: ubuntusakshi:59487, NodeHttpAddress: ubuntusakshi:8042, Resource: <memory:1024, vCores:1>, Priority: 20, Token: Token { kind: ContainerToken, service: 127.0.1.1:59487 }, ] resource=<memory:1024, vCores:1> queue=default: capacity=1.0, absoluteCapacity=1.0, usedResources=<memory:4096, vCores:3>usedCapacity=0.5, absoluteUsedCapacity=0.5, numApps=2, numContainers=3 usedCapacity=0.5 absoluteUsedCapacity=0.5 used=<memory:4096, vCores:3> cluster=<memory:8192, vCores:8>
2013-11-27 22:40:24,718 INFO org.apache.hadoop.yarn.server.resourcemanager.scheduler.capacity.ParentQueue: completedContainer queue=root usedCapacity=0.5 absoluteUsedCapacity=0.5 used=<memory:4096, vCores:3> cluster=<memory:8192, vCores:8>
2013-11-27 22:40:24,718 INFO org.apache.hadoop.yarn.server.resourcemanager.scheduler.capacity.ParentQueue: Re-sorting completed queue: root.default stats: default: capacity=1.0, absoluteCapacity=1.0, usedResources=<memory:4096, vCores:3>usedCapacity=0.5, absoluteUsedCapacity=0.5, numApps=2, numContainers=3
2013-11-27 22:40:24,718 INFO org.apache.hadoop.yarn.server.resourcemanager.scheduler.capacity.CapacityScheduler: Application appattempt_1385613010171_0002_000001 released container container_1385613010171_0002_01_000002 on node: host: ubuntusakshi:59487 #containers=3 available=4096 used=4096 with event: FINISHED
2013-11-27 22:40:24,719 INFO org.apache.hadoop.yarn.server.resourcemanager.rmapp.attempt.RMAppAttemptImpl: Processing event for appattempt_1385613010171_0002_000001 of type CONTAINER_FINISHED
2013-11-27 22:40:24,719 INFO org.apache.hadoop.yarn.server.resourcemanager.rmcontainer.RMContainerImpl: container_1385613010171_0002_01_000003 Container Transitioned from RUNNING to COMPLETED
2013-11-27 22:40:24,719 INFO org.apache.hadoop.yarn.server.resourcemanager.scheduler.common.fica.FiCaSchedulerApp: Completed container: container_1385613010171_0002_01_000003 in state: COMPLETED event:FINISHED
2013-11-27 22:40:24,720 INFO org.apache.hadoop.yarn.server.resourcemanager.RMAuditLogger: USER=sakshi	OPERATION=AM Released Container	TARGET=SchedulerApp	RESULT=SUCCESS	APPID=application_1385613010171_0002	CONTAINERID=container_1385613010171_0002_01_000003
2013-11-27 22:40:24,721 INFO org.apache.hadoop.yarn.server.resourcemanager.scheduler.common.fica.FiCaSchedulerNode: Released container container_1385613010171_0002_01_000003 of capacity <memory:1024, vCores:1> on host ubuntusakshi:59487, which currently has 2 containers, <memory:3072, vCores:2> used and <memory:5120, vCores:6> available, release resources=true
2013-11-27 22:40:24,721 INFO org.apache.hadoop.yarn.server.resourcemanager.scheduler.capacity.LeafQueue: default used=<memory:3072, vCores:2> numContainers=2 user=sakshi user-resources=<memory:3072, vCores:2>
2013-11-27 22:40:24,734 INFO org.apache.hadoop.yarn.server.resourcemanager.scheduler.capacity.LeafQueue: completedContainer container=Container: [ContainerId: container_1385613010171_0002_01_000003, NodeId: ubuntusakshi:59487, NodeHttpAddress: ubuntusakshi:8042, Resource: <memory:1024, vCores:1>, Priority: 20, Token: Token { kind: ContainerToken, service: 127.0.1.1:59487 }, ] resource=<memory:1024, vCores:1> queue=default: capacity=1.0, absoluteCapacity=1.0, usedResources=<memory:3072, vCores:2>usedCapacity=0.375, absoluteUsedCapacity=0.375, numApps=2, numContainers=2 usedCapacity=0.375 absoluteUsedCapacity=0.375 used=<memory:3072, vCores:2> cluster=<memory:8192, vCores:8>
2013-11-27 22:40:24,735 INFO org.apache.hadoop.yarn.server.resourcemanager.scheduler.capacity.ParentQueue: completedContainer queue=root usedCapacity=0.375 absoluteUsedCapacity=0.375 used=<memory:3072, vCores:2> cluster=<memory:8192, vCores:8>
2013-11-27 22:40:24,735 INFO org.apache.hadoop.yarn.server.resourcemanager.scheduler.capacity.ParentQueue: Re-sorting completed queue: root.default stats: default: capacity=1.0, absoluteCapacity=1.0, usedResources=<memory:3072, vCores:2>usedCapacity=0.375, absoluteUsedCapacity=0.375, numApps=2, numContainers=2
2013-11-27 22:40:24,735 INFO org.apache.hadoop.yarn.server.resourcemanager.scheduler.capacity.CapacityScheduler: Application appattempt_1385613010171_0002_000001 released container container_1385613010171_0002_01_000003 on node: host: ubuntusakshi:59487 #containers=2 available=5120 used=3072 with event: FINISHED
2013-11-27 22:40:24,735 INFO org.apache.hadoop.yarn.server.resourcemanager.rmapp.attempt.RMAppAttemptImpl: Processing event for appattempt_1385613010171_0002_000001 of type CONTAINER_FINISHED
2013-11-27 22:40:24,736 INFO org.apache.hadoop.yarn.server.resourcemanager.rmcontainer.RMContainerImpl: container_1385613010171_0002_01_000005 Container Transitioned from RUNNING to COMPLETED
2013-11-27 22:40:24,736 INFO org.apache.hadoop.yarn.server.resourcemanager.scheduler.common.fica.FiCaSchedulerApp: Completed container: container_1385613010171_0002_01_000005 in state: COMPLETED event:FINISHED
2013-11-27 22:40:24,736 INFO org.apache.hadoop.yarn.server.resourcemanager.RMAuditLogger: USER=sakshi	OPERATION=AM Released Container	TARGET=SchedulerApp	RESULT=SUCCESS	APPID=application_1385613010171_0002	CONTAINERID=container_1385613010171_0002_01_000005
2013-11-27 22:40:24,736 INFO org.apache.hadoop.yarn.server.resourcemanager.scheduler.common.fica.FiCaSchedulerNode: Released container container_1385613010171_0002_01_000005 of capacity <memory:1024, vCores:1> on host ubuntusakshi:59487, which currently has 1 containers, <memory:2048, vCores:1> used and <memory:6144, vCores:7> available, release resources=true
2013-11-27 22:40:24,736 INFO org.apache.hadoop.yarn.server.resourcemanager.scheduler.capacity.LeafQueue: default used=<memory:2048, vCores:1> numContainers=1 user=sakshi user-resources=<memory:2048, vCores:1>
2013-11-27 22:40:24,736 INFO org.apache.hadoop.yarn.server.resourcemanager.scheduler.capacity.LeafQueue: completedContainer container=Container: [ContainerId: container_1385613010171_0002_01_000005, NodeId: ubuntusakshi:59487, NodeHttpAddress: ubuntusakshi:8042, Resource: <memory:1024, vCores:1>, Priority: 20, Token: Token { kind: ContainerToken, service: 127.0.1.1:59487 }, ] resource=<memory:1024, vCores:1> queue=default: capacity=1.0, absoluteCapacity=1.0, usedResources=<memory:2048, vCores:1>usedCapacity=0.25, absoluteUsedCapacity=0.25, numApps=2, numContainers=1 usedCapacity=0.25 absoluteUsedCapacity=0.25 used=<memory:2048, vCores:1> cluster=<memory:8192, vCores:8>
2013-11-27 22:40:24,737 INFO org.apache.hadoop.yarn.server.resourcemanager.scheduler.capacity.ParentQueue: completedContainer queue=root usedCapacity=0.25 absoluteUsedCapacity=0.25 used=<memory:2048, vCores:1> cluster=<memory:8192, vCores:8>
2013-11-27 22:40:24,737 INFO org.apache.hadoop.yarn.server.resourcemanager.scheduler.capacity.ParentQueue: Re-sorting completed queue: root.default stats: default: capacity=1.0, absoluteCapacity=1.0, usedResources=<memory:2048, vCores:1>usedCapacity=0.25, absoluteUsedCapacity=0.25, numApps=2, numContainers=1
2013-11-27 22:40:24,737 INFO org.apache.hadoop.yarn.server.resourcemanager.scheduler.capacity.CapacityScheduler: Application appattempt_1385613010171_0002_000001 released container container_1385613010171_0002_01_000005 on node: host: ubuntusakshi:59487 #containers=1 available=6144 used=2048 with event: FINISHED
2013-11-27 22:40:25,532 INFO org.apache.hadoop.yarn.server.resourcemanager.rmapp.attempt.RMAppAttemptImpl: Processing event for appattempt_1385613010171_0002_000001 of type STATUS_UPDATE
2013-11-27 22:40:27,475 INFO org.apache.hadoop.yarn.server.resourcemanager.rmapp.attempt.RMAppAttemptImpl: Processing event for appattempt_1385613010171_0002_000001 of type STATUS_UPDATE
2013-11-27 22:40:28,496 INFO org.apache.hadoop.yarn.server.resourcemanager.rmapp.attempt.RMAppAttemptImpl: Processing event for appattempt_1385613010171_0002_000001 of type CONTAINER_ALLOCATED
2013-11-27 22:40:28,497 INFO org.apache.hadoop.yarn.server.resourcemanager.rmcontainer.RMContainerImpl: container_1385613010171_0002_01_000007 Container Transitioned from NEW to ALLOCATED
2013-11-27 22:40:28,497 INFO org.apache.hadoop.yarn.server.resourcemanager.RMAuditLogger: USER=sakshi	OPERATION=AM Allocated Container	TARGET=SchedulerApp	RESULT=SUCCESS	APPID=application_1385613010171_0002	CONTAINERID=container_1385613010171_0002_01_000007
2013-11-27 22:40:28,497 INFO org.apache.hadoop.yarn.server.resourcemanager.scheduler.common.fica.FiCaSchedulerNode: Assigned container container_1385613010171_0002_01_000007 of capacity <memory:1024, vCores:1> on host ubuntusakshi:59487, which currently has 2 containers, <memory:3072, vCores:2> used and <memory:5120, vCores:6> available
2013-11-27 22:40:28,499 INFO org.apache.hadoop.yarn.server.resourcemanager.scheduler.capacity.LeafQueue: assignedContainer application=application_1385613010171_0002 container=Container: [ContainerId: container_1385613010171_0002_01_000007, NodeId: ubuntusakshi:59487, NodeHttpAddress: ubuntusakshi:8042, Resource: <memory:1024, vCores:1>, Priority: 10, Token: Token { kind: ContainerToken, service: 127.0.1.1:59487 }, ] containerId=container_1385613010171_0002_01_000007 queue=default: capacity=1.0, absoluteCapacity=1.0, usedResources=<memory:2048, vCores:1>usedCapacity=0.25, absoluteUsedCapacity=0.25, numApps=2, numContainers=1 usedCapacity=0.25 absoluteUsedCapacity=0.25 used=<memory:2048, vCores:1> cluster=<memory:8192, vCores:8>
2013-11-27 22:40:28,500 INFO org.apache.hadoop.yarn.server.resourcemanager.scheduler.capacity.ParentQueue: Re-sorting assigned queue: root.default stats: default: capacity=1.0, absoluteCapacity=1.0, usedResources=<memory:3072, vCores:2>usedCapacity=0.375, absoluteUsedCapacity=0.375, numApps=2, numContainers=2
2013-11-27 22:40:28,501 INFO org.apache.hadoop.yarn.server.resourcemanager.scheduler.capacity.ParentQueue: assignedContainer queue=root usedCapacity=0.375 absoluteUsedCapacity=0.375 used=<memory:3072, vCores:2> cluster=<memory:8192, vCores:8>
2013-11-27 22:40:28,551 INFO org.apache.hadoop.yarn.server.resourcemanager.rmapp.attempt.RMAppAttemptImpl: Processing event for appattempt_1385613010171_0002_000001 of type STATUS_UPDATE
2013-11-27 22:40:28,565 INFO org.apache.hadoop.yarn.server.resourcemanager.rmcontainer.RMContainerImpl: container_1385613010171_0002_01_000007 Container Transitioned from ALLOCATED to ACQUIRED
2013-11-27 22:40:28,565 INFO org.apache.hadoop.yarn.server.resourcemanager.rmapp.attempt.RMAppAttemptImpl: Processing event for appattempt_1385613010171_0002_000001 of type CONTAINER_ACQUIRED
2013-11-27 22:40:29,525 INFO org.apache.hadoop.yarn.server.resourcemanager.rmcontainer.RMContainerImpl: container_1385613010171_0002_01_000007 Container Transitioned from ACQUIRED to RUNNING
2013-11-27 22:40:29,526 INFO org.apache.hadoop.yarn.server.resourcemanager.rmcontainer.RMContainerImpl: container_1385613010171_0002_01_000008 Container Transitioned from NEW to ALLOCATED
2013-11-27 22:40:29,526 INFO org.apache.hadoop.yarn.server.resourcemanager.RMAuditLogger: USER=sakshi	OPERATION=AM Allocated Container	TARGET=SchedulerApp	RESULT=SUCCESS	APPID=application_1385613010171_0002	CONTAINERID=container_1385613010171_0002_01_000008
2013-11-27 22:40:29,526 INFO org.apache.hadoop.yarn.server.resourcemanager.scheduler.common.fica.FiCaSchedulerNode: Assigned container container_1385613010171_0002_01_000008 of capacity <memory:1024, vCores:1> on host ubuntusakshi:59487, which currently has 3 containers, <memory:4096, vCores:3> used and <memory:4096, vCores:5> available
2013-11-27 22:40:29,526 INFO org.apache.hadoop.yarn.server.resourcemanager.scheduler.capacity.LeafQueue: assignedContainer application=application_1385613010171_0002 container=Container: [ContainerId: container_1385613010171_0002_01_000008, NodeId: ubuntusakshi:59487, NodeHttpAddress: ubuntusakshi:8042, Resource: <memory:1024, vCores:1>, Priority: 5, Token: Token { kind: ContainerToken, service: 127.0.1.1:59487 }, ] containerId=container_1385613010171_0002_01_000008 queue=default: capacity=1.0, absoluteCapacity=1.0, usedResources=<memory:3072, vCores:2>usedCapacity=0.375, absoluteUsedCapacity=0.375, numApps=2, numContainers=2 usedCapacity=0.375 absoluteUsedCapacity=0.375 used=<memory:3072, vCores:2> cluster=<memory:8192, vCores:8>
2013-11-27 22:40:29,551 INFO org.apache.hadoop.yarn.server.resourcemanager.scheduler.capacity.ParentQueue: Re-sorting assigned queue: root.default stats: default: capacity=1.0, absoluteCapacity=1.0, usedResources=<memory:4096, vCores:3>usedCapacity=0.5, absoluteUsedCapacity=0.5, numApps=2, numContainers=3
2013-11-27 22:40:29,527 INFO org.apache.hadoop.yarn.server.resourcemanager.rmapp.attempt.RMAppAttemptImpl: Processing event for appattempt_1385613010171_0002_000001 of type CONTAINER_ALLOCATED
2013-11-27 22:40:29,590 INFO org.apache.hadoop.yarn.server.resourcemanager.scheduler.capacity.ParentQueue: assignedContainer queue=root usedCapacity=0.5 absoluteUsedCapacity=0.5 used=<memory:4096, vCores:3> cluster=<memory:8192, vCores:8>
2013-11-27 22:40:29,708 INFO org.apache.hadoop.yarn.server.resourcemanager.rmapp.attempt.RMAppAttemptImpl: Processing event for appattempt_1385613010171_0002_000001 of type STATUS_UPDATE
2013-11-27 22:40:29,708 INFO org.apache.hadoop.yarn.server.resourcemanager.scheduler.AppSchedulingInfo: checking for deactivate... 
2013-11-27 22:40:29,711 INFO org.apache.hadoop.yarn.server.resourcemanager.rmapp.attempt.RMAppAttemptImpl: Processing event for appattempt_1385613010171_0002_000001 of type CONTAINER_ACQUIRED
2013-11-27 22:40:29,712 INFO org.apache.hadoop.yarn.server.resourcemanager.rmcontainer.RMContainerImpl: container_1385613010171_0002_01_000008 Container Transitioned from ALLOCATED to ACQUIRED
2013-11-27 22:40:30,573 INFO org.apache.hadoop.yarn.server.resourcemanager.rmcontainer.RMContainerImpl: container_1385613010171_0002_01_000008 Container Transitioned from ACQUIRED to RUNNING
2013-11-27 22:40:30,573 INFO org.apache.hadoop.yarn.server.resourcemanager.rmcontainer.RMContainerImpl: container_1385613010171_0002_01_000009 Container Transitioned from NEW to ALLOCATED
2013-11-27 22:40:30,573 INFO org.apache.hadoop.yarn.server.resourcemanager.RMAuditLogger: USER=sakshi	OPERATION=AM Allocated Container	TARGET=SchedulerApp	RESULT=SUCCESS	APPID=application_1385613010171_0002	CONTAINERID=container_1385613010171_0002_01_000009
2013-11-27 22:40:30,573 INFO org.apache.hadoop.yarn.server.resourcemanager.scheduler.common.fica.FiCaSchedulerNode: Assigned container container_1385613010171_0002_01_000009 of capacity <memory:1024, vCores:1> on host ubuntusakshi:59487, which currently has 4 containers, <memory:5120, vCores:4> used and <memory:3072, vCores:4> available
2013-11-27 22:40:30,574 INFO org.apache.hadoop.yarn.server.resourcemanager.scheduler.capacity.LeafQueue: assignedContainer application=application_1385613010171_0002 container=Container: [ContainerId: container_1385613010171_0002_01_000009, NodeId: ubuntusakshi:59487, NodeHttpAddress: ubuntusakshi:8042, Resource: <memory:1024, vCores:1>, Priority: 5, Token: Token { kind: ContainerToken, service: 127.0.1.1:59487 }, ] containerId=container_1385613010171_0002_01_000009 queue=default: capacity=1.0, absoluteCapacity=1.0, usedResources=<memory:4096, vCores:3>usedCapacity=0.5, absoluteUsedCapacity=0.5, numApps=2, numContainers=3 usedCapacity=0.5 absoluteUsedCapacity=0.5 used=<memory:4096, vCores:3> cluster=<memory:8192, vCores:8>
2013-11-27 22:40:30,574 INFO org.apache.hadoop.yarn.server.resourcemanager.scheduler.capacity.ParentQueue: Re-sorting assigned queue: root.default stats: default: capacity=1.0, absoluteCapacity=1.0, usedResources=<memory:5120, vCores:4>usedCapacity=0.625, absoluteUsedCapacity=0.625, numApps=2, numContainers=4
2013-11-27 22:40:30,574 INFO org.apache.hadoop.yarn.server.resourcemanager.scheduler.capacity.ParentQueue: assignedContainer queue=root usedCapacity=0.625 absoluteUsedCapacity=0.625 used=<memory:5120, vCores:4> cluster=<memory:8192, vCores:8>
2013-11-27 22:40:30,574 INFO org.apache.hadoop.yarn.server.resourcemanager.rmapp.attempt.RMAppAttemptImpl: Processing event for appattempt_1385613010171_0002_000001 of type CONTAINER_ALLOCATED
2013-11-27 22:40:30,757 INFO org.apache.hadoop.yarn.server.resourcemanager.rmapp.attempt.RMAppAttemptImpl: Processing event for appattempt_1385613010171_0002_000001 of type STATUS_UPDATE
2013-11-27 22:40:30,757 INFO org.apache.hadoop.yarn.server.resourcemanager.rmapp.attempt.RMAppAttemptImpl: Processing event for appattempt_1385613010171_0002_000001 of type CONTAINER_ACQUIRED
2013-11-27 22:40:30,757 INFO org.apache.hadoop.yarn.server.resourcemanager.rmcontainer.RMContainerImpl: container_1385613010171_0002_01_000009 Container Transitioned from ALLOCATED to ACQUIRED
2013-11-27 22:40:31,638 INFO org.apache.hadoop.yarn.server.resourcemanager.rmcontainer.RMContainerImpl: container_1385613010171_0002_01_000009 Container Transitioned from ACQUIRED to RUNNING
2013-11-27 22:40:31,639 INFO org.apache.hadoop.yarn.server.resourcemanager.rmcontainer.RMContainerImpl: container_1385613010171_0002_01_000010 Container Transitioned from NEW to ALLOCATED
2013-11-27 22:40:31,639 INFO org.apache.hadoop.yarn.server.resourcemanager.RMAuditLogger: USER=sakshi	OPERATION=AM Allocated Container	TARGET=SchedulerApp	RESULT=SUCCESS	APPID=application_1385613010171_0002	CONTAINERID=container_1385613010171_0002_01_000010
2013-11-27 22:40:31,639 INFO org.apache.hadoop.yarn.server.resourcemanager.scheduler.common.fica.FiCaSchedulerNode: Assigned container container_1385613010171_0002_01_000010 of capacity <memory:1024, vCores:1> on host ubuntusakshi:59487, which currently has 5 containers, <memory:6144, vCores:5> used and <memory:2048, vCores:3> available
2013-11-27 22:40:31,643 INFO org.apache.hadoop.yarn.server.resourcemanager.rmapp.attempt.RMAppAttemptImpl: Processing event for appattempt_1385613010171_0002_000001 of type CONTAINER_ALLOCATED
2013-11-27 22:40:31,643 INFO org.apache.hadoop.yarn.server.resourcemanager.scheduler.capacity.LeafQueue: assignedContainer application=application_1385613010171_0002 container=Container: [ContainerId: container_1385613010171_0002_01_000010, NodeId: ubuntusakshi:59487, NodeHttpAddress: ubuntusakshi:8042, Resource: <memory:1024, vCores:1>, Priority: 5, Token: Token { kind: ContainerToken, service: 127.0.1.1:59487 }, ] containerId=container_1385613010171_0002_01_000010 queue=default: capacity=1.0, absoluteCapacity=1.0, usedResources=<memory:5120, vCores:4>usedCapacity=0.625, absoluteUsedCapacity=0.625, numApps=2, numContainers=4 usedCapacity=0.625 absoluteUsedCapacity=0.625 used=<memory:5120, vCores:4> cluster=<memory:8192, vCores:8>
2013-11-27 22:40:31,643 INFO org.apache.hadoop.yarn.server.resourcemanager.scheduler.capacity.ParentQueue: Re-sorting assigned queue: root.default stats: default: capacity=1.0, absoluteCapacity=1.0, usedResources=<memory:6144, vCores:5>usedCapacity=0.75, absoluteUsedCapacity=0.75, numApps=2, numContainers=5
2013-11-27 22:40:31,643 INFO org.apache.hadoop.yarn.server.resourcemanager.scheduler.capacity.ParentQueue: assignedContainer queue=root usedCapacity=0.75 absoluteUsedCapacity=0.75 used=<memory:6144, vCores:5> cluster=<memory:8192, vCores:8>
2013-11-27 22:40:31,781 INFO org.apache.hadoop.yarn.server.resourcemanager.rmapp.attempt.RMAppAttemptImpl: Processing event for appattempt_1385613010171_0002_000001 of type STATUS_UPDATE
2013-11-27 22:40:31,781 INFO org.apache.hadoop.yarn.server.resourcemanager.scheduler.AppSchedulingInfo: checking for deactivate... 
2013-11-27 22:40:31,782 INFO org.apache.hadoop.yarn.server.resourcemanager.rmapp.attempt.RMAppAttemptImpl: Processing event for appattempt_1385613010171_0002_000001 of type CONTAINER_ACQUIRED
2013-11-27 22:40:31,782 INFO org.apache.hadoop.yarn.server.resourcemanager.rmcontainer.RMContainerImpl: container_1385613010171_0002_01_000010 Container Transitioned from ALLOCATED to ACQUIRED
2013-11-27 22:40:32,816 INFO org.apache.hadoop.yarn.server.resourcemanager.rmapp.attempt.RMAppAttemptImpl: Processing event for appattempt_1385613010171_0002_000001 of type STATUS_UPDATE
2013-11-27 22:40:32,875 INFO org.apache.hadoop.yarn.server.resourcemanager.rmapp.attempt.RMAppAttemptImpl: Processing event for appattempt_1385613010171_0002_000001 of type CONTAINER_FINISHED
2013-11-27 22:40:32,875 INFO org.apache.hadoop.yarn.server.resourcemanager.rmcontainer.RMContainerImpl: container_1385613010171_0002_01_000010 Container Transitioned from ACQUIRED to RELEASED
2013-11-27 22:40:32,875 INFO org.apache.hadoop.yarn.server.resourcemanager.scheduler.common.fica.FiCaSchedulerApp: Completed container: container_1385613010171_0002_01_000010 in state: RELEASED event:RELEASED
2013-11-27 22:40:32,875 INFO org.apache.hadoop.yarn.server.resourcemanager.RMAuditLogger: USER=sakshi	IP=127.0.0.1	OPERATION=AM Released Container	TARGET=SchedulerApp	RESULT=SUCCESS	APPID=application_1385613010171_0002	CONTAINERID=container_1385613010171_0002_01_000010
2013-11-27 22:40:32,876 INFO org.apache.hadoop.yarn.server.resourcemanager.scheduler.common.fica.FiCaSchedulerNode: Released container container_1385613010171_0002_01_000010 of capacity <memory:1024, vCores:1> on host ubuntusakshi:59487, which currently has 4 containers, <memory:5120, vCores:4> used and <memory:3072, vCores:4> available, release resources=true
2013-11-27 22:40:32,876 INFO org.apache.hadoop.yarn.server.resourcemanager.scheduler.capacity.LeafQueue: default used=<memory:5120, vCores:4> numContainers=4 user=sakshi user-resources=<memory:5120, vCores:4>
2013-11-27 22:40:32,877 INFO org.apache.hadoop.yarn.server.resourcemanager.scheduler.capacity.LeafQueue: completedContainer container=Container: [ContainerId: container_1385613010171_0002_01_000010, NodeId: ubuntusakshi:59487, NodeHttpAddress: ubuntusakshi:8042, Resource: <memory:1024, vCores:1>, Priority: 5, Token: Token { kind: ContainerToken, service: 127.0.1.1:59487 }, ] resource=<memory:1024, vCores:1> queue=default: capacity=1.0, absoluteCapacity=1.0, usedResources=<memory:5120, vCores:4>usedCapacity=0.625, absoluteUsedCapacity=0.625, numApps=2, numContainers=4 usedCapacity=0.625 absoluteUsedCapacity=0.625 used=<memory:5120, vCores:4> cluster=<memory:8192, vCores:8>
2013-11-27 22:40:32,878 INFO org.apache.hadoop.yarn.server.resourcemanager.scheduler.capacity.ParentQueue: completedContainer queue=root usedCapacity=0.625 absoluteUsedCapacity=0.625 used=<memory:5120, vCores:4> cluster=<memory:8192, vCores:8>
2013-11-27 22:40:32,879 INFO org.apache.hadoop.yarn.server.resourcemanager.scheduler.capacity.ParentQueue: Re-sorting completed queue: root.default stats: default: capacity=1.0, absoluteCapacity=1.0, usedResources=<memory:5120, vCores:4>usedCapacity=0.625, absoluteUsedCapacity=0.625, numApps=2, numContainers=4
2013-11-27 22:40:32,880 INFO org.apache.hadoop.yarn.server.resourcemanager.scheduler.capacity.CapacityScheduler: Application appattempt_1385613010171_0002_000001 released container container_1385613010171_0002_01_000010 on node: host: ubuntusakshi:59487 #containers=4 available=3072 used=5120 with event: RELEASED
2013-11-27 22:40:33,910 INFO org.apache.hadoop.yarn.server.resourcemanager.rmapp.attempt.RMAppAttemptImpl: Processing event for appattempt_1385613010171_0002_000001 of type STATUS_UPDATE
2013-11-27 22:40:34,931 INFO org.apache.hadoop.yarn.server.resourcemanager.rmapp.attempt.RMAppAttemptImpl: Processing event for appattempt_1385613010171_0002_000001 of type STATUS_UPDATE
2013-11-27 22:40:36,012 INFO org.apache.hadoop.yarn.server.resourcemanager.rmapp.attempt.RMAppAttemptImpl: Processing event for appattempt_1385613010171_0002_000001 of type STATUS_UPDATE
2013-11-27 22:40:37,119 INFO org.apache.hadoop.yarn.server.resourcemanager.rmapp.attempt.RMAppAttemptImpl: Processing event for appattempt_1385613010171_0002_000001 of type STATUS_UPDATE
2013-11-27 22:40:38,124 INFO org.apache.hadoop.yarn.server.resourcemanager.rmapp.attempt.RMAppAttemptImpl: Processing event for appattempt_1385613010171_0002_000001 of type STATUS_UPDATE
2013-11-27 22:40:39,221 INFO org.apache.hadoop.yarn.server.resourcemanager.rmapp.attempt.RMAppAttemptImpl: Processing event for appattempt_1385613010171_0002_000001 of type STATUS_UPDATE
2013-11-27 22:40:40,228 INFO org.apache.hadoop.yarn.server.resourcemanager.rmapp.attempt.RMAppAttemptImpl: Processing event for appattempt_1385613010171_0002_000001 of type STATUS_UPDATE
2013-11-27 22:40:41,519 INFO org.apache.hadoop.yarn.server.resourcemanager.rmapp.attempt.RMAppAttemptImpl: Processing event for appattempt_1385613010171_0002_000001 of type STATUS_UPDATE
2013-11-27 22:40:42,672 INFO org.apache.hadoop.yarn.server.resourcemanager.rmapp.attempt.RMAppAttemptImpl: Processing event for appattempt_1385613010171_0002_000001 of type STATUS_UPDATE
2013-11-27 22:40:43,732 INFO org.apache.hadoop.yarn.server.resourcemanager.rmapp.attempt.RMAppAttemptImpl: Processing event for appattempt_1385613010171_0002_000001 of type STATUS_UPDATE
2013-11-27 22:40:44,874 INFO org.apache.hadoop.yarn.server.resourcemanager.rmapp.attempt.RMAppAttemptImpl: Processing event for appattempt_1385613010171_0002_000001 of type STATUS_UPDATE
2013-11-27 22:40:45,897 INFO org.apache.hadoop.yarn.server.resourcemanager.rmapp.attempt.RMAppAttemptImpl: Processing event for appattempt_1385613010171_0002_000001 of type STATUS_UPDATE
2013-11-27 22:40:46,971 INFO org.apache.hadoop.yarn.server.resourcemanager.rmapp.attempt.RMAppAttemptImpl: Processing event for appattempt_1385613010171_0002_000001 of type STATUS_UPDATE
2013-11-27 22:40:47,989 INFO org.apache.hadoop.yarn.server.resourcemanager.rmapp.attempt.RMAppAttemptImpl: Processing event for appattempt_1385613010171_0002_000001 of type STATUS_UPDATE
2013-11-27 22:40:49,019 INFO org.apache.hadoop.yarn.server.resourcemanager.rmapp.attempt.RMAppAttemptImpl: Processing event for appattempt_1385613010171_0002_000001 of type STATUS_UPDATE
2013-11-27 22:40:50,124 INFO org.apache.hadoop.yarn.server.resourcemanager.rmapp.attempt.RMAppAttemptImpl: Processing event for appattempt_1385613010171_0002_000001 of type STATUS_UPDATE
2013-11-27 22:40:51,396 INFO org.apache.hadoop.yarn.server.resourcemanager.rmapp.attempt.RMAppAttemptImpl: Processing event for appattempt_1385613010171_0002_000001 of type STATUS_UPDATE
2013-11-27 22:40:52,406 INFO org.apache.hadoop.yarn.server.resourcemanager.rmapp.attempt.RMAppAttemptImpl: Processing event for appattempt_1385613010171_0002_000001 of type STATUS_UPDATE
2013-11-27 22:40:53,539 INFO org.apache.hadoop.yarn.server.resourcemanager.rmapp.attempt.RMAppAttemptImpl: Processing event for appattempt_1385613010171_0002_000001 of type STATUS_UPDATE
2013-11-27 22:40:55,145 INFO org.apache.hadoop.yarn.server.resourcemanager.rmapp.attempt.RMAppAttemptImpl: Processing event for appattempt_1385613010171_0002_000001 of type STATUS_UPDATE
2013-11-27 22:40:56,627 INFO org.apache.hadoop.yarn.server.resourcemanager.rmapp.attempt.RMAppAttemptImpl: Processing event for appattempt_1385613010171_0002_000001 of type STATUS_UPDATE
2013-11-27 22:40:58,443 INFO org.apache.hadoop.yarn.server.resourcemanager.rmapp.attempt.RMAppAttemptImpl: Processing event for appattempt_1385613010171_0002_000001 of type STATUS_UPDATE
2013-11-27 22:40:59,670 INFO org.apache.hadoop.yarn.server.resourcemanager.rmapp.attempt.RMAppAttemptImpl: Processing event for appattempt_1385613010171_0002_000001 of type STATUS_UPDATE
2013-11-27 22:41:00,559 INFO org.apache.hadoop.yarn.server.resourcemanager.rmcontainer.RMContainerImpl: container_1385613010171_0002_01_000008 Container Transitioned from RUNNING to COMPLETED
2013-11-27 22:41:00,559 INFO org.apache.hadoop.yarn.server.resourcemanager.scheduler.common.fica.FiCaSchedulerApp: Completed container: container_1385613010171_0002_01_000008 in state: COMPLETED event:FINISHED
2013-11-27 22:41:00,559 INFO org.apache.hadoop.yarn.server.resourcemanager.RMAuditLogger: USER=sakshi	OPERATION=AM Released Container	TARGET=SchedulerApp	RESULT=SUCCESS	APPID=application_1385613010171_0002	CONTAINERID=container_1385613010171_0002_01_000008
2013-11-27 22:41:00,559 INFO org.apache.hadoop.yarn.server.resourcemanager.scheduler.common.fica.FiCaSchedulerNode: Released container container_1385613010171_0002_01_000008 of capacity <memory:1024, vCores:1> on host ubuntusakshi:59487, which currently has 3 containers, <memory:4096, vCores:3> used and <memory:4096, vCores:5> available, release resources=true
2013-11-27 22:41:00,560 INFO org.apache.hadoop.yarn.server.resourcemanager.rmapp.attempt.RMAppAttemptImpl: Processing event for appattempt_1385613010171_0002_000001 of type CONTAINER_FINISHED
2013-11-27 22:41:00,572 INFO org.apache.hadoop.yarn.server.resourcemanager.scheduler.capacity.LeafQueue: default used=<memory:4096, vCores:3> numContainers=3 user=sakshi user-resources=<memory:4096, vCores:3>
2013-11-27 22:41:00,574 INFO org.apache.hadoop.yarn.server.resourcemanager.scheduler.capacity.LeafQueue: completedContainer container=Container: [ContainerId: container_1385613010171_0002_01_000008, NodeId: ubuntusakshi:59487, NodeHttpAddress: ubuntusakshi:8042, Resource: <memory:1024, vCores:1>, Priority: 5, Token: Token { kind: ContainerToken, service: 127.0.1.1:59487 }, ] resource=<memory:1024, vCores:1> queue=default: capacity=1.0, absoluteCapacity=1.0, usedResources=<memory:4096, vCores:3>usedCapacity=0.5, absoluteUsedCapacity=0.5, numApps=2, numContainers=3 usedCapacity=0.5 absoluteUsedCapacity=0.5 used=<memory:4096, vCores:3> cluster=<memory:8192, vCores:8>
2013-11-27 22:41:00,574 INFO org.apache.hadoop.yarn.server.resourcemanager.scheduler.capacity.ParentQueue: completedContainer queue=root usedCapacity=0.5 absoluteUsedCapacity=0.5 used=<memory:4096, vCores:3> cluster=<memory:8192, vCores:8>
2013-11-27 22:41:00,574 INFO org.apache.hadoop.yarn.server.resourcemanager.scheduler.capacity.ParentQueue: Re-sorting completed queue: root.default stats: default: capacity=1.0, absoluteCapacity=1.0, usedResources=<memory:4096, vCores:3>usedCapacity=0.5, absoluteUsedCapacity=0.5, numApps=2, numContainers=3
2013-11-27 22:41:00,574 INFO org.apache.hadoop.yarn.server.resourcemanager.scheduler.capacity.CapacityScheduler: Application appattempt_1385613010171_0002_000001 released container container_1385613010171_0002_01_000008 on node: host: ubuntusakshi:59487 #containers=3 available=4096 used=4096 with event: FINISHED
2013-11-27 22:41:00,575 INFO org.apache.hadoop.yarn.server.resourcemanager.rmapp.attempt.RMAppAttemptImpl: Processing event for appattempt_1385613010171_0002_000001 of type CONTAINER_FINISHED
2013-11-27 22:41:00,575 INFO org.apache.hadoop.yarn.server.resourcemanager.rmcontainer.RMContainerImpl: container_1385613010171_0002_01_000009 Container Transitioned from RUNNING to COMPLETED
2013-11-27 22:41:00,676 INFO org.apache.hadoop.yarn.server.resourcemanager.scheduler.common.fica.FiCaSchedulerApp: Completed container: container_1385613010171_0002_01_000009 in state: COMPLETED event:FINISHED
2013-11-27 22:41:00,694 INFO org.apache.hadoop.yarn.server.resourcemanager.RMAuditLogger: USER=sakshi	OPERATION=AM Released Container	TARGET=SchedulerApp	RESULT=SUCCESS	APPID=application_1385613010171_0002	CONTAINERID=container_1385613010171_0002_01_000009
2013-11-27 22:41:00,695 INFO org.apache.hadoop.yarn.server.resourcemanager.scheduler.common.fica.FiCaSchedulerNode: Released container container_1385613010171_0002_01_000009 of capacity <memory:1024, vCores:1> on host ubuntusakshi:59487, which currently has 2 containers, <memory:3072, vCores:2> used and <memory:5120, vCores:6> available, release resources=true
2013-11-27 22:41:00,695 INFO org.apache.hadoop.yarn.server.resourcemanager.scheduler.capacity.LeafQueue: default used=<memory:3072, vCores:2> numContainers=2 user=sakshi user-resources=<memory:3072, vCores:2>
2013-11-27 22:41:00,695 INFO org.apache.hadoop.yarn.server.resourcemanager.scheduler.capacity.LeafQueue: completedContainer container=Container: [ContainerId: container_1385613010171_0002_01_000009, NodeId: ubuntusakshi:59487, NodeHttpAddress: ubuntusakshi:8042, Resource: <memory:1024, vCores:1>, Priority: 5, Token: Token { kind: ContainerToken, service: 127.0.1.1:59487 }, ] resource=<memory:1024, vCores:1> queue=default: capacity=1.0, absoluteCapacity=1.0, usedResources=<memory:3072, vCores:2>usedCapacity=0.375, absoluteUsedCapacity=0.375, numApps=2, numContainers=2 usedCapacity=0.375 absoluteUsedCapacity=0.375 used=<memory:3072, vCores:2> cluster=<memory:8192, vCores:8>
2013-11-27 22:41:00,695 INFO org.apache.hadoop.yarn.server.resourcemanager.scheduler.capacity.ParentQueue: completedContainer queue=root usedCapacity=0.375 absoluteUsedCapacity=0.375 used=<memory:3072, vCores:2> cluster=<memory:8192, vCores:8>
2013-11-27 22:41:00,698 INFO org.apache.hadoop.yarn.server.resourcemanager.rmapp.attempt.RMAppAttemptImpl: Processing event for appattempt_1385613010171_0002_000001 of type STATUS_UPDATE
2013-11-27 22:41:00,698 INFO org.apache.hadoop.yarn.server.resourcemanager.scheduler.capacity.ParentQueue: Re-sorting completed queue: root.default stats: default: capacity=1.0, absoluteCapacity=1.0, usedResources=<memory:3072, vCores:2>usedCapacity=0.375, absoluteUsedCapacity=0.375, numApps=2, numContainers=2
2013-11-27 22:41:00,698 INFO org.apache.hadoop.yarn.server.resourcemanager.scheduler.capacity.CapacityScheduler: Application appattempt_1385613010171_0002_000001 released container container_1385613010171_0002_01_000009 on node: host: ubuntusakshi:59487 #containers=2 available=5120 used=3072 with event: FINISHED
2013-11-27 22:41:01,744 INFO org.apache.hadoop.yarn.server.resourcemanager.rmapp.attempt.RMAppAttemptImpl: Processing event for appattempt_1385613010171_0002_000001 of type STATUS_UPDATE
2013-11-27 22:41:02,814 INFO org.apache.hadoop.yarn.server.resourcemanager.rmapp.attempt.RMAppAttemptImpl: Processing event for appattempt_1385613010171_0002_000001 of type STATUS_UPDATE
2013-11-27 22:41:04,033 INFO org.apache.hadoop.yarn.server.resourcemanager.rmapp.attempt.RMAppAttemptImpl: Processing event for appattempt_1385613010171_0002_000001 of type STATUS_UPDATE
2013-11-27 22:41:04,827 INFO org.apache.hadoop.yarn.server.resourcemanager.rmcontainer.RMContainerImpl: container_1385613010171_0002_01_000007 Container Transitioned from RUNNING to COMPLETED
2013-11-27 22:41:04,827 INFO org.apache.hadoop.yarn.server.resourcemanager.scheduler.common.fica.FiCaSchedulerApp: Completed container: container_1385613010171_0002_01_000007 in state: COMPLETED event:FINISHED
2013-11-27 22:41:04,827 INFO org.apache.hadoop.yarn.server.resourcemanager.RMAuditLogger: USER=sakshi	OPERATION=AM Released Container	TARGET=SchedulerApp	RESULT=SUCCESS	APPID=application_1385613010171_0002	CONTAINERID=container_1385613010171_0002_01_000007
2013-11-27 22:41:04,827 INFO org.apache.hadoop.yarn.server.resourcemanager.scheduler.common.fica.FiCaSchedulerNode: Released container container_1385613010171_0002_01_000007 of capacity <memory:1024, vCores:1> on host ubuntusakshi:59487, which currently has 1 containers, <memory:2048, vCores:1> used and <memory:6144, vCores:7> available, release resources=true
2013-11-27 22:41:04,827 INFO org.apache.hadoop.yarn.server.resourcemanager.scheduler.capacity.LeafQueue: default used=<memory:2048, vCores:1> numContainers=1 user=sakshi user-resources=<memory:2048, vCores:1>
2013-11-27 22:41:04,828 INFO org.apache.hadoop.yarn.server.resourcemanager.scheduler.capacity.LeafQueue: completedContainer container=Container: [ContainerId: container_1385613010171_0002_01_000007, NodeId: ubuntusakshi:59487, NodeHttpAddress: ubuntusakshi:8042, Resource: <memory:1024, vCores:1>, Priority: 10, Token: Token { kind: ContainerToken, service: 127.0.1.1:59487 }, ] resource=<memory:1024, vCores:1> queue=default: capacity=1.0, absoluteCapacity=1.0, usedResources=<memory:2048, vCores:1>usedCapacity=0.25, absoluteUsedCapacity=0.25, numApps=2, numContainers=1 usedCapacity=0.25 absoluteUsedCapacity=0.25 used=<memory:2048, vCores:1> cluster=<memory:8192, vCores:8>
2013-11-27 22:41:04,828 INFO org.apache.hadoop.yarn.server.resourcemanager.scheduler.capacity.ParentQueue: completedContainer queue=root usedCapacity=0.25 absoluteUsedCapacity=0.25 used=<memory:2048, vCores:1> cluster=<memory:8192, vCores:8>
2013-11-27 22:41:04,828 INFO org.apache.hadoop.yarn.server.resourcemanager.scheduler.capacity.ParentQueue: Re-sorting completed queue: root.default stats: default: capacity=1.0, absoluteCapacity=1.0, usedResources=<memory:2048, vCores:1>usedCapacity=0.25, absoluteUsedCapacity=0.25, numApps=2, numContainers=1
2013-11-27 22:41:04,828 INFO org.apache.hadoop.yarn.server.resourcemanager.scheduler.capacity.CapacityScheduler: Application appattempt_1385613010171_0002_000001 released container container_1385613010171_0002_01_000007 on node: host: ubuntusakshi:59487 #containers=1 available=6144 used=2048 with event: FINISHED
2013-11-27 22:41:04,828 INFO org.apache.hadoop.yarn.server.resourcemanager.rmapp.attempt.RMAppAttemptImpl: Processing event for appattempt_1385613010171_0002_000001 of type CONTAINER_FINISHED
2013-11-27 22:41:05,042 INFO org.apache.hadoop.yarn.server.resourcemanager.rmapp.attempt.RMAppAttemptImpl: Processing event for appattempt_1385613010171_0002_000001 of type STATUS_UPDATE
2013-11-27 22:41:06,060 INFO org.apache.hadoop.yarn.server.resourcemanager.rmapp.attempt.RMAppAttemptImpl: Processing event for appattempt_1385613010171_0002_000001 of type STATUS_UPDATE
2013-11-27 22:41:07,083 INFO org.apache.hadoop.yarn.server.resourcemanager.rmapp.attempt.RMAppAttemptImpl: Processing event for appattempt_1385613010171_0002_000001 of type STATUS_UPDATE
2013-11-27 22:41:08,456 INFO org.apache.hadoop.yarn.server.resourcemanager.rmapp.attempt.RMAppAttemptImpl: Processing event for appattempt_1385613010171_0002_000001 of type STATUS_UPDATE
2013-11-27 22:41:09,498 INFO org.apache.hadoop.yarn.server.resourcemanager.rmapp.attempt.RMAppAttemptImpl: Processing event for appattempt_1385613010171_0002_000001 of type STATUS_UPDATE
2013-11-27 22:41:10,617 INFO org.apache.hadoop.yarn.server.resourcemanager.rmapp.attempt.RMAppAttemptImpl: Processing event for appattempt_1385613010171_0002_000001 of type STATUS_UPDATE
2013-11-27 22:41:11,695 INFO org.apache.hadoop.yarn.server.resourcemanager.rmapp.attempt.RMAppAttemptImpl: Processing event for appattempt_1385613010171_0002_000001 of type STATUS_UPDATE
2013-11-27 22:41:12,481 INFO org.apache.hadoop.yarn.server.resourcemanager.rmapp.attempt.RMAppAttemptImpl: Processing event for appattempt_1385613010171_0002_000001 of type UNREGISTERED
2013-11-27 22:41:12,568 INFO org.apache.hadoop.yarn.server.resourcemanager.rmapp.attempt.RMAppAttemptImpl: Sakshi appattempt_1385613010171_0002_000001 State change from RUNNING to FINISHING after EVENT: UNREGISTERED
2013-11-27 22:41:12,570 INFO org.apache.hadoop.yarn.server.resourcemanager.rmapp.RMAppImpl: Sakshi application_1385613010171_0002 State change from RUNNING to FINISHING after EVENT: ATTEMPT_FINISHING
2013-11-27 22:41:13,478 INFO org.apache.hadoop.yarn.server.resourcemanager.rmcontainer.RMContainerImpl: container_1385613010171_0002_01_000001 Container Transitioned from RUNNING to COMPLETED
2013-11-27 22:41:13,479 INFO org.apache.hadoop.yarn.server.resourcemanager.scheduler.common.fica.FiCaSchedulerApp: Completed container: container_1385613010171_0002_01_000001 in state: COMPLETED event:FINISHED
2013-11-27 22:41:13,479 INFO org.apache.hadoop.yarn.server.resourcemanager.RMAuditLogger: USER=sakshi	OPERATION=AM Released Container	TARGET=SchedulerApp	RESULT=SUCCESS	APPID=application_1385613010171_0002	CONTAINERID=container_1385613010171_0002_01_000001
2013-11-27 22:41:13,479 INFO org.apache.hadoop.yarn.server.resourcemanager.scheduler.common.fica.FiCaSchedulerNode: Released container container_1385613010171_0002_01_000001 of capacity <memory:2048, vCores:1> on host ubuntusakshi:59487, which currently has 0 containers, <memory:0, vCores:0> used and <memory:8192, vCores:8> available, release resources=true
2013-11-27 22:41:13,479 INFO org.apache.hadoop.yarn.server.resourcemanager.scheduler.capacity.LeafQueue: default used=<memory:0, vCores:0> numContainers=0 user=sakshi user-resources=<memory:0, vCores:0>
2013-11-27 22:41:13,480 INFO org.apache.hadoop.yarn.server.resourcemanager.scheduler.capacity.LeafQueue: completedContainer container=Container: [ContainerId: container_1385613010171_0002_01_000001, NodeId: ubuntusakshi:59487, NodeHttpAddress: ubuntusakshi:8042, Resource: <memory:2048, vCores:1>, Priority: 0, Token: Token { kind: ContainerToken, service: 127.0.1.1:59487 }, ] resource=<memory:2048, vCores:1> queue=default: capacity=1.0, absoluteCapacity=1.0, usedResources=<memory:0, vCores:0>usedCapacity=0.0, absoluteUsedCapacity=0.0, numApps=2, numContainers=0 usedCapacity=0.0 absoluteUsedCapacity=0.0 used=<memory:0, vCores:0> cluster=<memory:8192, vCores:8>
2013-11-27 22:41:13,480 INFO org.apache.hadoop.yarn.server.resourcemanager.scheduler.capacity.ParentQueue: completedContainer queue=root usedCapacity=0.0 absoluteUsedCapacity=0.0 used=<memory:0, vCores:0> cluster=<memory:8192, vCores:8>
2013-11-27 22:41:13,480 INFO org.apache.hadoop.yarn.server.resourcemanager.scheduler.capacity.ParentQueue: Re-sorting completed queue: root.default stats: default: capacity=1.0, absoluteCapacity=1.0, usedResources=<memory:0, vCores:0>usedCapacity=0.0, absoluteUsedCapacity=0.0, numApps=2, numContainers=0
2013-11-27 22:41:13,480 INFO org.apache.hadoop.yarn.server.resourcemanager.rmapp.attempt.RMAppAttemptImpl: Processing event for appattempt_1385613010171_0002_000001 of type CONTAINER_FINISHED
2013-11-27 22:41:13,482 INFO org.apache.hadoop.yarn.server.resourcemanager.ApplicationMasterService: Unregistering app attempt : appattempt_1385613010171_0002_000001
2013-11-27 22:41:13,485 INFO org.apache.hadoop.yarn.server.resourcemanager.scheduler.capacity.CapacityScheduler: Application appattempt_1385613010171_0002_000001 released container container_1385613010171_0002_01_000001 on node: host: ubuntusakshi:59487 #containers=0 available=8192 used=0 with event: FINISHED
2013-11-27 22:41:13,512 INFO org.apache.hadoop.yarn.server.resourcemanager.rmapp.attempt.RMAppAttemptImpl: Sakshi appattempt_1385613010171_0002_000001 State change from FINISHING to FINISHED after EVENT: CONTAINER_FINISHED
2013-11-27 22:41:13,611 INFO org.apache.hadoop.yarn.server.resourcemanager.rmapp.RMAppImpl: Sakshi application_1385613010171_0002 State change from FINISHING to FINISHED after EVENT: ATTEMPT_FINISHED
2013-11-27 22:41:13,612 INFO org.apache.hadoop.yarn.server.resourcemanager.scheduler.capacity.CapacityScheduler: Application appattempt_1385613010171_0002_000001 is done. finalState=FINISHED
2013-11-27 22:41:13,639 INFO org.apache.hadoop.yarn.server.resourcemanager.scheduler.AppSchedulingInfo: Application application_1385613010171_0002 requests cleared
2013-11-27 22:41:13,639 INFO org.apache.hadoop.yarn.server.resourcemanager.scheduler.capacity.LeafQueue: Application application_1385613010171_0001 from user: sakshi activated in queue: default
2013-11-27 22:41:13,639 INFO org.apache.hadoop.yarn.server.resourcemanager.scheduler.capacity.LeafQueue: Application removed - appId: application_1385613010171_0002 user: sakshi queue: default #user-pending-applications: 0 #user-active-applications: 1 #queue-pending-applications: 0 #queue-active-applications: 1
2013-11-27 22:41:13,639 INFO org.apache.hadoop.yarn.server.resourcemanager.scheduler.capacity.ParentQueue: Application removed - appId: application_1385613010171_0002 user: sakshi leaf-queue of parent: root #applications: 1
2013-11-27 22:41:13,650 INFO org.apache.hadoop.yarn.server.resourcemanager.RMAuditLogger: USER=sakshi	OPERATION=Application Finished - Succeeded	TARGET=RMAppManager	RESULT=SUCCESS	APPID=application_1385613010171_0002
2013-11-27 22:41:13,654 INFO org.apache.hadoop.yarn.server.resourcemanager.amlauncher.AMLauncher: Cleaning master appattempt_1385613010171_0002_000001
2013-11-27 22:41:13,696 INFO org.apache.hadoop.yarn.server.resourcemanager.recovery.RMStateStore: Removing info for app: application_1385613010171_0002
2013-11-27 22:41:13,754 INFO org.apache.hadoop.yarn.server.resourcemanager.RMAppManager$ApplicationSummary: appId=application_1385613010171_0002,name=QuasiMonteCarlo,user=sakshi,queue=default,state=FINISHED,trackingUrl=ubuntusakshi:8088/proxy/application_1385613010171_0002/jobhistory/job/job_1385613010171_0002,appMasterHost=ubuntusakshi,startTime=1385613293449,finishTime=1385613672568
2013-11-27 22:41:14,497 INFO org.apache.hadoop.yarn.server.resourcemanager.rmapp.attempt.RMAppAttemptImpl: Processing event for appattempt_1385613010171_0001_000001 of type CONTAINER_ALLOCATED
2013-11-27 22:41:14,497 INFO org.apache.hadoop.yarn.server.resourcemanager.rmcontainer.RMContainerImpl: container_1385613010171_0001_01_000001 Container Transitioned from NEW to ALLOCATED
2013-11-27 22:41:14,498 INFO org.apache.hadoop.yarn.server.resourcemanager.RMAuditLogger: USER=sakshi	OPERATION=AM Allocated Container	TARGET=SchedulerApp	RESULT=SUCCESS	APPID=application_1385613010171_0001	CONTAINERID=container_1385613010171_0001_01_000001
2013-11-27 22:41:14,498 INFO org.apache.hadoop.yarn.server.resourcemanager.scheduler.common.fica.FiCaSchedulerNode: Assigned container container_1385613010171_0001_01_000001 of capacity <memory:2048, vCores:1> on host ubuntusakshi:59487, which currently has 1 containers, <memory:2048, vCores:1> used and <memory:6144, vCores:7> available
2013-11-27 22:41:14,499 INFO org.apache.hadoop.yarn.server.resourcemanager.scheduler.capacity.LeafQueue: assignedContainer application=application_1385613010171_0001 container=Container: [ContainerId: container_1385613010171_0001_01_000001, NodeId: ubuntusakshi:59487, NodeHttpAddress: ubuntusakshi:8042, Resource: <memory:2048, vCores:1>, Priority: 0, Token: Token { kind: ContainerToken, service: 127.0.1.1:59487 }, ] containerId=container_1385613010171_0001_01_000001 queue=default: capacity=1.0, absoluteCapacity=1.0, usedResources=<memory:0, vCores:0>usedCapacity=0.0, absoluteUsedCapacity=0.0, numApps=1, numContainers=0 usedCapacity=0.0 absoluteUsedCapacity=0.0 used=<memory:0, vCores:0> cluster=<memory:8192, vCores:8>
2013-11-27 22:41:14,502 INFO org.apache.hadoop.yarn.server.resourcemanager.rmcontainer.RMContainerImpl: container_1385613010171_0001_01_000001 Container Transitioned from ALLOCATED to ACQUIRED
2013-11-27 22:41:14,503 INFO org.apache.hadoop.yarn.server.resourcemanager.rmapp.attempt.RMAppAttemptImpl: Storing attempt: AppId: application_1385613010171_0001 AttemptId: appattempt_1385613010171_0001_000001 MasterContainer: Container: [ContainerId: container_1385613010171_0001_01_000001, NodeId: ubuntusakshi:59487, NodeHttpAddress: ubuntusakshi:8042, Resource: <memory:2048, vCores:1>, Priority: 0, Token: Token { kind: ContainerToken, service: 127.0.1.1:59487 }, ]
2013-11-27 22:41:14,504 INFO org.apache.hadoop.yarn.server.resourcemanager.rmapp.attempt.RMAppAttemptImpl: Sakshi appattempt_1385613010171_0001_000001 State change from SCHEDULED to ALLOCATED_SAVING after EVENT: CONTAINER_ALLOCATED
2013-11-27 22:41:14,504 INFO org.apache.hadoop.yarn.server.resourcemanager.rmapp.attempt.RMAppAttemptImpl: Processing event for appattempt_1385613010171_0001_000001 of type CONTAINER_ACQUIRED
2013-11-27 22:41:14,508 INFO org.apache.hadoop.yarn.server.resourcemanager.recovery.RMStateStore: Storing info for attempt: appattempt_1385613010171_0001_000001
2013-11-27 22:41:14,513 INFO org.apache.hadoop.yarn.server.resourcemanager.rmapp.attempt.RMAppAttemptImpl: Processing event for appattempt_1385613010171_0001_000001 of type ATTEMPT_SAVED
2013-11-27 22:41:14,513 INFO org.apache.hadoop.yarn.server.resourcemanager.rmapp.attempt.RMAppAttemptImpl: Sakshi appattempt_1385613010171_0001_000001 State change from ALLOCATED_SAVING to ALLOCATED after EVENT: ATTEMPT_SAVED
2013-11-27 22:41:14,511 INFO org.apache.hadoop.yarn.server.resourcemanager.scheduler.capacity.ParentQueue: Re-sorting assigned queue: root.default stats: default: capacity=1.0, absoluteCapacity=1.0, usedResources=<memory:2048, vCores:1>usedCapacity=0.25, absoluteUsedCapacity=0.25, numApps=1, numContainers=1
2013-11-27 22:41:14,514 INFO org.apache.hadoop.yarn.server.resourcemanager.scheduler.capacity.ParentQueue: assignedContainer queue=root usedCapacity=0.25 absoluteUsedCapacity=0.25 used=<memory:2048, vCores:1> cluster=<memory:8192, vCores:8>
2013-11-27 22:41:14,531 INFO org.apache.hadoop.yarn.server.resourcemanager.amlauncher.AMLauncher: Launching masterappattempt_1385613010171_0001_000001
2013-11-27 22:41:14,534 INFO org.apache.hadoop.yarn.server.resourcemanager.amlauncher.AMLauncher: Setting up container Container: [ContainerId: container_1385613010171_0001_01_000001, NodeId: ubuntusakshi:59487, NodeHttpAddress: ubuntusakshi:8042, Resource: <memory:2048, vCores:1>, Priority: 0, Token: Token { kind: ContainerToken, service: 127.0.1.1:59487 }, ] for AM appattempt_1385613010171_0001_000001
2013-11-27 22:41:14,535 INFO org.apache.hadoop.yarn.server.resourcemanager.amlauncher.AMLauncher: Command to launch container container_1385613010171_0001_01_000001 : $JAVA_HOME/bin/java -Dlog4j.configuration=container-log4j.properties -Dyarn.app.container.log.dir=<LOG_DIR> -Dyarn.app.container.log.filesize=0 -Dhadoop.root.logger=INFO,CLA  -Xmx1024m org.apache.hadoop.mapreduce.v2.app.MRAppMaster 1><LOG_DIR>/stdout 2><LOG_DIR>/stderr 
2013-11-27 22:41:14,721 INFO org.apache.hadoop.yarn.server.resourcemanager.amlauncher.AMLauncher: Done launching container Container: [ContainerId: container_1385613010171_0001_01_000001, NodeId: ubuntusakshi:59487, NodeHttpAddress: ubuntusakshi:8042, Resource: <memory:2048, vCores:1>, Priority: 0, Token: Token { kind: ContainerToken, service: 127.0.1.1:59487 }, ] for AM appattempt_1385613010171_0001_000001
2013-11-27 22:41:14,721 INFO org.apache.hadoop.yarn.server.resourcemanager.rmapp.attempt.RMAppAttemptImpl: Processing event for appattempt_1385613010171_0001_000001 of type LAUNCHED
2013-11-27 22:41:14,721 INFO org.apache.hadoop.yarn.server.resourcemanager.rmapp.attempt.RMAppAttemptImpl: Sakshi appattempt_1385613010171_0001_000001 State change from ALLOCATED to LAUNCHED after EVENT: LAUNCHED
2013-11-27 22:41:15,515 INFO org.apache.hadoop.yarn.server.resourcemanager.rmcontainer.RMContainerImpl: container_1385613010171_0001_01_000001 Container Transitioned from ACQUIRED to RUNNING
2013-11-27 22:41:23,706 INFO SecurityLogger.org.apache.hadoop.ipc.Server: Auth successful for appattempt_1385613010171_0001_000001 (auth:SIMPLE)
2013-11-27 22:41:23,711 INFO org.apache.hadoop.yarn.server.resourcemanager.ApplicationMasterService: AM registration appattempt_1385613010171_0001_000001
2013-11-27 22:41:23,711 INFO org.apache.hadoop.yarn.server.resourcemanager.RMAuditLogger: USER=sakshi	IP=127.0.0.1	OPERATION=Register App Master	TARGET=ApplicationMasterService	RESULT=SUCCESS	APPID=application_1385613010171_0001	APPATTEMPTID=appattempt_1385613010171_0001_000001
2013-11-27 22:41:23,712 INFO org.apache.hadoop.yarn.server.resourcemanager.rmapp.attempt.RMAppAttemptImpl: Processing event for appattempt_1385613010171_0001_000001 of type REGISTERED
2013-11-27 22:41:23,712 INFO org.apache.hadoop.yarn.server.resourcemanager.rmapp.attempt.RMAppAttemptImpl: Sakshi appattempt_1385613010171_0001_000001 State change from LAUNCHED to RUNNING after EVENT: REGISTERED
2013-11-27 22:41:23,713 INFO org.apache.hadoop.yarn.server.resourcemanager.rmapp.RMAppImpl: Sakshi application_1385613010171_0001 State change from ACCEPTED to RUNNING after EVENT: ATTEMPT_REGISTERED
2013-11-27 22:41:24,795 INFO org.apache.hadoop.yarn.server.resourcemanager.rmapp.attempt.RMAppAttemptImpl: Processing event for appattempt_1385613010171_0001_000001 of type STATUS_UPDATE
2013-11-27 22:41:25,568 INFO org.apache.hadoop.yarn.server.resourcemanager.rmcontainer.RMContainerImpl: container_1385613010171_0001_01_000002 Container Transitioned from NEW to ALLOCATED
2013-11-27 22:41:25,568 INFO org.apache.hadoop.yarn.server.resourcemanager.RMAuditLogger: USER=sakshi	OPERATION=AM Allocated Container	TARGET=SchedulerApp	RESULT=SUCCESS	APPID=application_1385613010171_0001	CONTAINERID=container_1385613010171_0001_01_000002
2013-11-27 22:41:25,568 INFO org.apache.hadoop.yarn.server.resourcemanager.scheduler.common.fica.FiCaSchedulerNode: Assigned container container_1385613010171_0001_01_000002 of capacity <memory:1024, vCores:1> on host ubuntusakshi:59487, which currently has 2 containers, <memory:3072, vCores:2> used and <memory:5120, vCores:6> available
2013-11-27 22:41:25,568 INFO org.apache.hadoop.yarn.server.resourcemanager.scheduler.capacity.LeafQueue: assignedContainer application=application_1385613010171_0001 container=Container: [ContainerId: container_1385613010171_0001_01_000002, NodeId: ubuntusakshi:59487, NodeHttpAddress: ubuntusakshi:8042, Resource: <memory:1024, vCores:1>, Priority: 20, Token: Token { kind: ContainerToken, service: 127.0.1.1:59487 }, ] containerId=container_1385613010171_0001_01_000002 queue=default: capacity=1.0, absoluteCapacity=1.0, usedResources=<memory:2048, vCores:1>usedCapacity=0.25, absoluteUsedCapacity=0.25, numApps=1, numContainers=1 usedCapacity=0.25 absoluteUsedCapacity=0.25 used=<memory:2048, vCores:1> cluster=<memory:8192, vCores:8>
2013-11-27 22:41:25,571 INFO org.apache.hadoop.yarn.server.resourcemanager.rmapp.attempt.RMAppAttemptImpl: Processing event for appattempt_1385613010171_0001_000001 of type CONTAINER_ALLOCATED
2013-11-27 22:41:25,571 INFO org.apache.hadoop.yarn.server.resourcemanager.scheduler.capacity.ParentQueue: Re-sorting assigned queue: root.default stats: default: capacity=1.0, absoluteCapacity=1.0, usedResources=<memory:3072, vCores:2>usedCapacity=0.375, absoluteUsedCapacity=0.375, numApps=1, numContainers=2
2013-11-27 22:41:25,573 INFO org.apache.hadoop.yarn.server.resourcemanager.scheduler.capacity.ParentQueue: assignedContainer queue=root usedCapacity=0.375 absoluteUsedCapacity=0.375 used=<memory:3072, vCores:2> cluster=<memory:8192, vCores:8>
2013-11-27 22:41:25,574 INFO org.apache.hadoop.yarn.server.resourcemanager.rmapp.attempt.RMAppAttemptImpl: Processing event for appattempt_1385613010171_0001_000001 of type CONTAINER_ALLOCATED
2013-11-27 22:41:25,574 INFO org.apache.hadoop.yarn.server.resourcemanager.rmcontainer.RMContainerImpl: container_1385613010171_0001_01_000003 Container Transitioned from NEW to ALLOCATED
2013-11-27 22:41:25,574 INFO org.apache.hadoop.yarn.server.resourcemanager.RMAuditLogger: USER=sakshi	OPERATION=AM Allocated Container	TARGET=SchedulerApp	RESULT=SUCCESS	APPID=application_1385613010171_0001	CONTAINERID=container_1385613010171_0001_01_000003
2013-11-27 22:41:25,574 INFO org.apache.hadoop.yarn.server.resourcemanager.scheduler.common.fica.FiCaSchedulerNode: Assigned container container_1385613010171_0001_01_000003 of capacity <memory:1024, vCores:1> on host ubuntusakshi:59487, which currently has 3 containers, <memory:4096, vCores:3> used and <memory:4096, vCores:5> available
2013-11-27 22:41:25,574 INFO org.apache.hadoop.yarn.server.resourcemanager.scheduler.capacity.LeafQueue: assignedContainer application=application_1385613010171_0001 container=Container: [ContainerId: container_1385613010171_0001_01_000003, NodeId: ubuntusakshi:59487, NodeHttpAddress: ubuntusakshi:8042, Resource: <memory:1024, vCores:1>, Priority: 20, Token: Token { kind: ContainerToken, service: 127.0.1.1:59487 }, ] containerId=container_1385613010171_0001_01_000003 queue=default: capacity=1.0, absoluteCapacity=1.0, usedResources=<memory:3072, vCores:2>usedCapacity=0.375, absoluteUsedCapacity=0.375, numApps=1, numContainers=2 usedCapacity=0.375 absoluteUsedCapacity=0.375 used=<memory:3072, vCores:2> cluster=<memory:8192, vCores:8>
2013-11-27 22:41:25,575 INFO org.apache.hadoop.yarn.server.resourcemanager.scheduler.capacity.ParentQueue: Re-sorting assigned queue: root.default stats: default: capacity=1.0, absoluteCapacity=1.0, usedResources=<memory:4096, vCores:3>usedCapacity=0.5, absoluteUsedCapacity=0.5, numApps=1, numContainers=3
2013-11-27 22:41:25,575 INFO org.apache.hadoop.yarn.server.resourcemanager.scheduler.capacity.ParentQueue: assignedContainer queue=root usedCapacity=0.5 absoluteUsedCapacity=0.5 used=<memory:4096, vCores:3> cluster=<memory:8192, vCores:8>
2013-11-27 22:41:25,575 INFO org.apache.hadoop.yarn.server.resourcemanager.rmapp.attempt.RMAppAttemptImpl: Processing event for appattempt_1385613010171_0001_000001 of type CONTAINER_ALLOCATED
2013-11-27 22:41:25,575 INFO org.apache.hadoop.yarn.server.resourcemanager.rmcontainer.RMContainerImpl: container_1385613010171_0001_01_000004 Container Transitioned from NEW to ALLOCATED
2013-11-27 22:41:25,575 INFO org.apache.hadoop.yarn.server.resourcemanager.RMAuditLogger: USER=sakshi	OPERATION=AM Allocated Container	TARGET=SchedulerApp	RESULT=SUCCESS	APPID=application_1385613010171_0001	CONTAINERID=container_1385613010171_0001_01_000004
2013-11-27 22:41:25,576 INFO org.apache.hadoop.yarn.server.resourcemanager.scheduler.common.fica.FiCaSchedulerNode: Assigned container container_1385613010171_0001_01_000004 of capacity <memory:1024, vCores:1> on host ubuntusakshi:59487, which currently has 4 containers, <memory:5120, vCores:4> used and <memory:3072, vCores:4> available
2013-11-27 22:41:25,576 INFO org.apache.hadoop.yarn.server.resourcemanager.scheduler.capacity.LeafQueue: assignedContainer application=application_1385613010171_0001 container=Container: [ContainerId: container_1385613010171_0001_01_000004, NodeId: ubuntusakshi:59487, NodeHttpAddress: ubuntusakshi:8042, Resource: <memory:1024, vCores:1>, Priority: 20, Token: Token { kind: ContainerToken, service: 127.0.1.1:59487 }, ] containerId=container_1385613010171_0001_01_000004 queue=default: capacity=1.0, absoluteCapacity=1.0, usedResources=<memory:4096, vCores:3>usedCapacity=0.5, absoluteUsedCapacity=0.5, numApps=1, numContainers=3 usedCapacity=0.5 absoluteUsedCapacity=0.5 used=<memory:4096, vCores:3> cluster=<memory:8192, vCores:8>
2013-11-27 22:41:25,576 INFO org.apache.hadoop.yarn.server.resourcemanager.scheduler.capacity.ParentQueue: Re-sorting assigned queue: root.default stats: default: capacity=1.0, absoluteCapacity=1.0, usedResources=<memory:5120, vCores:4>usedCapacity=0.625, absoluteUsedCapacity=0.625, numApps=1, numContainers=4
2013-11-27 22:41:25,576 INFO org.apache.hadoop.yarn.server.resourcemanager.scheduler.capacity.ParentQueue: assignedContainer queue=root usedCapacity=0.625 absoluteUsedCapacity=0.625 used=<memory:5120, vCores:4> cluster=<memory:8192, vCores:8>
2013-11-27 22:41:25,580 INFO org.apache.hadoop.yarn.server.resourcemanager.rmapp.attempt.RMAppAttemptImpl: Processing event for appattempt_1385613010171_0001_000001 of type CONTAINER_ALLOCATED
2013-11-27 22:41:25,580 INFO org.apache.hadoop.yarn.server.resourcemanager.rmcontainer.RMContainerImpl: container_1385613010171_0001_01_000005 Container Transitioned from NEW to ALLOCATED
2013-11-27 22:41:25,581 INFO org.apache.hadoop.yarn.server.resourcemanager.RMAuditLogger: USER=sakshi	OPERATION=AM Allocated Container	TARGET=SchedulerApp	RESULT=SUCCESS	APPID=application_1385613010171_0001	CONTAINERID=container_1385613010171_0001_01_000005
2013-11-27 22:41:25,581 INFO org.apache.hadoop.yarn.server.resourcemanager.scheduler.common.fica.FiCaSchedulerNode: Assigned container container_1385613010171_0001_01_000005 of capacity <memory:1024, vCores:1> on host ubuntusakshi:59487, which currently has 5 containers, <memory:6144, vCores:5> used and <memory:2048, vCores:3> available
2013-11-27 22:41:25,581 INFO org.apache.hadoop.yarn.server.resourcemanager.scheduler.capacity.LeafQueue: assignedContainer application=application_1385613010171_0001 container=Container: [ContainerId: container_1385613010171_0001_01_000005, NodeId: ubuntusakshi:59487, NodeHttpAddress: ubuntusakshi:8042, Resource: <memory:1024, vCores:1>, Priority: 20, Token: Token { kind: ContainerToken, service: 127.0.1.1:59487 }, ] containerId=container_1385613010171_0001_01_000005 queue=default: capacity=1.0, absoluteCapacity=1.0, usedResources=<memory:5120, vCores:4>usedCapacity=0.625, absoluteUsedCapacity=0.625, numApps=1, numContainers=4 usedCapacity=0.625 absoluteUsedCapacity=0.625 used=<memory:5120, vCores:4> cluster=<memory:8192, vCores:8>
2013-11-27 22:41:25,581 INFO org.apache.hadoop.yarn.server.resourcemanager.scheduler.capacity.ParentQueue: Re-sorting assigned queue: root.default stats: default: capacity=1.0, absoluteCapacity=1.0, usedResources=<memory:6144, vCores:5>usedCapacity=0.75, absoluteUsedCapacity=0.75, numApps=1, numContainers=5
2013-11-27 22:41:25,581 INFO org.apache.hadoop.yarn.server.resourcemanager.scheduler.capacity.ParentQueue: assignedContainer queue=root usedCapacity=0.75 absoluteUsedCapacity=0.75 used=<memory:6144, vCores:5> cluster=<memory:8192, vCores:8>
2013-11-27 22:41:25,582 INFO org.apache.hadoop.yarn.server.resourcemanager.rmapp.attempt.RMAppAttemptImpl: Processing event for appattempt_1385613010171_0001_000001 of type CONTAINER_ALLOCATED
2013-11-27 22:41:25,583 INFO org.apache.hadoop.yarn.server.resourcemanager.rmcontainer.RMContainerImpl: container_1385613010171_0001_01_000006 Container Transitioned from NEW to ALLOCATED
2013-11-27 22:41:25,583 INFO org.apache.hadoop.yarn.server.resourcemanager.RMAuditLogger: USER=sakshi	OPERATION=AM Allocated Container	TARGET=SchedulerApp	RESULT=SUCCESS	APPID=application_1385613010171_0001	CONTAINERID=container_1385613010171_0001_01_000006
2013-11-27 22:41:25,583 INFO org.apache.hadoop.yarn.server.resourcemanager.scheduler.common.fica.FiCaSchedulerNode: Assigned container container_1385613010171_0001_01_000006 of capacity <memory:1024, vCores:1> on host ubuntusakshi:59487, which currently has 6 containers, <memory:7168, vCores:6> used and <memory:1024, vCores:2> available
2013-11-27 22:41:25,583 INFO org.apache.hadoop.yarn.server.resourcemanager.scheduler.capacity.LeafQueue: assignedContainer application=application_1385613010171_0001 container=Container: [ContainerId: container_1385613010171_0001_01_000006, NodeId: ubuntusakshi:59487, NodeHttpAddress: ubuntusakshi:8042, Resource: <memory:1024, vCores:1>, Priority: 20, Token: Token { kind: ContainerToken, service: 127.0.1.1:59487 }, ] containerId=container_1385613010171_0001_01_000006 queue=default: capacity=1.0, absoluteCapacity=1.0, usedResources=<memory:6144, vCores:5>usedCapacity=0.75, absoluteUsedCapacity=0.75, numApps=1, numContainers=5 usedCapacity=0.75 absoluteUsedCapacity=0.75 used=<memory:6144, vCores:5> cluster=<memory:8192, vCores:8>
2013-11-27 22:41:25,583 INFO org.apache.hadoop.yarn.server.resourcemanager.scheduler.capacity.ParentQueue: Re-sorting assigned queue: root.default stats: default: capacity=1.0, absoluteCapacity=1.0, usedResources=<memory:7168, vCores:6>usedCapacity=0.875, absoluteUsedCapacity=0.875, numApps=1, numContainers=6
2013-11-27 22:41:25,583 INFO org.apache.hadoop.yarn.server.resourcemanager.scheduler.capacity.ParentQueue: assignedContainer queue=root usedCapacity=0.875 absoluteUsedCapacity=0.875 used=<memory:7168, vCores:6> cluster=<memory:8192, vCores:8>
2013-11-27 22:41:25,861 INFO org.apache.hadoop.yarn.server.resourcemanager.rmapp.attempt.RMAppAttemptImpl: Processing event for appattempt_1385613010171_0001_000001 of type STATUS_UPDATE
2013-11-27 22:41:25,861 INFO org.apache.hadoop.yarn.server.resourcemanager.rmapp.attempt.RMAppAttemptImpl: Processing event for appattempt_1385613010171_0001_000001 of type CONTAINER_ACQUIRED
2013-11-27 22:41:25,862 INFO org.apache.hadoop.yarn.server.resourcemanager.rmcontainer.RMContainerImpl: container_1385613010171_0001_01_000002 Container Transitioned from ALLOCATED to ACQUIRED
2013-11-27 22:41:25,862 INFO org.apache.hadoop.yarn.server.resourcemanager.rmapp.attempt.RMAppAttemptImpl: Processing event for appattempt_1385613010171_0001_000001 of type CONTAINER_ACQUIRED
2013-11-27 22:41:25,862 INFO org.apache.hadoop.yarn.server.resourcemanager.rmcontainer.RMContainerImpl: container_1385613010171_0001_01_000003 Container Transitioned from ALLOCATED to ACQUIRED
2013-11-27 22:41:25,863 INFO org.apache.hadoop.yarn.server.resourcemanager.rmapp.attempt.RMAppAttemptImpl: Processing event for appattempt_1385613010171_0001_000001 of type CONTAINER_ACQUIRED
2013-11-27 22:41:25,863 INFO org.apache.hadoop.yarn.server.resourcemanager.rmcontainer.RMContainerImpl: container_1385613010171_0001_01_000004 Container Transitioned from ALLOCATED to ACQUIRED
2013-11-27 22:41:25,863 INFO org.apache.hadoop.yarn.server.resourcemanager.rmapp.attempt.RMAppAttemptImpl: Processing event for appattempt_1385613010171_0001_000001 of type CONTAINER_ACQUIRED
2013-11-27 22:41:25,863 INFO org.apache.hadoop.yarn.server.resourcemanager.rmcontainer.RMContainerImpl: container_1385613010171_0001_01_000005 Container Transitioned from ALLOCATED to ACQUIRED
2013-11-27 22:41:25,864 INFO org.apache.hadoop.yarn.server.resourcemanager.rmapp.attempt.RMAppAttemptImpl: Processing event for appattempt_1385613010171_0001_000001 of type CONTAINER_ACQUIRED
2013-11-27 22:41:25,864 INFO org.apache.hadoop.yarn.server.resourcemanager.rmcontainer.RMContainerImpl: container_1385613010171_0001_01_000006 Container Transitioned from ALLOCATED to ACQUIRED
2013-11-27 22:41:26,886 INFO org.apache.hadoop.yarn.server.resourcemanager.scheduler.AppSchedulingInfo: checking for deactivate... 
2013-11-27 22:41:26,887 INFO org.apache.hadoop.yarn.server.resourcemanager.rmapp.attempt.RMAppAttemptImpl: Processing event for appattempt_1385613010171_0001_000001 of type STATUS_UPDATE
2013-11-27 22:41:27,889 INFO org.apache.hadoop.yarn.server.resourcemanager.rmapp.attempt.RMAppAttemptImpl: Processing event for appattempt_1385613010171_0001_000001 of type STATUS_UPDATE
2013-11-27 22:41:28,266 INFO org.apache.hadoop.yarn.server.resourcemanager.rmcontainer.RMContainerImpl: container_1385613010171_0001_01_000003 Container Transitioned from ACQUIRED to RUNNING
2013-11-27 22:41:28,266 INFO org.apache.hadoop.yarn.server.resourcemanager.rmcontainer.RMContainerImpl: container_1385613010171_0001_01_000004 Container Transitioned from ACQUIRED to RUNNING
2013-11-27 22:41:28,266 INFO org.apache.hadoop.yarn.server.resourcemanager.rmcontainer.RMContainerImpl: container_1385613010171_0001_01_000005 Container Transitioned from ACQUIRED to RUNNING
2013-11-27 22:41:28,295 INFO org.apache.hadoop.yarn.server.resourcemanager.rmcontainer.RMContainerImpl: container_1385613010171_0001_01_000006 Container Transitioned from ACQUIRED to RUNNING
2013-11-27 22:41:28,892 INFO org.apache.hadoop.yarn.server.resourcemanager.rmapp.attempt.RMAppAttemptImpl: Processing event for appattempt_1385613010171_0001_000001 of type STATUS_UPDATE
2013-11-27 22:41:29,273 INFO org.apache.hadoop.yarn.server.resourcemanager.rmcontainer.RMContainerImpl: container_1385613010171_0001_01_000002 Container Transitioned from ACQUIRED to RUNNING
2013-11-27 22:41:29,985 INFO org.apache.hadoop.yarn.server.resourcemanager.rmapp.attempt.RMAppAttemptImpl: Processing event for appattempt_1385613010171_0001_000001 of type STATUS_UPDATE
2013-11-27 22:41:30,988 INFO org.apache.hadoop.yarn.server.resourcemanager.rmapp.attempt.RMAppAttemptImpl: Processing event for appattempt_1385613010171_0001_000001 of type STATUS_UPDATE
2013-11-27 22:41:31,990 INFO org.apache.hadoop.yarn.server.resourcemanager.rmapp.attempt.RMAppAttemptImpl: Processing event for appattempt_1385613010171_0001_000001 of type STATUS_UPDATE
2013-11-27 22:41:32,992 INFO org.apache.hadoop.yarn.server.resourcemanager.rmapp.attempt.RMAppAttemptImpl: Processing event for appattempt_1385613010171_0001_000001 of type STATUS_UPDATE
2013-11-27 22:41:33,994 INFO org.apache.hadoop.yarn.server.resourcemanager.rmapp.attempt.RMAppAttemptImpl: Processing event for appattempt_1385613010171_0001_000001 of type STATUS_UPDATE
2013-11-27 22:41:35,020 INFO org.apache.hadoop.yarn.server.resourcemanager.rmapp.attempt.RMAppAttemptImpl: Processing event for appattempt_1385613010171_0001_000001 of type STATUS_UPDATE
2013-11-27 22:41:36,015 INFO org.apache.hadoop.yarn.server.resourcemanager.rmapp.attempt.RMAppAttemptImpl: Processing event for appattempt_1385613010171_0001_000001 of type STATUS_UPDATE
2013-11-27 22:41:37,016 INFO org.apache.hadoop.yarn.server.resourcemanager.rmapp.attempt.RMAppAttemptImpl: Processing event for appattempt_1385613010171_0001_000001 of type STATUS_UPDATE
2013-11-27 22:41:38,018 INFO org.apache.hadoop.yarn.server.resourcemanager.rmapp.attempt.RMAppAttemptImpl: Processing event for appattempt_1385613010171_0001_000001 of type STATUS_UPDATE
2013-11-27 22:41:39,021 INFO org.apache.hadoop.yarn.server.resourcemanager.rmapp.attempt.RMAppAttemptImpl: Processing event for appattempt_1385613010171_0001_000001 of type STATUS_UPDATE
2013-11-27 22:41:40,080 INFO org.apache.hadoop.yarn.server.resourcemanager.rmapp.attempt.RMAppAttemptImpl: Processing event for appattempt_1385613010171_0001_000001 of type STATUS_UPDATE
2013-11-27 22:41:41,093 INFO org.apache.hadoop.yarn.server.resourcemanager.rmapp.attempt.RMAppAttemptImpl: Processing event for appattempt_1385613010171_0001_000001 of type STATUS_UPDATE
2013-11-27 22:41:42,100 INFO org.apache.hadoop.yarn.server.resourcemanager.rmapp.attempt.RMAppAttemptImpl: Processing event for appattempt_1385613010171_0001_000001 of type STATUS_UPDATE
2013-11-27 22:41:43,099 INFO org.apache.hadoop.yarn.server.resourcemanager.rmapp.attempt.RMAppAttemptImpl: Processing event for appattempt_1385613010171_0001_000001 of type STATUS_UPDATE
2013-11-27 22:41:44,102 INFO org.apache.hadoop.yarn.server.resourcemanager.rmapp.attempt.RMAppAttemptImpl: Processing event for appattempt_1385613010171_0001_000001 of type STATUS_UPDATE
2013-11-27 22:41:45,104 INFO org.apache.hadoop.yarn.server.resourcemanager.rmapp.attempt.RMAppAttemptImpl: Processing event for appattempt_1385613010171_0001_000001 of type STATUS_UPDATE
2013-11-27 22:41:46,146 INFO org.apache.hadoop.yarn.server.resourcemanager.rmapp.attempt.RMAppAttemptImpl: Processing event for appattempt_1385613010171_0001_000001 of type STATUS_UPDATE
2013-11-27 22:41:47,166 INFO org.apache.hadoop.yarn.server.resourcemanager.rmapp.attempt.RMAppAttemptImpl: Processing event for appattempt_1385613010171_0001_000001 of type STATUS_UPDATE
2013-11-27 22:41:48,177 INFO org.apache.hadoop.yarn.server.resourcemanager.rmapp.attempt.RMAppAttemptImpl: Processing event for appattempt_1385613010171_0001_000001 of type STATUS_UPDATE
2013-11-27 22:41:49,236 INFO org.apache.hadoop.yarn.server.resourcemanager.rmapp.attempt.RMAppAttemptImpl: Processing event for appattempt_1385613010171_0001_000001 of type STATUS_UPDATE
2013-11-27 22:41:50,231 INFO org.apache.hadoop.yarn.server.resourcemanager.rmapp.attempt.RMAppAttemptImpl: Processing event for appattempt_1385613010171_0001_000001 of type STATUS_UPDATE
2013-11-27 22:41:51,236 INFO org.apache.hadoop.yarn.server.resourcemanager.rmapp.attempt.RMAppAttemptImpl: Processing event for appattempt_1385613010171_0001_000001 of type STATUS_UPDATE
2013-11-27 22:41:52,367 INFO org.apache.hadoop.yarn.server.resourcemanager.rmapp.attempt.RMAppAttemptImpl: Processing event for appattempt_1385613010171_0001_000001 of type STATUS_UPDATE
2013-11-27 22:41:53,411 INFO org.apache.hadoop.yarn.server.resourcemanager.rmapp.attempt.RMAppAttemptImpl: Processing event for appattempt_1385613010171_0001_000001 of type STATUS_UPDATE
2013-11-27 22:41:54,423 INFO org.apache.hadoop.yarn.server.resourcemanager.rmapp.attempt.RMAppAttemptImpl: Processing event for appattempt_1385613010171_0001_000001 of type STATUS_UPDATE
2013-11-27 22:41:55,429 INFO org.apache.hadoop.yarn.server.resourcemanager.rmapp.attempt.RMAppAttemptImpl: Processing event for appattempt_1385613010171_0001_000001 of type STATUS_UPDATE
2013-11-27 22:41:56,452 INFO org.apache.hadoop.yarn.server.resourcemanager.rmapp.attempt.RMAppAttemptImpl: Processing event for appattempt_1385613010171_0001_000001 of type STATUS_UPDATE
2013-11-27 22:41:57,454 INFO org.apache.hadoop.yarn.server.resourcemanager.rmapp.attempt.RMAppAttemptImpl: Processing event for appattempt_1385613010171_0001_000001 of type STATUS_UPDATE
2013-11-27 22:41:58,457 INFO org.apache.hadoop.yarn.server.resourcemanager.rmapp.attempt.RMAppAttemptImpl: Processing event for appattempt_1385613010171_0001_000001 of type STATUS_UPDATE
2013-11-27 22:41:59,459 INFO org.apache.hadoop.yarn.server.resourcemanager.rmapp.attempt.RMAppAttemptImpl: Processing event for appattempt_1385613010171_0001_000001 of type STATUS_UPDATE
2013-11-27 22:42:00,476 INFO org.apache.hadoop.yarn.server.resourcemanager.rmapp.attempt.RMAppAttemptImpl: Processing event for appattempt_1385613010171_0001_000001 of type STATUS_UPDATE
2013-11-27 22:42:01,475 INFO org.apache.hadoop.yarn.server.resourcemanager.rmapp.attempt.RMAppAttemptImpl: Processing event for appattempt_1385613010171_0001_000001 of type STATUS_UPDATE
2013-11-27 22:42:02,478 INFO org.apache.hadoop.yarn.server.resourcemanager.rmapp.attempt.RMAppAttemptImpl: Processing event for appattempt_1385613010171_0001_000001 of type STATUS_UPDATE
2013-11-27 22:42:03,481 INFO org.apache.hadoop.yarn.server.resourcemanager.rmapp.attempt.RMAppAttemptImpl: Processing event for appattempt_1385613010171_0001_000001 of type STATUS_UPDATE
2013-11-27 22:43:52,365 INFO org.apache.hadoop.yarn.server.resourcemanager.rmapp.attempt.RMAppAttemptImpl: Processing event for appattempt_1385613010171_0001_000001 of type STATUS_UPDATE
2013-11-27 22:43:55,428 INFO SecurityLogger.org.apache.hadoop.ipc.Server: Auth successful for appattempt_1385613010171_0001_000001 (auth:SIMPLE)
2013-11-27 22:43:57,498 INFO org.apache.hadoop.yarn.server.resourcemanager.rmapp.attempt.RMAppAttemptImpl: Processing event for appattempt_1385613010171_0001_000001 of type STATUS_UPDATE
2013-11-27 22:43:59,485 INFO org.apache.hadoop.yarn.server.resourcemanager.rmapp.attempt.RMAppAttemptImpl: Processing event for appattempt_1385613010171_0001_000001 of type STATUS_UPDATE
2013-11-27 22:44:02,624 INFO org.apache.hadoop.yarn.server.resourcemanager.rmapp.attempt.RMAppAttemptImpl: Processing event for appattempt_1385613010171_0001_000001 of type STATUS_UPDATE
2013-11-27 22:44:09,362 INFO org.apache.hadoop.yarn.server.resourcemanager.rmapp.attempt.RMAppAttemptImpl: Processing event for appattempt_1385613010171_0001_000001 of type STATUS_UPDATE
2013-11-27 22:44:10,521 INFO org.apache.hadoop.yarn.server.resourcemanager.rmapp.attempt.RMAppAttemptImpl: Processing event for appattempt_1385613010171_0001_000001 of type STATUS_UPDATE
2013-11-27 22:44:13,808 INFO org.apache.hadoop.yarn.server.resourcemanager.rmapp.attempt.RMAppAttemptImpl: Processing event for appattempt_1385613010171_0001_000001 of type STATUS_UPDATE
2013-11-27 22:44:16,436 INFO org.apache.hadoop.yarn.server.resourcemanager.rmapp.attempt.RMAppAttemptImpl: Processing event for appattempt_1385613010171_0001_000001 of type STATUS_UPDATE
2013-11-27 22:44:20,840 INFO org.apache.hadoop.yarn.server.resourcemanager.rmapp.attempt.RMAppAttemptImpl: Processing event for appattempt_1385613010171_0001_000001 of type STATUS_UPDATE
2013-11-27 22:44:25,063 INFO org.apache.hadoop.yarn.server.resourcemanager.rmapp.attempt.RMAppAttemptImpl: Processing event for appattempt_1385613010171_0001_000001 of type STATUS_UPDATE
2013-11-27 22:44:28,489 INFO org.apache.hadoop.yarn.server.resourcemanager.rmapp.attempt.RMAppAttemptImpl: Processing event for appattempt_1385613010171_0001_000001 of type STATUS_UPDATE
2013-11-27 22:44:30,568 INFO org.apache.hadoop.yarn.server.resourcemanager.rmapp.attempt.RMAppAttemptImpl: Processing event for appattempt_1385613010171_0001_000001 of type STATUS_UPDATE
2013-11-27 22:44:30,980 INFO org.apache.hadoop.yarn.server.resourcemanager.rmapp.attempt.RMAppAttemptImpl: Processing event for appattempt_1385613010171_0001_000001 of type CONTAINER_FINISHED
2013-11-27 22:44:30,991 INFO org.apache.hadoop.yarn.server.resourcemanager.rmcontainer.RMContainerImpl: container_1385613010171_0001_01_000004 Container Transitioned from RUNNING to COMPLETED
2013-11-27 22:44:30,991 INFO org.apache.hadoop.yarn.server.resourcemanager.scheduler.common.fica.FiCaSchedulerApp: Completed container: container_1385613010171_0001_01_000004 in state: COMPLETED event:FINISHED
2013-11-27 22:44:30,997 INFO org.apache.hadoop.yarn.server.resourcemanager.RMAuditLogger: USER=sakshi	OPERATION=AM Released Container	TARGET=SchedulerApp	RESULT=SUCCESS	APPID=application_1385613010171_0001	CONTAINERID=container_1385613010171_0001_01_000004
2013-11-27 22:44:31,035 INFO org.apache.hadoop.yarn.server.resourcemanager.scheduler.common.fica.FiCaSchedulerNode: Released container container_1385613010171_0001_01_000004 of capacity <memory:1024, vCores:1> on host ubuntusakshi:59487, which currently has 5 containers, <memory:6144, vCores:5> used and <memory:2048, vCores:3> available, release resources=true
2013-11-27 22:44:31,051 INFO org.apache.hadoop.yarn.server.resourcemanager.scheduler.capacity.LeafQueue: default used=<memory:6144, vCores:5> numContainers=5 user=sakshi user-resources=<memory:6144, vCores:5>
2013-11-27 22:44:31,113 INFO org.apache.hadoop.yarn.server.resourcemanager.scheduler.capacity.LeafQueue: completedContainer container=Container: [ContainerId: container_1385613010171_0001_01_000004, NodeId: ubuntusakshi:59487, NodeHttpAddress: ubuntusakshi:8042, Resource: <memory:1024, vCores:1>, Priority: 20, Token: Token { kind: ContainerToken, service: 127.0.1.1:59487 }, ] resource=<memory:1024, vCores:1> queue=default: capacity=1.0, absoluteCapacity=1.0, usedResources=<memory:6144, vCores:5>usedCapacity=0.75, absoluteUsedCapacity=0.75, numApps=1, numContainers=5 usedCapacity=0.75 absoluteUsedCapacity=0.75 used=<memory:6144, vCores:5> cluster=<memory:8192, vCores:8>
2013-11-27 22:44:31,114 INFO org.apache.hadoop.yarn.server.resourcemanager.scheduler.capacity.ParentQueue: completedContainer queue=root usedCapacity=0.75 absoluteUsedCapacity=0.75 used=<memory:6144, vCores:5> cluster=<memory:8192, vCores:8>
2013-11-27 22:44:31,196 INFO org.apache.hadoop.yarn.server.resourcemanager.scheduler.capacity.ParentQueue: Re-sorting completed queue: root.default stats: default: capacity=1.0, absoluteCapacity=1.0, usedResources=<memory:6144, vCores:5>usedCapacity=0.75, absoluteUsedCapacity=0.75, numApps=1, numContainers=5
2013-11-27 22:44:31,197 INFO org.apache.hadoop.yarn.server.resourcemanager.scheduler.capacity.CapacityScheduler: Application appattempt_1385613010171_0001_000001 released container container_1385613010171_0001_01_000004 on node: host: ubuntusakshi:59487 #containers=5 available=2048 used=6144 with event: FINISHED
2013-11-27 22:44:31,630 INFO org.apache.hadoop.yarn.server.resourcemanager.rmapp.attempt.RMAppAttemptImpl: Processing event for appattempt_1385613010171_0001_000001 of type STATUS_UPDATE
2013-11-27 22:44:32,557 INFO org.apache.hadoop.yarn.server.resourcemanager.rmcontainer.RMContainerImpl: container_1385613010171_0001_01_000002 Container Transitioned from RUNNING to COMPLETED
2013-11-27 22:44:32,557 INFO org.apache.hadoop.yarn.server.resourcemanager.scheduler.common.fica.FiCaSchedulerApp: Completed container: container_1385613010171_0001_01_000002 in state: COMPLETED event:FINISHED
2013-11-27 22:44:32,557 INFO org.apache.hadoop.yarn.server.resourcemanager.RMAuditLogger: USER=sakshi	OPERATION=AM Released Container	TARGET=SchedulerApp	RESULT=SUCCESS	APPID=application_1385613010171_0001	CONTAINERID=container_1385613010171_0001_01_000002
2013-11-27 22:44:32,557 INFO org.apache.hadoop.yarn.server.resourcemanager.scheduler.common.fica.FiCaSchedulerNode: Released container container_1385613010171_0001_01_000002 of capacity <memory:1024, vCores:1> on host ubuntusakshi:59487, which currently has 4 containers, <memory:5120, vCores:4> used and <memory:3072, vCores:4> available, release resources=true
2013-11-27 22:44:32,557 INFO org.apache.hadoop.yarn.server.resourcemanager.scheduler.capacity.LeafQueue: default used=<memory:5120, vCores:4> numContainers=4 user=sakshi user-resources=<memory:5120, vCores:4>
2013-11-27 22:44:32,557 INFO org.apache.hadoop.yarn.server.resourcemanager.scheduler.capacity.LeafQueue: completedContainer container=Container: [ContainerId: container_1385613010171_0001_01_000002, NodeId: ubuntusakshi:59487, NodeHttpAddress: ubuntusakshi:8042, Resource: <memory:1024, vCores:1>, Priority: 20, Token: Token { kind: ContainerToken, service: 127.0.1.1:59487 }, ] resource=<memory:1024, vCores:1> queue=default: capacity=1.0, absoluteCapacity=1.0, usedResources=<memory:5120, vCores:4>usedCapacity=0.625, absoluteUsedCapacity=0.625, numApps=1, numContainers=4 usedCapacity=0.625 absoluteUsedCapacity=0.625 used=<memory:5120, vCores:4> cluster=<memory:8192, vCores:8>
2013-11-27 22:44:32,557 INFO org.apache.hadoop.yarn.server.resourcemanager.scheduler.capacity.ParentQueue: completedContainer queue=root usedCapacity=0.625 absoluteUsedCapacity=0.625 used=<memory:5120, vCores:4> cluster=<memory:8192, vCores:8>
2013-11-27 22:44:32,557 INFO org.apache.hadoop.yarn.server.resourcemanager.rmapp.attempt.RMAppAttemptImpl: Processing event for appattempt_1385613010171_0001_000001 of type CONTAINER_FINISHED
2013-11-27 22:44:32,579 INFO org.apache.hadoop.yarn.server.resourcemanager.scheduler.capacity.ParentQueue: Re-sorting completed queue: root.default stats: default: capacity=1.0, absoluteCapacity=1.0, usedResources=<memory:5120, vCores:4>usedCapacity=0.625, absoluteUsedCapacity=0.625, numApps=1, numContainers=4
2013-11-27 22:44:32,674 INFO org.apache.hadoop.yarn.server.resourcemanager.scheduler.capacity.CapacityScheduler: Application appattempt_1385613010171_0001_000001 released container container_1385613010171_0001_01_000002 on node: host: ubuntusakshi:59487 #containers=4 available=3072 used=5120 with event: FINISHED
2013-11-27 22:44:32,675 INFO org.apache.hadoop.yarn.server.resourcemanager.rmcontainer.RMContainerImpl: container_1385613010171_0001_01_000003 Container Transitioned from RUNNING to COMPLETED
2013-11-27 22:44:32,675 INFO org.apache.hadoop.yarn.server.resourcemanager.scheduler.common.fica.FiCaSchedulerApp: Completed container: container_1385613010171_0001_01_000003 in state: COMPLETED event:FINISHED
2013-11-27 22:44:32,675 INFO org.apache.hadoop.yarn.server.resourcemanager.RMAuditLogger: USER=sakshi	OPERATION=AM Released Container	TARGET=SchedulerApp	RESULT=SUCCESS	APPID=application_1385613010171_0001	CONTAINERID=container_1385613010171_0001_01_000003
2013-11-27 22:44:32,675 INFO org.apache.hadoop.yarn.server.resourcemanager.rmapp.attempt.RMAppAttemptImpl: Processing event for appattempt_1385613010171_0001_000001 of type CONTAINER_FINISHED
2013-11-27 22:44:32,689 INFO org.apache.hadoop.yarn.server.resourcemanager.scheduler.common.fica.FiCaSchedulerNode: Released container container_1385613010171_0001_01_000003 of capacity <memory:1024, vCores:1> on host ubuntusakshi:59487, which currently has 3 containers, <memory:4096, vCores:3> used and <memory:4096, vCores:5> available, release resources=true
2013-11-27 22:44:32,690 INFO org.apache.hadoop.yarn.server.resourcemanager.scheduler.capacity.LeafQueue: default used=<memory:4096, vCores:3> numContainers=3 user=sakshi user-resources=<memory:4096, vCores:3>
2013-11-27 22:44:32,690 INFO org.apache.hadoop.yarn.server.resourcemanager.scheduler.capacity.LeafQueue: completedContainer container=Container: [ContainerId: container_1385613010171_0001_01_000003, NodeId: ubuntusakshi:59487, NodeHttpAddress: ubuntusakshi:8042, Resource: <memory:1024, vCores:1>, Priority: 20, Token: Token { kind: ContainerToken, service: 127.0.1.1:59487 }, ] resource=<memory:1024, vCores:1> queue=default: capacity=1.0, absoluteCapacity=1.0, usedResources=<memory:4096, vCores:3>usedCapacity=0.5, absoluteUsedCapacity=0.5, numApps=1, numContainers=3 usedCapacity=0.5 absoluteUsedCapacity=0.5 used=<memory:4096, vCores:3> cluster=<memory:8192, vCores:8>
2013-11-27 22:44:32,690 INFO org.apache.hadoop.yarn.server.resourcemanager.scheduler.capacity.ParentQueue: completedContainer queue=root usedCapacity=0.5 absoluteUsedCapacity=0.5 used=<memory:4096, vCores:3> cluster=<memory:8192, vCores:8>
2013-11-27 22:44:32,690 INFO org.apache.hadoop.yarn.server.resourcemanager.scheduler.capacity.ParentQueue: Re-sorting completed queue: root.default stats: default: capacity=1.0, absoluteCapacity=1.0, usedResources=<memory:4096, vCores:3>usedCapacity=0.5, absoluteUsedCapacity=0.5, numApps=1, numContainers=3
2013-11-27 22:44:32,725 INFO org.apache.hadoop.yarn.server.resourcemanager.scheduler.capacity.CapacityScheduler: Application appattempt_1385613010171_0001_000001 released container container_1385613010171_0001_01_000003 on node: host: ubuntusakshi:59487 #containers=3 available=4096 used=4096 with event: FINISHED
2013-11-27 22:44:33,228 INFO org.apache.hadoop.yarn.server.resourcemanager.rmapp.attempt.RMAppAttemptImpl: Processing event for appattempt_1385613010171_0001_000001 of type STATUS_UPDATE
2013-11-27 22:44:33,851 INFO org.apache.hadoop.yarn.server.resourcemanager.rmcontainer.RMContainerImpl: container_1385613010171_0001_01_000006 Container Transitioned from RUNNING to COMPLETED
2013-11-27 22:44:33,851 INFO org.apache.hadoop.yarn.server.resourcemanager.scheduler.common.fica.FiCaSchedulerApp: Completed container: container_1385613010171_0001_01_000006 in state: COMPLETED event:FINISHED
2013-11-27 22:44:33,851 INFO org.apache.hadoop.yarn.server.resourcemanager.RMAuditLogger: USER=sakshi	OPERATION=AM Released Container	TARGET=SchedulerApp	RESULT=SUCCESS	APPID=application_1385613010171_0001	CONTAINERID=container_1385613010171_0001_01_000006
2013-11-27 22:44:33,851 INFO org.apache.hadoop.yarn.server.resourcemanager.scheduler.common.fica.FiCaSchedulerNode: Released container container_1385613010171_0001_01_000006 of capacity <memory:1024, vCores:1> on host ubuntusakshi:59487, which currently has 2 containers, <memory:3072, vCores:2> used and <memory:5120, vCores:6> available, release resources=true
2013-11-27 22:44:33,851 INFO org.apache.hadoop.yarn.server.resourcemanager.scheduler.capacity.LeafQueue: default used=<memory:3072, vCores:2> numContainers=2 user=sakshi user-resources=<memory:3072, vCores:2>
2013-11-27 22:44:33,852 INFO org.apache.hadoop.yarn.server.resourcemanager.scheduler.capacity.LeafQueue: completedContainer container=Container: [ContainerId: container_1385613010171_0001_01_000006, NodeId: ubuntusakshi:59487, NodeHttpAddress: ubuntusakshi:8042, Resource: <memory:1024, vCores:1>, Priority: 20, Token: Token { kind: ContainerToken, service: 127.0.1.1:59487 }, ] resource=<memory:1024, vCores:1> queue=default: capacity=1.0, absoluteCapacity=1.0, usedResources=<memory:3072, vCores:2>usedCapacity=0.375, absoluteUsedCapacity=0.375, numApps=1, numContainers=2 usedCapacity=0.375 absoluteUsedCapacity=0.375 used=<memory:3072, vCores:2> cluster=<memory:8192, vCores:8>
2013-11-27 22:44:33,852 INFO org.apache.hadoop.yarn.server.resourcemanager.scheduler.capacity.ParentQueue: completedContainer queue=root usedCapacity=0.375 absoluteUsedCapacity=0.375 used=<memory:3072, vCores:2> cluster=<memory:8192, vCores:8>
2013-11-27 22:44:33,852 INFO org.apache.hadoop.yarn.server.resourcemanager.rmapp.attempt.RMAppAttemptImpl: Processing event for appattempt_1385613010171_0001_000001 of type CONTAINER_FINISHED
2013-11-27 22:44:33,862 INFO org.apache.hadoop.yarn.server.resourcemanager.scheduler.capacity.ParentQueue: Re-sorting completed queue: root.default stats: default: capacity=1.0, absoluteCapacity=1.0, usedResources=<memory:3072, vCores:2>usedCapacity=0.375, absoluteUsedCapacity=0.375, numApps=1, numContainers=2
2013-11-27 22:44:33,886 INFO org.apache.hadoop.yarn.server.resourcemanager.scheduler.capacity.CapacityScheduler: Application appattempt_1385613010171_0001_000001 released container container_1385613010171_0001_01_000006 on node: host: ubuntusakshi:59487 #containers=2 available=5120 used=3072 with event: FINISHED
2013-11-27 22:44:34,368 INFO org.apache.hadoop.yarn.server.resourcemanager.rmapp.attempt.RMAppAttemptImpl: Processing event for appattempt_1385613010171_0001_000001 of type STATUS_UPDATE
2013-11-27 22:44:35,091 INFO org.apache.hadoop.yarn.server.resourcemanager.rmcontainer.RMContainerImpl: container_1385613010171_0001_01_000005 Container Transitioned from RUNNING to COMPLETED
2013-11-27 22:44:35,091 INFO org.apache.hadoop.yarn.server.resourcemanager.scheduler.common.fica.FiCaSchedulerApp: Completed container: container_1385613010171_0001_01_000005 in state: COMPLETED event:FINISHED
2013-11-27 22:44:35,091 INFO org.apache.hadoop.yarn.server.resourcemanager.RMAuditLogger: USER=sakshi	OPERATION=AM Released Container	TARGET=SchedulerApp	RESULT=SUCCESS	APPID=application_1385613010171_0001	CONTAINERID=container_1385613010171_0001_01_000005
2013-11-27 22:44:35,091 INFO org.apache.hadoop.yarn.server.resourcemanager.scheduler.common.fica.FiCaSchedulerNode: Released container container_1385613010171_0001_01_000005 of capacity <memory:1024, vCores:1> on host ubuntusakshi:59487, which currently has 1 containers, <memory:2048, vCores:1> used and <memory:6144, vCores:7> available, release resources=true
2013-11-27 22:44:35,091 INFO org.apache.hadoop.yarn.server.resourcemanager.scheduler.capacity.LeafQueue: default used=<memory:2048, vCores:1> numContainers=1 user=sakshi user-resources=<memory:2048, vCores:1>
2013-11-27 22:44:35,092 INFO org.apache.hadoop.yarn.server.resourcemanager.rmapp.attempt.RMAppAttemptImpl: Processing event for appattempt_1385613010171_0001_000001 of type CONTAINER_FINISHED
2013-11-27 22:44:35,103 INFO org.apache.hadoop.yarn.server.resourcemanager.scheduler.capacity.LeafQueue: completedContainer container=Container: [ContainerId: container_1385613010171_0001_01_000005, NodeId: ubuntusakshi:59487, NodeHttpAddress: ubuntusakshi:8042, Resource: <memory:1024, vCores:1>, Priority: 20, Token: Token { kind: ContainerToken, service: 127.0.1.1:59487 }, ] resource=<memory:1024, vCores:1> queue=default: capacity=1.0, absoluteCapacity=1.0, usedResources=<memory:2048, vCores:1>usedCapacity=0.25, absoluteUsedCapacity=0.25, numApps=1, numContainers=1 usedCapacity=0.25 absoluteUsedCapacity=0.25 used=<memory:2048, vCores:1> cluster=<memory:8192, vCores:8>
2013-11-27 22:44:35,103 INFO org.apache.hadoop.yarn.server.resourcemanager.scheduler.capacity.ParentQueue: completedContainer queue=root usedCapacity=0.25 absoluteUsedCapacity=0.25 used=<memory:2048, vCores:1> cluster=<memory:8192, vCores:8>
2013-11-27 22:44:35,103 INFO org.apache.hadoop.yarn.server.resourcemanager.scheduler.capacity.ParentQueue: Re-sorting completed queue: root.default stats: default: capacity=1.0, absoluteCapacity=1.0, usedResources=<memory:2048, vCores:1>usedCapacity=0.25, absoluteUsedCapacity=0.25, numApps=1, numContainers=1
2013-11-27 22:44:35,104 INFO org.apache.hadoop.yarn.server.resourcemanager.scheduler.capacity.CapacityScheduler: Application appattempt_1385613010171_0001_000001 released container container_1385613010171_0001_01_000005 on node: host: ubuntusakshi:59487 #containers=1 available=6144 used=2048 with event: FINISHED
2013-11-27 22:44:35,483 INFO org.apache.hadoop.yarn.server.resourcemanager.rmapp.attempt.RMAppAttemptImpl: Processing event for appattempt_1385613010171_0001_000001 of type STATUS_UPDATE
2013-11-27 22:44:36,159 INFO org.apache.hadoop.yarn.server.resourcemanager.rmcontainer.RMContainerImpl: container_1385613010171_0001_01_000007 Container Transitioned from NEW to ALLOCATED
2013-11-27 22:44:36,159 INFO org.apache.hadoop.yarn.server.resourcemanager.RMAuditLogger: USER=sakshi	OPERATION=AM Allocated Container	TARGET=SchedulerApp	RESULT=SUCCESS	APPID=application_1385613010171_0001	CONTAINERID=container_1385613010171_0001_01_000007
2013-11-27 22:44:36,159 INFO org.apache.hadoop.yarn.server.resourcemanager.scheduler.common.fica.FiCaSchedulerNode: Assigned container container_1385613010171_0001_01_000007 of capacity <memory:1024, vCores:1> on host ubuntusakshi:59487, which currently has 2 containers, <memory:3072, vCores:2> used and <memory:5120, vCores:6> available
2013-11-27 22:44:36,159 INFO org.apache.hadoop.yarn.server.resourcemanager.scheduler.capacity.LeafQueue: assignedContainer application=application_1385613010171_0001 container=Container: [ContainerId: container_1385613010171_0001_01_000007, NodeId: ubuntusakshi:59487, NodeHttpAddress: ubuntusakshi:8042, Resource: <memory:1024, vCores:1>, Priority: 5, Token: Token { kind: ContainerToken, service: 127.0.1.1:59487 }, ] containerId=container_1385613010171_0001_01_000007 queue=default: capacity=1.0, absoluteCapacity=1.0, usedResources=<memory:2048, vCores:1>usedCapacity=0.25, absoluteUsedCapacity=0.25, numApps=1, numContainers=1 usedCapacity=0.25 absoluteUsedCapacity=0.25 used=<memory:2048, vCores:1> cluster=<memory:8192, vCores:8>
2013-11-27 22:44:36,159 INFO org.apache.hadoop.yarn.server.resourcemanager.rmapp.attempt.RMAppAttemptImpl: Processing event for appattempt_1385613010171_0001_000001 of type CONTAINER_ALLOCATED
2013-11-27 22:44:36,163 INFO org.apache.hadoop.yarn.server.resourcemanager.scheduler.capacity.ParentQueue: Re-sorting assigned queue: root.default stats: default: capacity=1.0, absoluteCapacity=1.0, usedResources=<memory:3072, vCores:2>usedCapacity=0.375, absoluteUsedCapacity=0.375, numApps=1, numContainers=2
2013-11-27 22:44:36,175 INFO org.apache.hadoop.yarn.server.resourcemanager.scheduler.capacity.ParentQueue: assignedContainer queue=root usedCapacity=0.375 absoluteUsedCapacity=0.375 used=<memory:3072, vCores:2> cluster=<memory:8192, vCores:8>
2013-11-27 22:44:36,506 INFO org.apache.hadoop.yarn.server.resourcemanager.rmapp.attempt.RMAppAttemptImpl: Processing event for appattempt_1385613010171_0001_000001 of type STATUS_UPDATE
2013-11-27 22:44:36,508 INFO org.apache.hadoop.yarn.server.resourcemanager.rmapp.attempt.RMAppAttemptImpl: Processing event for appattempt_1385613010171_0001_000001 of type CONTAINER_ACQUIRED
2013-11-27 22:44:36,508 INFO org.apache.hadoop.yarn.server.resourcemanager.rmcontainer.RMContainerImpl: container_1385613010171_0001_01_000007 Container Transitioned from ALLOCATED to ACQUIRED
2013-11-27 22:44:37,529 INFO org.apache.hadoop.yarn.server.resourcemanager.rmapp.attempt.RMAppAttemptImpl: Processing event for appattempt_1385613010171_0001_000001 of type STATUS_UPDATE
2013-11-27 22:44:37,529 INFO org.apache.hadoop.yarn.server.resourcemanager.scheduler.AppSchedulingInfo: checking for deactivate... 
2013-11-27 22:44:38,420 INFO org.apache.hadoop.yarn.server.resourcemanager.rmcontainer.RMContainerImpl: container_1385613010171_0001_01_000007 Container Transitioned from ACQUIRED to RUNNING
2013-11-27 22:44:38,425 INFO org.apache.hadoop.yarn.server.resourcemanager.rmcontainer.RMContainerImpl: container_1385613010171_0001_01_000008 Container Transitioned from NEW to ALLOCATED
2013-11-27 22:44:38,425 INFO org.apache.hadoop.yarn.server.resourcemanager.RMAuditLogger: USER=sakshi	OPERATION=AM Allocated Container	TARGET=SchedulerApp	RESULT=SUCCESS	APPID=application_1385613010171_0001	CONTAINERID=container_1385613010171_0001_01_000008
2013-11-27 22:44:38,426 INFO org.apache.hadoop.yarn.server.resourcemanager.scheduler.common.fica.FiCaSchedulerNode: Assigned container container_1385613010171_0001_01_000008 of capacity <memory:1024, vCores:1> on host ubuntusakshi:59487, which currently has 3 containers, <memory:4096, vCores:3> used and <memory:4096, vCores:5> available
2013-11-27 22:44:38,426 INFO org.apache.hadoop.yarn.server.resourcemanager.scheduler.capacity.LeafQueue: assignedContainer application=application_1385613010171_0001 container=Container: [ContainerId: container_1385613010171_0001_01_000008, NodeId: ubuntusakshi:59487, NodeHttpAddress: ubuntusakshi:8042, Resource: <memory:1024, vCores:1>, Priority: 10, Token: Token { kind: ContainerToken, service: 127.0.1.1:59487 }, ] containerId=container_1385613010171_0001_01_000008 queue=default: capacity=1.0, absoluteCapacity=1.0, usedResources=<memory:3072, vCores:2>usedCapacity=0.375, absoluteUsedCapacity=0.375, numApps=1, numContainers=2 usedCapacity=0.375 absoluteUsedCapacity=0.375 used=<memory:3072, vCores:2> cluster=<memory:8192, vCores:8>
2013-11-27 22:44:38,426 INFO org.apache.hadoop.yarn.server.resourcemanager.scheduler.capacity.ParentQueue: Re-sorting assigned queue: root.default stats: default: capacity=1.0, absoluteCapacity=1.0, usedResources=<memory:4096, vCores:3>usedCapacity=0.5, absoluteUsedCapacity=0.5, numApps=1, numContainers=3
2013-11-27 22:44:38,426 INFO org.apache.hadoop.yarn.server.resourcemanager.scheduler.capacity.ParentQueue: assignedContainer queue=root usedCapacity=0.5 absoluteUsedCapacity=0.5 used=<memory:4096, vCores:3> cluster=<memory:8192, vCores:8>
2013-11-27 22:44:38,426 INFO org.apache.hadoop.yarn.server.resourcemanager.rmapp.attempt.RMAppAttemptImpl: Processing event for appattempt_1385613010171_0001_000001 of type CONTAINER_ALLOCATED
2013-11-27 22:44:38,710 INFO org.apache.hadoop.yarn.server.resourcemanager.rmapp.attempt.RMAppAttemptImpl: Processing event for appattempt_1385613010171_0001_000001 of type STATUS_UPDATE
2013-11-27 22:44:38,711 INFO org.apache.hadoop.yarn.server.resourcemanager.rmcontainer.RMContainerImpl: container_1385613010171_0001_01_000008 Container Transitioned from ALLOCATED to ACQUIRED
2013-11-27 22:44:38,713 INFO org.apache.hadoop.yarn.server.resourcemanager.rmapp.attempt.RMAppAttemptImpl: Processing event for appattempt_1385613010171_0001_000001 of type CONTAINER_ACQUIRED
2013-11-27 22:44:39,689 INFO org.apache.hadoop.yarn.server.resourcemanager.rmcontainer.RMContainerImpl: container_1385613010171_0001_01_000008 Container Transitioned from ACQUIRED to RUNNING
2013-11-27 22:44:39,802 INFO org.apache.hadoop.yarn.server.resourcemanager.scheduler.AppSchedulingInfo: checking for deactivate... 
2013-11-27 22:44:39,803 INFO org.apache.hadoop.yarn.server.resourcemanager.rmapp.attempt.RMAppAttemptImpl: Processing event for appattempt_1385613010171_0001_000001 of type STATUS_UPDATE
2013-11-27 22:44:40,812 INFO org.apache.hadoop.yarn.server.resourcemanager.rmapp.attempt.RMAppAttemptImpl: Processing event for appattempt_1385613010171_0001_000001 of type STATUS_UPDATE
2013-11-27 22:44:41,827 INFO org.apache.hadoop.yarn.server.resourcemanager.rmapp.attempt.RMAppAttemptImpl: Processing event for appattempt_1385613010171_0001_000001 of type STATUS_UPDATE
2013-11-27 22:44:42,835 INFO org.apache.hadoop.yarn.server.resourcemanager.rmapp.attempt.RMAppAttemptImpl: Processing event for appattempt_1385613010171_0001_000001 of type STATUS_UPDATE
2013-11-27 22:44:43,841 INFO org.apache.hadoop.yarn.server.resourcemanager.rmapp.attempt.RMAppAttemptImpl: Processing event for appattempt_1385613010171_0001_000001 of type STATUS_UPDATE
2013-11-27 22:44:44,857 INFO org.apache.hadoop.yarn.server.resourcemanager.rmapp.attempt.RMAppAttemptImpl: Processing event for appattempt_1385613010171_0001_000001 of type STATUS_UPDATE
2013-11-27 22:44:45,874 INFO org.apache.hadoop.yarn.server.resourcemanager.rmapp.attempt.RMAppAttemptImpl: Processing event for appattempt_1385613010171_0001_000001 of type STATUS_UPDATE
2013-11-27 22:44:46,887 INFO org.apache.hadoop.yarn.server.resourcemanager.rmapp.attempt.RMAppAttemptImpl: Processing event for appattempt_1385613010171_0001_000001 of type STATUS_UPDATE
2013-11-27 22:44:47,893 INFO org.apache.hadoop.yarn.server.resourcemanager.rmapp.attempt.RMAppAttemptImpl: Processing event for appattempt_1385613010171_0001_000001 of type STATUS_UPDATE
2013-11-27 22:44:48,899 INFO org.apache.hadoop.yarn.server.resourcemanager.rmapp.attempt.RMAppAttemptImpl: Processing event for appattempt_1385613010171_0001_000001 of type STATUS_UPDATE
2013-11-27 22:44:49,897 INFO org.apache.hadoop.yarn.server.resourcemanager.rmapp.attempt.RMAppAttemptImpl: Processing event for appattempt_1385613010171_0001_000001 of type STATUS_UPDATE
2013-11-27 22:44:50,948 INFO org.apache.hadoop.yarn.server.resourcemanager.rmapp.attempt.RMAppAttemptImpl: Processing event for appattempt_1385613010171_0001_000001 of type STATUS_UPDATE
2013-11-27 22:44:51,986 INFO org.apache.hadoop.yarn.server.resourcemanager.rmapp.attempt.RMAppAttemptImpl: Processing event for appattempt_1385613010171_0001_000001 of type STATUS_UPDATE
2013-11-27 22:44:52,936 INFO org.apache.hadoop.yarn.server.resourcemanager.rmcontainer.RMContainerImpl: container_1385613010171_0001_01_000007 Container Transitioned from RUNNING to COMPLETED
2013-11-27 22:44:52,937 INFO org.apache.hadoop.yarn.server.resourcemanager.scheduler.common.fica.FiCaSchedulerApp: Completed container: container_1385613010171_0001_01_000007 in state: COMPLETED event:FINISHED
2013-11-27 22:44:52,939 INFO org.apache.hadoop.yarn.server.resourcemanager.rmapp.attempt.RMAppAttemptImpl: Processing event for appattempt_1385613010171_0001_000001 of type CONTAINER_FINISHED
2013-11-27 22:44:52,940 INFO org.apache.hadoop.yarn.server.resourcemanager.RMAuditLogger: USER=sakshi	OPERATION=AM Released Container	TARGET=SchedulerApp	RESULT=SUCCESS	APPID=application_1385613010171_0001	CONTAINERID=container_1385613010171_0001_01_000007
2013-11-27 22:44:52,941 INFO org.apache.hadoop.yarn.server.resourcemanager.scheduler.common.fica.FiCaSchedulerNode: Released container container_1385613010171_0001_01_000007 of capacity <memory:1024, vCores:1> on host ubuntusakshi:59487, which currently has 2 containers, <memory:3072, vCores:2> used and <memory:5120, vCores:6> available, release resources=true
2013-11-27 22:44:52,945 INFO org.apache.hadoop.yarn.server.resourcemanager.scheduler.capacity.LeafQueue: default used=<memory:3072, vCores:2> numContainers=2 user=sakshi user-resources=<memory:3072, vCores:2>
2013-11-27 22:44:52,948 INFO org.apache.hadoop.yarn.server.resourcemanager.scheduler.capacity.LeafQueue: completedContainer container=Container: [ContainerId: container_1385613010171_0001_01_000007, NodeId: ubuntusakshi:59487, NodeHttpAddress: ubuntusakshi:8042, Resource: <memory:1024, vCores:1>, Priority: 5, Token: Token { kind: ContainerToken, service: 127.0.1.1:59487 }, ] resource=<memory:1024, vCores:1> queue=default: capacity=1.0, absoluteCapacity=1.0, usedResources=<memory:3072, vCores:2>usedCapacity=0.375, absoluteUsedCapacity=0.375, numApps=1, numContainers=2 usedCapacity=0.375 absoluteUsedCapacity=0.375 used=<memory:3072, vCores:2> cluster=<memory:8192, vCores:8>
2013-11-27 22:44:52,948 INFO org.apache.hadoop.yarn.server.resourcemanager.scheduler.capacity.ParentQueue: completedContainer queue=root usedCapacity=0.375 absoluteUsedCapacity=0.375 used=<memory:3072, vCores:2> cluster=<memory:8192, vCores:8>
2013-11-27 22:44:52,949 INFO org.apache.hadoop.yarn.server.resourcemanager.scheduler.capacity.ParentQueue: Re-sorting completed queue: root.default stats: default: capacity=1.0, absoluteCapacity=1.0, usedResources=<memory:3072, vCores:2>usedCapacity=0.375, absoluteUsedCapacity=0.375, numApps=1, numContainers=2
2013-11-27 22:44:52,950 INFO org.apache.hadoop.yarn.server.resourcemanager.scheduler.capacity.CapacityScheduler: Application appattempt_1385613010171_0001_000001 released container container_1385613010171_0001_01_000007 on node: host: ubuntusakshi:59487 #containers=2 available=5120 used=3072 with event: FINISHED
2013-11-27 22:44:52,995 INFO org.apache.hadoop.yarn.server.resourcemanager.rmapp.attempt.RMAppAttemptImpl: Processing event for appattempt_1385613010171_0001_000001 of type STATUS_UPDATE
2013-11-27 22:44:54,009 INFO org.apache.hadoop.yarn.server.resourcemanager.rmapp.attempt.RMAppAttemptImpl: Processing event for appattempt_1385613010171_0001_000001 of type STATUS_UPDATE
2013-11-27 22:44:55,026 INFO org.apache.hadoop.yarn.server.resourcemanager.rmapp.attempt.RMAppAttemptImpl: Processing event for appattempt_1385613010171_0001_000001 of type STATUS_UPDATE
2013-11-27 22:44:55,661 INFO org.apache.hadoop.yarn.server.resourcemanager.rmcontainer.RMContainerImpl: container_1385613010171_0001_01_000008 Container Transitioned from RUNNING to COMPLETED
2013-11-27 22:44:55,661 INFO org.apache.hadoop.yarn.server.resourcemanager.scheduler.common.fica.FiCaSchedulerApp: Completed container: container_1385613010171_0001_01_000008 in state: COMPLETED event:FINISHED
2013-11-27 22:44:55,661 INFO org.apache.hadoop.yarn.server.resourcemanager.RMAuditLogger: USER=sakshi	OPERATION=AM Released Container	TARGET=SchedulerApp	RESULT=SUCCESS	APPID=application_1385613010171_0001	CONTAINERID=container_1385613010171_0001_01_000008
2013-11-27 22:44:55,661 INFO org.apache.hadoop.yarn.server.resourcemanager.rmapp.attempt.RMAppAttemptImpl: Processing event for appattempt_1385613010171_0001_000001 of type CONTAINER_FINISHED
2013-11-27 22:44:55,663 INFO org.apache.hadoop.yarn.server.resourcemanager.scheduler.common.fica.FiCaSchedulerNode: Released container container_1385613010171_0001_01_000008 of capacity <memory:1024, vCores:1> on host ubuntusakshi:59487, which currently has 1 containers, <memory:2048, vCores:1> used and <memory:6144, vCores:7> available, release resources=true
2013-11-27 22:44:55,663 INFO org.apache.hadoop.yarn.server.resourcemanager.scheduler.capacity.LeafQueue: default used=<memory:2048, vCores:1> numContainers=1 user=sakshi user-resources=<memory:2048, vCores:1>
2013-11-27 22:44:55,663 INFO org.apache.hadoop.yarn.server.resourcemanager.scheduler.capacity.LeafQueue: completedContainer container=Container: [ContainerId: container_1385613010171_0001_01_000008, NodeId: ubuntusakshi:59487, NodeHttpAddress: ubuntusakshi:8042, Resource: <memory:1024, vCores:1>, Priority: 10, Token: Token { kind: ContainerToken, service: 127.0.1.1:59487 }, ] resource=<memory:1024, vCores:1> queue=default: capacity=1.0, absoluteCapacity=1.0, usedResources=<memory:2048, vCores:1>usedCapacity=0.25, absoluteUsedCapacity=0.25, numApps=1, numContainers=1 usedCapacity=0.25 absoluteUsedCapacity=0.25 used=<memory:2048, vCores:1> cluster=<memory:8192, vCores:8>
2013-11-27 22:44:55,669 INFO org.apache.hadoop.yarn.server.resourcemanager.scheduler.capacity.ParentQueue: completedContainer queue=root usedCapacity=0.25 absoluteUsedCapacity=0.25 used=<memory:2048, vCores:1> cluster=<memory:8192, vCores:8>
2013-11-27 22:44:55,670 INFO org.apache.hadoop.yarn.server.resourcemanager.scheduler.capacity.ParentQueue: Re-sorting completed queue: root.default stats: default: capacity=1.0, absoluteCapacity=1.0, usedResources=<memory:2048, vCores:1>usedCapacity=0.25, absoluteUsedCapacity=0.25, numApps=1, numContainers=1
2013-11-27 22:44:55,673 INFO org.apache.hadoop.yarn.server.resourcemanager.scheduler.capacity.CapacityScheduler: Application appattempt_1385613010171_0001_000001 released container container_1385613010171_0001_01_000008 on node: host: ubuntusakshi:59487 #containers=1 available=6144 used=2048 with event: FINISHED
2013-11-27 22:44:56,033 INFO org.apache.hadoop.yarn.server.resourcemanager.rmapp.attempt.RMAppAttemptImpl: Processing event for appattempt_1385613010171_0001_000001 of type STATUS_UPDATE
2013-11-27 22:44:57,037 INFO org.apache.hadoop.yarn.server.resourcemanager.rmapp.attempt.RMAppAttemptImpl: Processing event for appattempt_1385613010171_0001_000001 of type STATUS_UPDATE
2013-11-27 22:44:58,043 INFO org.apache.hadoop.yarn.server.resourcemanager.rmapp.attempt.RMAppAttemptImpl: Processing event for appattempt_1385613010171_0001_000001 of type STATUS_UPDATE
2013-11-27 22:44:59,062 INFO org.apache.hadoop.yarn.server.resourcemanager.rmapp.attempt.RMAppAttemptImpl: Processing event for appattempt_1385613010171_0001_000001 of type STATUS_UPDATE
2013-11-27 22:44:59,744 INFO org.apache.hadoop.yarn.server.resourcemanager.rmapp.attempt.RMAppAttemptImpl: Processing event for appattempt_1385613010171_0001_000001 of type UNREGISTERED
2013-11-27 22:44:59,772 INFO org.apache.hadoop.yarn.server.resourcemanager.rmapp.attempt.RMAppAttemptImpl: Sakshi appattempt_1385613010171_0001_000001 State change from RUNNING to FINISHING after EVENT: UNREGISTERED
2013-11-27 22:44:59,772 INFO org.apache.hadoop.yarn.server.resourcemanager.rmapp.RMAppImpl: Sakshi application_1385613010171_0001 State change from RUNNING to FINISHING after EVENT: ATTEMPT_FINISHING
2013-11-27 22:45:00,918 INFO org.apache.hadoop.yarn.server.resourcemanager.rmcontainer.RMContainerImpl: container_1385613010171_0001_01_000001 Container Transitioned from RUNNING to COMPLETED
2013-11-27 22:45:00,918 INFO org.apache.hadoop.yarn.server.resourcemanager.scheduler.common.fica.FiCaSchedulerApp: Completed container: container_1385613010171_0001_01_000001 in state: COMPLETED event:FINISHED
2013-11-27 22:45:00,918 INFO org.apache.hadoop.yarn.server.resourcemanager.RMAuditLogger: USER=sakshi	OPERATION=AM Released Container	TARGET=SchedulerApp	RESULT=SUCCESS	APPID=application_1385613010171_0001	CONTAINERID=container_1385613010171_0001_01_000001
2013-11-27 22:45:00,918 INFO org.apache.hadoop.yarn.server.resourcemanager.scheduler.common.fica.FiCaSchedulerNode: Released container container_1385613010171_0001_01_000001 of capacity <memory:2048, vCores:1> on host ubuntusakshi:59487, which currently has 0 containers, <memory:0, vCores:0> used and <memory:8192, vCores:8> available, release resources=true
2013-11-27 22:45:00,918 INFO org.apache.hadoop.yarn.server.resourcemanager.scheduler.capacity.LeafQueue: default used=<memory:0, vCores:0> numContainers=0 user=sakshi user-resources=<memory:0, vCores:0>
2013-11-27 22:45:00,919 INFO org.apache.hadoop.yarn.server.resourcemanager.rmapp.attempt.RMAppAttemptImpl: Processing event for appattempt_1385613010171_0001_000001 of type CONTAINER_FINISHED
2013-11-27 22:45:00,919 INFO org.apache.hadoop.yarn.server.resourcemanager.ApplicationMasterService: Unregistering app attempt : appattempt_1385613010171_0001_000001
2013-11-27 22:45:00,927 INFO org.apache.hadoop.yarn.server.resourcemanager.rmapp.attempt.RMAppAttemptImpl: Sakshi appattempt_1385613010171_0001_000001 State change from FINISHING to FINISHED after EVENT: CONTAINER_FINISHED
2013-11-27 22:45:00,927 INFO org.apache.hadoop.yarn.server.resourcemanager.rmapp.RMAppImpl: Sakshi application_1385613010171_0001 State change from FINISHING to FINISHED after EVENT: ATTEMPT_FINISHED
2013-11-27 22:45:00,928 INFO org.apache.hadoop.yarn.server.resourcemanager.scheduler.capacity.LeafQueue: completedContainer container=Container: [ContainerId: container_1385613010171_0001_01_000001, NodeId: ubuntusakshi:59487, NodeHttpAddress: ubuntusakshi:8042, Resource: <memory:2048, vCores:1>, Priority: 0, Token: Token { kind: ContainerToken, service: 127.0.1.1:59487 }, ] resource=<memory:2048, vCores:1> queue=default: capacity=1.0, absoluteCapacity=1.0, usedResources=<memory:0, vCores:0>usedCapacity=0.0, absoluteUsedCapacity=0.0, numApps=1, numContainers=0 usedCapacity=0.0 absoluteUsedCapacity=0.0 used=<memory:0, vCores:0> cluster=<memory:8192, vCores:8>
2013-11-27 22:45:00,929 INFO org.apache.hadoop.yarn.server.resourcemanager.scheduler.capacity.ParentQueue: completedContainer queue=root usedCapacity=0.0 absoluteUsedCapacity=0.0 used=<memory:0, vCores:0> cluster=<memory:8192, vCores:8>
2013-11-27 22:45:00,931 INFO org.apache.hadoop.yarn.server.resourcemanager.scheduler.capacity.ParentQueue: Re-sorting completed queue: root.default stats: default: capacity=1.0, absoluteCapacity=1.0, usedResources=<memory:0, vCores:0>usedCapacity=0.0, absoluteUsedCapacity=0.0, numApps=1, numContainers=0
2013-11-27 22:45:00,931 INFO org.apache.hadoop.yarn.server.resourcemanager.scheduler.capacity.CapacityScheduler: Application appattempt_1385613010171_0001_000001 released container container_1385613010171_0001_01_000001 on node: host: ubuntusakshi:59487 #containers=0 available=8192 used=0 with event: FINISHED
2013-11-27 22:45:00,930 INFO org.apache.hadoop.yarn.server.resourcemanager.RMAuditLogger: USER=sakshi	OPERATION=Application Finished - Succeeded	TARGET=RMAppManager	RESULT=SUCCESS	APPID=application_1385613010171_0001
2013-11-27 22:45:00,949 INFO org.apache.hadoop.yarn.server.resourcemanager.RMAppManager$ApplicationSummary: appId=application_1385613010171_0001,name=QuasiMonteCarlo,user=sakshi,queue=default,state=FINISHED,trackingUrl=ubuntusakshi:8088/proxy/application_1385613010171_0001/jobhistory/job/job_1385613010171_0001,appMasterHost=ubuntusakshi,startTime=1385613293449,finishTime=1385613899772
2013-11-27 22:45:00,951 INFO org.apache.hadoop.yarn.server.resourcemanager.recovery.RMStateStore: Removing info for app: application_1385613010171_0001
2013-11-27 22:45:00,981 INFO org.apache.hadoop.yarn.server.resourcemanager.amlauncher.AMLauncher: Cleaning master appattempt_1385613010171_0001_000001
2013-11-27 22:45:00,998 INFO org.apache.hadoop.yarn.server.resourcemanager.scheduler.capacity.CapacityScheduler: Application appattempt_1385613010171_0001_000001 is done. finalState=FINISHED
2013-11-27 22:45:01,000 INFO org.apache.hadoop.yarn.server.resourcemanager.scheduler.AppSchedulingInfo: Application application_1385613010171_0001 requests cleared
2013-11-27 22:45:01,000 INFO org.apache.hadoop.yarn.server.resourcemanager.scheduler.capacity.LeafQueue: Application removed - appId: application_1385613010171_0001 user: sakshi queue: default #user-pending-applications: 0 #user-active-applications: 0 #queue-pending-applications: 0 #queue-active-applications: 0
2013-11-27 22:45:01,000 INFO org.apache.hadoop.yarn.server.resourcemanager.scheduler.capacity.ParentQueue: Application removed - appId: application_1385613010171_0001 user: sakshi leaf-queue of parent: root #applications: 0
